Workbook

Sheet About
A1: GaHEbIC-government - BAU Government Expenditures by ISIC Code
A3: State: Virginia (VA) Base year: 2019 Pipeline: EPS IO Pipeline — stateior-based
A4: Deflator: 2019 USD -> 2012 USD = 1.12266 (BEA chained GDP price index; 2012 = 100.000, 2019 = 112.266)
A6: =========================================================
A7: Methodology
A8: =========================================================
A9: Government final demand by ISIC commodity is the row-sum of stateior's
A10: Use table across all government final-demand columns for this state:
A11: F06* Federal nondefense (consumption + investment)
A12: F07* Federal defense (consumption + investment)
A13: F10* State and local government (consumption + investment)
A15: All three families are included per BEA's 'government purchases of
... A104: - GaHEbIC-government / -household (match the CSVs)

Sheet Keys
A1: category | B1: key | C1: value | D1: description
A2: deflator | B2: deflator_nominal_to_2012 | C2: 1.12266 | D2: Divide nominal 2019 USD by this to get 2012 USD. BEA chained GDP price index; 2012 = 100.000, 2019 = 112.266
A3: year | B3: base_year | C3: 2019 | D3: stateior base year; nominal-USD vintage of the source tabs
A4: numeric | B4: epsilon_div_floor | C4: 1e-09 | D4: Denominator floor for ratio outputs (DCS, ESoP): x/MAX(den, epsilon) avoids div-by-zero; mirrors pmax(den, 1e-9) in the R pipeline
A5: numeric | B5: fogp_denom_floor_usd | C5: 1 | D5: FoGP-entity denominator floor: total purchases per category floored at $1 (mirrors pmax(total, 1)); near-zero totals give near-zero fractions

Sheet 1_Gov_by_BEA
A1: BEA_Summary_code | B1: gov_expenditure_USD_2019nominal
A2: 111CA | B2: 0
A3: 113FF | B3: 0
A4: 211 | B4: 0
A5: 212 | B5: 0
A6: 213 | B6: 0
A7: 22 | B7: 0
A8: 23 | B8: 9.2238493e+09
A9: 321 | B9: 1152823.9
A10: 327 | B10: 0
A11: 331 | B11: 0
A12: 332 | B12: 19577735
A13: 333 | B13: 2.5310625e+08
... A74: Other | B74: 0

Sheet 2_HH_by_BEA
A1: BEA_Summary_code | B1: hh_expenditure_USD_2019nominal
A2: 111CA | B2: 9.067878e+08
A3: 113FF | B3: 1.4466439e+08
A4: 211 | B4: 0
A5: 212 | B5: 1023259.5
A6: 213 | B6: 0
A7: 22 | B7: 7.0491774e+09
A8: 23 | B8: 0
A9: 321 | B9: 1.0787606e+08
A10: 327 | B10: 2.7713836e+08
A11: 331 | B11: 10806707
A12: 332 | B12: 3.6095591e+08
A13: 333 | B13: 2.1966196e+08
... A74: Other | B74: -1.9719652e+09

Sheet Src_Stateior_SoI_TotUse
A1: State-of-Interest Total Use matrix at BEA Summary resolution, from
A2: EPA stateior. Rows = commodities, columns = industries + final demand
A3: categories (F01* PCE, F02* investment, F06* fed nondefense, F07* fed
A4: defense, F10* state and local, F040 intl exports, F050 intl imports).
A5: Values in nominal 2019 USD. This is the raw input used to compute
A6: DCS, ESoP, government/household expenditures, and Leontief coefficients.
A9: commodity | B9: 111CA | C9: 113FF | D9: 211 | E9: 212 | F9: 213 | G9: 22 | H9: 23 | I9: 321 | J9: 327 | K9: 331 | L9: 332 | M9: 333 | N9: 334 | O9: 335 | P9: 3361MV | Q9: 3364OT | R9: 337 | S9: 339 | T9: 311FT | U9: 313TT | V9: 315AL | W9: 322 | X9: 323 | Y9: 324 | Z9: 325 | AA9: 326 | AB9: 42 | AC9: 441 | AD9: 445 | AE9: 452 | AF9: 4A0 | AG9: 481 | AH9: 482 | AI9: 483 | AJ9: 484 | AK9: 485 | AL9: 486 | AM9: 487OS | AN9: 493 | AO9: 511 | AP9: 512 | AQ9: 513 | AR9: 514 | AS9: 521CI | AT9: 523 | AU9: 524 | AV9: 525 | AW9: HS | AX9: ORE | AY9: 532RL | AZ9: 5411 | BA9: 5415 | BB9: 5412OP | BC9: 55 | BD9: 561 | BE9: 562 | BF9: 61 | BG9: 621 | BH9: 622 | BI9: 623 | BJ9: 624 | BK9: 711AS | BL9: 713 | BM9: 721 | BN9: 722 | BO9: 81 | BP9: GFGD | BQ9: GFGN | BR9: GFE | BS9: GSLG | BT9: GSLE | BU9: F010 | BV9: F02S | BW9: F02E | BX9: F02N | BY9: F02R | BZ9: F030 | CA9: F040 | CB9: F050 | CC9: F06C | CD9: F06S | CE9: F06E | CF9: F06N | CG9: F07C | CH9: F07S | CI9: F07E | CJ9: F07N | CK9: F10C | CL9: F10S | CM9: F10E | CN9: F10N
A10: 111CA | B10: 1.7346341e+08 | C10: 1111816 | D10: 0 | E10: 105527.89 | F10: 5963.6617 | G10: 0 | H10: 9279042 | I10: 0 | J10: 0 | K10: 0 | L10: 0 | M10: 0 | N10: 0 | O10: 0 | P10: 0 | Q10: 0 | R10: 0 | S10: 648077.53 | T10: 3.2910394e+09 | U10: 10384081 | V10: 0 | W10: 0 | X10: 0 | Y10: 0 | Z10: 22945731 | AA10: 0 | AB10: 3133911 | AC10: 4878333.2 | AD10: 5889351.7 | AE10: 981663.65 | AF10: 2082710 | AG10: 0 | AH10: 0 | AI10: 0 | AJ10: 0 | AK10: 0 | AL10: 0 | AM10: 268244.08 | AN10: 0 | AO10: 0 | AP10: 0 | AQ10: 0 | AR10: 0 | AS10: 5274.3019 | AT10: 0 | AU10: 0 | AV10: 0 | AW10: 0 | AX10: 16626.421 | AY10: 0 | AZ10: 4176.0656 | BA10: 0 | BB10: 11555712 | BC10: 179892.45 | BD10: 15604711 | BE10: 0 | BF10: 1547495.6 | BG10: 0 | BH10: 0 | BI10: 0 | BJ10: 0 | BK10: 0 | BL10: 3542991.7 | BM10: 320808.59 | BN10: 77302744 | BO10: 159281.63 | BP10: 391958.82 | BQ10: 1675470.5 | BR10: 0 | BS10: 30456334 | BT10: 0 | BU10: 9.0298692e+08 | BV10: 0 | BW10: 0 | BX10: 0 | BY10: 0 | BZ10: -1.2597533e+08 | CA10: 6.5905807e+08 | CB10: -1.5635104e+09 | CC10: 0 | CD10: 0 | CE10: 0 | CF10: 0 | CG10: 0 | CH10: 0 | CI10: 0 | CJ10: 0 | CK10: 0 | CL10: 0 | CM10: 0 | CN10: 0
A11: 113FF | B11: 92021614 | C11: 23385851 | D11: 0 | E11: 847658.89 | F11: 0 | G11: 0 | H11: 0 | I11: 1.5755881e+08 | J11: 0 | K11: 0 | L11: 0 | M11: 0 | N11: 0 | O11: 0 | P11: 0 | Q11: 0 | R11: 1705718.9 | S11: 1664783.9 | T11: 4.4446033e+08 | U11: 0 | V11: 299842.6 | W11: 22926907 | X11: 308806.7 | Y11: 0 | Z11: 1883611.7 | AA11: 34233877 | AB11: 0 | AC11: 0 | AD11: 16613686 | AE11: 0 | AF11: 0 | AG11: 0 | AH11: 0 | AI11: 0 | AJ11: 0 | AK11: 0 | AL11: 0 | AM11: 22941.679 | AN11: 0 | AO11: 0 | AP11: 0 | AQ11: 0 | AR11: 0 | AS11: 0 | AT11: 0 | AU11: 0 | AV11: 0 | AW11: 0 | AX11: 0 | AY11: 0 | AZ11: 0 | BA11: 0 | BB11: 5745794.3 | BC11: 294413.95 | BD11: 64384.131 | BE11: 0 | BF11: 904493.64 | BG11: 0 | BH11: 0 | BI11: 0 | BJ11: 0 | BK11: 0 | BL11: 3272881 | BM11: 6509978.4 | BN11: 1.1418523e+08 | BO11: 2240053.5 | BP11: 0 | BQ11: 1262375.4 | BR11: 875490.9 | BS11: 57815678 | BT11: 0 | BU11: 1.1392642e+08 | BV11: 0 | BW11: 0 | BX11: 0 | BY11: 0 | BZ11: 17648756 | CA11: 1.1419674e+08 | CB11: -6.9647072e+08 | CC11: 0 | CD11: 0 | CE11: 0 | CF11: 0 | CG11: 0 | CH11: 0 | CI11: 0 | CJ11: 0 | CK11: 0 | CL11: 0 | CM11: 0 | CN11: 0
A12: 211 | B12: 0 | C12: 0 | D12: 776322.01 | E12: 0 | F12: 4384.7159 | G12: 34098545 | H12: 0 | I12: 34969.961 | J12: 0.18757457 | K12: 0.2298521 | L12: 0 | M12: 0 | N12: 0 | O12: 0 | P12: 0.10779536 | Q12: 0 | R12: 0 | S12: 0 | T12: 0.53774511 | U12: 0 | V12: 0 | W12: 21184.387 | X12: 0.15949417 | Y12: 3.3157415e+08 | Z12: 1535343 | AA12: 0 | AB12: 18940.301 | AC12: 28009.49 | AD12: 0 | AE12: 0.27627854 | AF12: 38460.189 | AG12: 0 | AH12: 0 | AI12: 0 | AJ12: 0 | AK12: 0 | AL12: 6805.9812 | AM12: 0 | AN12: 550860.9 | AO12: 289343.17 | AP12: 0 | AQ12: 19962.533 | AR12: 92395.941 | AS12: 0 | AT12: 0 | AU12: 0 | AV12: 0 | AW12: 0 | AX12: 162991.74 | AY12: 0 | AZ12: 0 | BA12: 0.65894283 | BB12: 39861.461 | BC12: 34042.788 | BD12: 0 | BE12: 18789.309 | BF12: 1374393.6 | BG12: 0.21682345 | BH12: 0 | BI12: 0.19876986 | BJ12: 0 | BK12: 0 | BL12: 136191.42 | BM12: 0.16799969 | BN12: 0.21705874 | BO12: 60746.534 | BP12: 0 | BQ12: 0 | BR12: 6145156.5 | BS12: 0 | BT12: 19657361 | BU12: 0 | BV12: 0 | BW12: 0 | BX12: 0 | BY12: 0 | BZ12: 217.57875 | CA12: 3407.7901 | CB12: -3.9671088e+08 | CC12: 0 | CD12: 0 | CE12: 0 | CF12: 0 | CG12: 0 | CH12: 0 | CI12: 0 | CJ12: 0 | CK12: 0 | CL12: 0 | CM12: 0 | CN12: 0
A13: 212 | B13: 2253567.5 | C13: 0 | D13: 4530.5268 | E13: 27588988 | F13: 42348.099 | G13: 22638934 | H13: 77305585 | I13: 44633.822 | J13: 43238704 | K13: 18664962 | L13: 1420637.9 | M13: 352817.73 | N13: 31251.013 | O13: 751548.97 | P13: 419038.58 | Q13: 658860.49 | R13: 54365.077 | S13: 376679.22 | T13: 22176144 | U13: 210058.75 | V13: 0 | W13: 5027190.4 | X13: 0 | Y13: 1458884.6 | Z13: 13655004 | AA13: 529755.36 | AB13: 149901.74 | AC13: 0 | AD13: 0 | AE13: 0 | AF13: 22297.917 | AG13: 0 | AH13: 446902.75 | AI13: 0 | AJ13: 17305.919 | AK13: 2523.1757 | AL13: 0 | AM13: 3660.2905 | AN13: 7323.9255 | AO13: 39238.743 | AP13: 22671.998 | AQ13: 931082.93 | AR13: 2857890 | AS13: 0 | AT13: 0 | AU13: 0 | AV13: 0 | AW13: 22402.029 | AX13: 0 | AY13: 0 | AZ13: 0 | BA13: 0 | BB13: 14109480 | BC13: 196982.72 | BD13: 4622632.2 | BE13: 156686.26 | BF13: 1366854.3 | BG13: 0 | BH13: 53218.081 | BI13: 124022.24 | BJ13: 511952.34 | BK13: 711116.9 | BL13: 1858374.1 | BM13: 442126.6 | BN13: 2914684.6 | BO13: 5948957.4 | BP13: 0 | BQ13: 27640609 | BR13: 0 | BS13: 26989066 | BT13: 13112470 | BU13: 984312.91 | BV13: 0 | BW13: 860614.17 | BX13: 0 | BY13: 0 | BZ13: 16402656 | CA13: 2.0678253e+09 | CB13: -1.0973e+08 | CC13: 0 | CD13: 0 | CE13: 0 | CF13: 0 | CG13: 0 | CH13: 0 | CI13: 0 | CJ13: 0 | CK13: 0 | CL13: 0 | CM13: 0 | CN13: 0
A14: 213 | B14: 0 | C14: 0 | D14: 2595658.9 | E14: 9914070 | F14: 1877952.4 | G14: 0 | H14: 0 | I14: 0 | J14: 0 | K14: 0 | L14: 0 | M14: 0 | N14: 0 | O14: 0 | P14: 0 | Q14: 0 | R14: 0 | S14: 0 | T14: 0 | U14: 0 | V14: 0 | W14: 0 | X14: 0 | Y14: 0 | Z14: 0 | AA14: 0 | AB14: 0 | AC14: 0 | AD14: 0 | AE14: 0 | AF14: 0 | AG14: 0 | AH14: 0 | AI14: 0 | AJ14: 0 | AK14: 0 | AL14: 0 | AM14: 0 | AN14: 0 | AO14: 0 | AP14: 0 | AQ14: 0 | AR14: 0 | AS14: 0 | AT14: 0 | AU14: 0 | AV14: 0 | AW14: 0 | AX14: 0 | AY14: 0 | AZ14: 0 | BA14: 0 | BB14: 390545.96 | BC14: 34504.133 | BD14: 0 | BE14: 0 | BF14: 0 | BG14: 0 | BH14: 0 | BI14: 0 | BJ14: 0 | BK14: 0 | BL14: 0 | BM14: 0 | BN14: 0 | BO14: 0 | BP14: 0 | BQ14: 0 | BR14: 0 | BS14: 0 | BT14: 0 | BU14: 0 | BV14: 2.3652043e+08 | BW14: 2101679.4 | BX14: 0 | BY14: 0 | BZ14: -12083.912 | CA14: 47188998 | CB14: -1711543.8 | CC14: 0 | CD14: 0 | CE14: 0 | CF14: 0 | CG14: 0 | CH14: 0 | CI14: 0 | CJ14: 0 | CK14: 0 | CL14: 0 | CM14: 0 | CN14: 0
A15: 22 | B15: 22407636 | C15: 131607.34 | D15: 644125.19 | E15: 26768017 | F15: 291876.38 | G15: 1.9197909e+08 | H15: 63428120 | I15: 15412083 | J15: 21615837 | K15: 11241858 | L15: 17823491 | M15: 7434266.6 | N15: 3620477.8 | O15: 3582556.1 | P15: 9992719.8 | Q15: 23165760 | R15: 4122945.3 | S15: 2222176.7 | T15: 1.43525e+08 | U15: 7304766.4 | V15: 66414.038 | W15: 31140132 | X15: 5712948.4 | Y15: 4242290.4 | Z15: 26162603 | AA15: 33080296 | AB15: 74557288 | AC15: 32111971 | AD15: 73094803 | AE15: 64959066 | AF15: 83856867 | AG15: 9960444.4 | AH15: 398735.99 | AI15: 2148730.9 | AJ15: 20954678 | AK15: 1882805.1 | AL15: 1579254.1 | AM15: 8862133.9 | AN15: 15136440 | AO15: 3220492.9 | AP15: 1038149.2 | AQ15: 31725159 | AR15: 22800819 | AS15: 22413633 | AT15: 3827181.9 | AU15: 2450432.8 | AV15: 31040764 | AW15: 1470557.2 | AX15: 1.515899e+08 | AY15: 6073170.4 | AZ15: 3534152.2 | BA15: 16775102 | BB15: 61441177 | BC15: 47609758 | BD15: 27777218 | BE15: 7155949.9 | BF15: 29174736 | BG15: 27272467 | BH15: 39820199 | BI15: 22161742 | BJ15: 7095347.9 | BK15: 4640505 | BL15: 15147590 | BM15: 30673928 | BN15: 1.2801727e+08 | BO15: 59219294 | BP15: 56258529 | BQ15: 26126435 | BR15: 49630434 | BS15: 1.5874059e+08 | BT15: 15321842 | BU15: 1.9368572e+09 | BV15: 0 | BW15: 0 | BX15: 0 | BY15: 0 | BZ15: 0 | CA15: 1.0516821e+08 | CB15: -51886425 | CC15: 0 | CD15: 0 | CE15: 0 | CF15: 0 | CG15: 0 | CH15: 0 | CI15: 0 | CJ15: 0 | CK15: 0 | CL15: 0 | CM15: 0 | CN15: 0
A16: 23 | B16: 14562636 | C16: 196609.35 | D16: 53734.504 | E16: 86182981 | F16: 4039714.1 | G16: 1.4455109e+08 | H16: 7680110.7 | I16: 11015248 | J16: 19030456 | K16: 9215975.2 | L16: 20244491 | M16: 10596983 | N16: 4932040.2 | O16: 3019263.6 | P16: 10235213 | Q16: 13495380 | R16: 3538507.1 | S16: 3050808.5 | T16: 1.264204e+08 | U16: 3644411.8 | V16: 56450.775 | W16: 23281641 | X16: 5842831 | Y16: 23011708 | Z16: 15590268 | AA16: 21259936 | AB16: 73354499 | AC16: 38456356 | AD16: 30213156 | AE16: 63311751 | AF16: 72669572 | AG16: 8954247.2 | AH16: 54057524 | AI16: 2266950.2 | AJ16: 9635633.5 | AK16: 9014299.9 | AL16: 3909830.6 | AM16: 28952399 | AN16: 20771705 | AO16: 2039834.5 | AP16: 648339.26 | AQ16: 47590262 | AR16: 22867545 | AS16: 1.5702521e+08 | AT16: 20213887 | AU16: 12091504 | AV16: 5701310.5 | AW16: 2.463979e+09 | AX16: 7.0308576e+08 | AY16: 15671160 | AZ16: 3991457.6 | BA16: 6091247.2 | BB16: 95944015 | BC16: 29037989 | BD16: 31258496 | BE16: 2762004.2 | BF16: 40705633 | BG16: 18731631 | BH16: 23756605 | BI16: 15198433 | BJ16: 12766266 | BK16: 4045414.9 | BL16: 10435474 | BM16: 57422060 | BN16: 59773416 | BO16: 1.178771e+08 | BP16: 5.4122743e+08 | BQ16: 38463304 | BR16: 46411802 | BS16: 9.3930491e+08 | BT16: 9.3165754e+08 | BU16: 0 | BV16: 1.4206591e+10 | BW16: 0 | BX16: 0 | BY16: 1.7535422e+10 | BZ16: 0 | CA16: 2804195 | CB16: 0 | CC16: 0 | CD16: 0 | CE16: 0 | CF16: 0 | CG16: 0 | CH16: 5.8716869e+08 | CI16: 0 | CJ16: 0 | CK16: 0 | CL16: 8.6366806e+09 | CM16: 0 | CN16: 0
A17: 321 | B17: 2497764.8 | C17: 261204.49 | D17: 0 | E17: 1797307.2 | F17: 219729.6 | G17: 55308.655 | H17: 6.0270173e+08 | I17: 4.5291365e+08 | J17: 1829923.4 | K17: 1735737.5 | L17: 1468326.9 | M17: 5006807.2 | N17: 1175684.5 | O17: 5147357.7 | P17: 18967216 | Q17: 3212269.8 | R17: 89417675 | S17: 5668430.4 | T17: 11491634 | U17: 1182312.9 | V17: 0 | W17: 44641241 | X17: 18201.966 | Y17: 0 | Z17: 950752.95 | AA17: 25982085 | AB17: 56016927 | AC17: 1842559.4 | AD17: 8168046.6 | AE17: 2245329.7 | AF17: 8729921.1 | AG17: 0 | AH17: 24932328 | AI17: 0 | AJ17: 1427110.4 | AK17: 0 | AL17: 22263.876 | AM17: 594506.54 | AN17: 1559414.4 | AO17: 299666.74 | AP17: 355249.03 | AQ17: 7535102.3 | AR17: 13576792 | AS17: 3824954.7 | AT17: 43046.038 | AU17: 0 | AV17: 0 | AW17: 334470.74 | AX17: 59239461 | AY17: 3711933.7 | AZ17: 163458.1 | BA17: 1626465.6 | BB17: 16533267 | BC17: 75377.67 | BD17: 16215340 | BE17: 320753.48 | BF17: 401045.62 | BG17: 5098726.2 | BH17: 4939475 | BI17: 62866.935 | BJ17: 6606439.1 | BK17: 59415.466 | BL17: 1456960.2 | BM17: 10329566 | BN17: 11364636 | BO17: 6185576.6 | BP17: 816227.91 | BQ17: 1478157 | BR17: 123265.63 | BS17: 36228270 | BT17: 2576223.1 | BU17: 69939280 | BV17: 4908836.3 | BW17: 0 | BX17: 0 | BY17: 82727282 | BZ17: 15625310 | CA17: 1.6224249e+08 | CB17: -5.3895467e+08 | CC17: 0 | CD17: 0 | CE17: 0 | CF17: 0 | CG17: 0 | CH17: 0 | CI17: 115514.43 | CJ17: 0 | CK17: 0 | CL17: 0 | CM17: 0 | CN17: 0
A18: 327 | B18: 111666.89 | C18: 356618.89 | D18: 267583.67 | E18: 7212016.5 | F18: 1048629 | G18: 904132.75 | H18: 1.2558022e+09 | I18: 22246239 | J18: 2.0816017e+08 | K18: 12150170 | L18: 15934195 | M18: 13769881 | N18: 1957593.9 | O18: 21347814 | P18: 57638713 | Q18: 6386872.8 | R18: 6337622.2 | S18: 5006815.7 | T18: 1.641394e+08 | U18: 645780.54 | V18: 0 | W18: 6262754.1 | X18: 11239.334 | Y18: 2903820.7 | Z18: 7337668.8 | AA18: 33613987 | AB18: 1174061.8 | AC18: 4099548.2 | AD18: 1042448.1 | AE18: 5854647.9 | AF18: 7570198.3 | AG18: 0 | AH18: 221968.53 | AI18: 0 | AJ18: 1531097.7 | AK18: 0 | AL18: 0 | AM18: 210485.12 | AN18: 1395938.9 | AO18: 17866.032 | AP18: 5484.0543 | AQ18: 36836573 | AR18: 12072730 | AS18: 583152.22 | AT18: 250417.45 | AU18: 419175.57 | AV18: 0 | AW18: 2029203.3 | AX18: 724624.73 | AY18: 7265966.4 | AZ18: 0 | BA18: 8780700.1 | BB18: 1.2814402e+08 | BC18: 1085253.7 | BD18: 19924089 | BE18: 4021470.9 | BF18: 1111508.1 | BG18: 37287844 | BH18: 37195710 | BI18: 2194034 | BJ18: 6117380.1 | BK18: 132812.94 | BL18: 1581416.5 | BM18: 1317557 | BN18: 40668184 | BO18: 31554435 | BP18: 2778037.9 | BQ18: 27574295 | BR18: 0 | BS18: 33495378 | BT18: 33112813 | BU18: 2.4232298e+08 | BV18: 0 | BW18: 0 | BX18: 0 | BY18: 0 | BZ18: 24311590 | CA18: 1.6396712e+08 | CB18: -6.8913496e+08 | CC18: 0 | CD18: 0 | CE18: 0 | CF18: 0 | CG18: 0 | CH18: 0 | CI18: 0 | CJ18: 0 | CK18: 0 | CL18: 0 | CM18: 0 | CN18: 0
A19: 331 | B19: 608382.21 | C19: 0 | D19: 702593.65 | E19: 5234992.9 | F19: 467311.26 | G19: 28314.88 | H19: 68698697 | I19: 4639064.5 | J19: 14204454 | K19: 3.3471683e+08 | L19: 4.5214161e+08 | M19: 1.8082332e+08 | N19: 24420357 | O19: 1.202101e+08 | P19: 2.2776104e+08 | Q19: 1.0106593e+08 | R19: 38857403 | S19: 25801255 | T19: 63436515 | U19: 911238.87 | V19: 0 | W19: 9862330.3 | X19: 114074.12 | Y19: 21842.668 | Z19: 234266.18 | AA19: 18560815 | AB19: 4805847.4 | AC19: 87768.05 | AD19: 0 | AE19: 0 | AF19: 6788648.2 | AG19: 0 | AH19: 5290335.1 | AI19: 0 | AJ19: 0 | AK19: 0 | AL19: 0 | AM19: 1325475.2 | AN19: 0 | AO19: 96933.355 | AP19: 45593.047 | AQ19: 3664844 | AR19: 7986029.2 | AS19: 0 | AT19: 0 | AU19: 0 | AV19: 0 | AW19: 9947.7269 | AX19: 20965521 | AY19: 793465.69 | AZ19: 0 | BA19: 0 | BB19: 35110038 | BC19: 897630.6 | BD19: 9937329.2 | BE19: 2854924.7 | BF19: 1923903.6 | BG19: 2344698.1 | BH19: 221466.81 | BI19: 171277.8 | BJ19: 3045406.4 | BK19: 206073.92 | BL19: 2693072.4 | BM19: 352478.24 | BN19: 1268031.8 | BO19: 13906577 | BP19: 12230398 | BQ19: 18320918 | BR19: 0 | BS19: 1108988.7 | BT19: 5892455.5 | BU19: 8656074.5 | BV19: 0 | BW19: 0 | BX19: 0 | BY19: 0 | BZ19: 15116557 | CA19: 1.0822717e+08 | CB19: -1.0437993e+09 | CC19: 0 | CD19: 0 | CE19: 0 | CF19: 0 | CG19: 0 | CH19: 0 | CI19: 0 | CJ19: 0 | CK19: 0 | CL19: 0 | CM19: 0 | CN19: 0
A20: 332 | B20: 10478898 | C20: 644635.86 | D20: 1648207 | E20: 12760146 | F20: 845739.34 | G20: 11855695 | H20: 1.1628592e+09 | I20: 52170352 | J20: 18328302 | K20: 16749696 | L20: 2.6445759e+08 | M20: 1.4027614e+08 | N20: 30256213 | O20: 73822204 | P20: 1.5601133e+08 | Q20: 1.7623464e+08 | R20: 54117241 | S20: 19068082 | T20: 4.842764e+08 | U20: 6971523.3 | V20: 155036.39 | W20: 59476235 | X20: 6010797.6 | Y20: 2158861.5 | Z20: 34154559 | AA20: 94830489 | AB20: 22988296 | AC20: 4813408.9 | AD20: 3308143 | AE20: 2279145.4 | AF20: 21273419 | AG20: 4147583.7 | AH20: 4812813.8 | AI20: 25880846 | AJ20: 15662494 | AK20: 3392307.6 | AL20: 2934640.7 | AM20: 4776854.1 | AN20: 10110377 | AO20: 4357511.7 | AP20: 178472.52 | AQ20: 1.2012082e+08 | AR20: 22535097 | AS20: 5704022.2 | AT20: 1145313.6 | AU20: 0 | AV20: 1709416.9 | AW20: 298887.09 | AX20: 18588393 | AY20: 13836318 | AZ20: 396383.67 | BA20: 96169023 | BB20: 1.1553862e+08 | BC20: 10295386 | BD20: 43795663 | BE20: 33349332 | BF20: 4620777.5 | BG20: 4325293.3 | BH20: 14865351 | BI20: 304667.51 | BJ20: 28087418 | BK20: 347883.74 | BL20: 5008022.4 | BM20: 16065605 | BN20: 42713360 | BO20: 72060077 | BP20: 2.4097428e+08 | BQ20: 48687472 | BR20: 8541201.1 | BS20: 53113452 | BT20: 43547037 | BU20: 3.0336902e+08 | BV20: 0 | BW20: 1.2125097e+08 | BX20: 0 | BY20: 0 | BZ20: 56315338 | CA20: 4.6898335e+08 | CB20: -1.6979754e+09 | CC20: 0 | CD20: 0 | CE20: 1395220.4 | CF20: 0 | CG20: 0 | CH20: 0 | CI20: 9250235.9 | CJ20: 0 | CK20: 0 | CL20: 0 | CM20: 4221282 | CN20: 0
A21: 333 | B21: 16792735 | C21: 217789.55 | D21: 1717174.2 | E21: 57892969 | F21: 5163162.5 | G21: 26414176 | H21: 5.0552661e+08 | I21: 9195650.3 | J21: 1464337.1 | K21: 3866763.1 | L21: 41804323 | M21: 2.4454748e+08 | N21: 2620212.7 | O21: 22942564 | P21: 2.4995055e+08 | Q21: 59306801 | R21: 1636291.5 | S21: 4561500.4 | T21: 1.6777686e+08 | U21: 512313.14 | V21: 3203.1541 | W21: 18287307 | X21: 14614218 | Y21: 123606.97 | Z21: 18508636 | AA21: 27794684 | AB21: 28711289 | AC21: 3241418 | AD21: 1991483 | AE21: 1938177.2 | AF21: 8489171.2 | AG21: 93211.84 | AH21: 583117.75 | AI21: 1800470.5 | AJ21: 4654283.9 | AK21: 492616.4 | AL21: 205622.64 | AM21: 1.0134807e+08 | AN21: 20188450 | AO21: 515594.16 | AP21: 132663.3 | AQ21: 13080472 | AR21: 7557209.5 | AS21: 87462.109 | AT21: 232178 | AU21: 7087813.2 | AV21: 0 | AW21: 525084.32 | AX21: 769923.17 | AY21: 6177467.4 | AZ21: 180313.41 | BA21: 1.1963634e+08 | BB21: 69856336 | BC21: 7213401.1 | BD21: 90499652 | BE21: 65604715 | BF21: 22671499 | BG21: 14945916 | BH21: 8255336.4 | BI21: 1651226.3 | BJ21: 1870689.7 | BK21: 224004.33 | BL21: 1717999.7 | BM21: 740412.56 | BN21: 8306169.9 | BO21: 1.1142076e+08 | BP21: 51093568 | BQ21: 10476466 | BR21: 2614838.6 | BS21: 75100361 | BT21: 28562181 | BU21: 1.8945515e+08 | BV21: 0 | BW21: 1.6833261e+09 | BX21: 0 | BY21: 0 | BZ21: 41473378 | CA21: 8.4017066e+08 | CB21: -3.0440352e+09 | CC21: 0 | CD21: 0 | CE21: 0 | CF21: 0 | CG21: 0 | CH21: 0 | CI21: 10300269 | CJ21: 0 | CK21: 0 | CL21: 0 | CM21: 1.7688315e+08 | CN21: 0
... A82: Other | B82: 8880352.3 | C82: 221185.52 | D82: 283359.95 | E82: 492614.92 | F82: 651849.68 | G82: 38866684 | H82: 41314638 | I82: 7063746.5 | J82: 6336349.8 | K82: 5473624.7 | L82: 10469294 | M82: 15608760 | N82: 22791595 | O82: 5898908 | P82: 27617851 | Q82: 14352230 | R82: 3066706.2 | S82: 3980492.8 | T82: 1.3574851e+08 | U82: 3021435.5 | V82: 141126.94 | W82: 12181022 | X82: 4459481.6 | Y82: 16629888 | Z82: 17226775 | AA82: 17152609 | AB82: 1.3665187e+08 | AC82: 3165016.9 | AD82: 12771119 | AE82: 26169698 | AF82: 65573760 | AG82: 4.6509738e+08 | AH82: 2877755.2 | AI82: 66202030 | AJ82: 17951565 | AK82: 332105.79 | AL82: 724798.89 | AM82: 11103773 | AN82: 2019790.1 | AO82: 10068970 | AP82: 4582781.6 | AQ82: 1.2246907e+08 | AR82: 19056287 | AS82: 1.0317544e+08 | AT82: 4.4202326e+08 | AU82: 21779728 | AV82: 11577151 | AW82: 807355.58 | AX82: 16706375 | AY82: 25313687 | AZ82: 4339430.8 | BA82: 1.5115317e+08 | BB82: 1.3273518e+08 | BC82: 64305699 | BD82: 45873693 | BE82: 2104384.1 | BF82: 8751509 | BG82: 0 | BH82: 0 | BI82: 7077479.1 | BJ82: 0 | BK82: 5637586.2 | BL82: 3966501.4 | BM82: 13152432 | BN82: 50038251 | BO82: 1.2486286e+08 | BP82: 4.7705711e+08 | BQ82: 1.3444316e+08 | BR82: 261474.94 | BS82: 0 | BT82: 0 | BU82: -1.9719652e+09 | BV82: 0 | BW82: 0 | BX82: 6.8674569e+08 | BY82: 0 | BZ82: 0 | CA82: 1.4783371e+10 | CB82: -7.3684901e+09 | CC82: 0 | CD82: 0 | CE82: 0 | CF82: 0 | CG82: 0 | CH82: 0 | CI82: 0 | CJ82: 0 | CK82: 0 | CL82: 0 | CM82: 0 | CN82: 0

Sheet Src_Disagg_EIA_coal
A1: Raw EIA Annual Coal Report (Form EIA-7A) 2019 state production values,
A2: used as the numerator for the 212 BEA mining disagg split (05 coal vs
A3: 07T08 other mining). Source:
A4: https://www.eia.gov/coal/annual/
A6: THIS STATE: VA
A9: state | B9: short_tons | C9: short_tons_units | D9: value_usd | E9: source_notes
A10: AL | B10: 12031000 | C10: short tons | D10: 600000000 | E10: EIA Annual Coal Report 2019; AL avg ~$50/ton bituminous
A11: AK | B11: 1000000 | C11: short tons | D11: 40000000 | E11: EIA Annual Coal Report 2019; AK Usibelli ~$40/ton subbit
A12: AZ | B12: 4220000 | C12: short tons | D12: 125000000 | E12: EIA Annual Coal Report 2019; Kayenta mine closed 2019; partial year
A13: AR | B13: 0 | C13: short tons | D13: 0
A14: CA | B14: 0 | C14: short tons | D14: 0
A15: CO | B15: 10710000 | C15: short tons | D15: 330000000 | E15: EIA ~$31/ton
A16: CT | B16: 0 | C16: short tons | D16: 0
A17: DE | B17: 0 | C17: short tons | D17: 0
A18: DC | B18: 0 | C18: short tons | D18: 0
A19: FL | B19: 0 | C19: short tons | D19: 0
A20: GA | B20: 0 | C20: short tons | D20: 0
A21: HI | B21: 0 | C21: short tons | D21: 0
A22: ID | B22: 0 | C22: short tons | D22: 0
A23: IL | B23: 45919000 | C23: short tons | D23: 1950000000 | E23: IL Basin avg ~$42/ton
A24: IN | B24: 28820000 | C24: short tons | D24: 1210000000 | E24: IL Basin avg ~$42/ton
A25: IA | B25: 0 | C25: short tons | D25: 0
A26: KS | B26: 0 | C26: short tons | D26: 0
A27: KY | B27: 36140000 | C27: short tons | D27: 1730000000 | E27: KY split East (Central App ~$58/ton) + West (IL Basin ~$40/ton)
A28: LA | B28: 2720000 | C28: short tons | D28: 60000000 | E28: lignite ~$22/ton
A29: ME | B29: 0 | C29: short tons | D29: 0
A30: MD | B30: 1320000 | C30: short tons | D30: 70000000 | E30: NA Appalachia ~$55/ton
A31: MA | B31: 0 | C31: short tons | D31: 0
A32: MI | B32: 0 | C32: short tons | D32: 0
A33: MN | B33: 0 | C33: short tons | D33: 0
A34: MS | B34: 2800000 | C34: short tons | D34: 65000000 | E34: lignite
A35: MO | B35: 264000 | C35: short tons | D35: 12000000
A36: MT | B36: 38660000 | C36: short tons | D36: 590000000 | E36: PRB subbit ~$14/ton + some bituminous
A37: NE | B37: 0 | C37: short tons | D37: 0
A38: NV | B38: 0 | C38: short tons | D38: 0
A39: NH | B39: 0 | C39: short tons | D39: 0
A40: NJ | B40: 0 | C40: short tons | D40: 0
A41: NM | B41: 10720000 | C41: short tons | D41: 260000000 | E41: San Juan + McKinley ~$24/ton
A42: NY | B42: 0 | C42: short tons | D42: 0
A43: NC | B43: 0 | C43: short tons | D43: 0
...

Sheet Src_Disagg_heuristics
A1: Hand-curated heuristic tables used as layer-3 fallback for BEA 327
A2: (nonmetallic) / 331 (primary metals) / 325 (chemicals) disaggregation
A3: when Census ASM is suppressed and GHGRP lacks coverage.
A5: Sources:
A6: - cement-heavy state list: GHGRP Subpart H 2019 facility presence
A7: + USGS Minerals Yearbook 2019 cement production rankings
A8: - glass-heavy state list: Census ASM 2017 NAICS 3272 top-6 states
A9: - steel_share: Census ASM 2017 NAICS 331 VA breakdown (2021 SUSB
A10: supplement where suppressed) + industry knowledge
A11: - pharma_share: Census ASM 2017 NAICS 325 VA breakdown +
A12: BLS QCEW 2019 NAICS 3254 employment share
A14: See R/build_state_overrides.R for the applied logic.
... A23: 331 / 325 heuristic split shares (used only where Census ASM / GHGRP unavailable):
A25: state | B25: 331_steel_share (-> ISIC 241) | C25: 331_other_share (-> ISIC 242) | D25: 325_pharma_share (-> ISIC 21) | E25: 325_chem_share (-> ISIC 20)
A26: AK | B26: 0.4 | C26: 0.6 | D26: 0.3 | E26: 0.7
A27: AL | B27: 0.7 | C27: 0.3 | D27: 0.15 | E27: 0.85
A28: AR | B28: 0.5 | C28: 0.5 | D28: 0.1 | E28: 0.9
A29: AZ | B29: 0.3 | C29: 0.7 | D29: 0.2 | E29: 0.8
A30: CA | B30: 0.35 | C30: 0.65 | D30: 0.55 | E30: 0.45
A31: CO | B31: 0.5 | C31: 0.5 | D31: 0.3 | E31: 0.7
A32: CT | B32: 0.4 | C32: 0.6 | D32: 0.5 | E32: 0.5
A33: DC | B33: 0.4 | C33: 0.6 | D33: 0.3 | E33: 0.7
A34: DE | B34: 0.5 | C34: 0.5 | D34: 0.4 | E34: 0.6
A35: FL | B35: 0.35 | C35: 0.65 | D35: 0.4 | E35: 0.6
A36: GA | B36: 0.5 | C36: 0.5 | D36: 0.3 | E36: 0.7
A37: HI | B37: 0.4 | C37: 0.6 | D37: 0.3 | E37: 0.7
... A76: WY | B76: 0.3 | C76: 0.7 | D76: 0.1 | E76: 0.9

Sheet Crosswalk_BEA_to_ISIC
A1: BEA Summary (post-disagg) -> 42-ISIC crosswalk, applied to state VA.
A3: Rows with allocation_weight != 1.0 represent BEA sectors that are split
A4: across multiple ISIC codes (e.g. BEA 22 utilities -> 351/352T353/36T39).
A5: State-specific overrides are loaded from crosswalks/state_overrides/<ST>/splits.csv.
A8: BEA_code | B8: BEA_name | C8: ISIC_code | D8: ISIC_name | E8: allocation_weight | F8: notes | G8: source
A9: 111CA | B9: Farms | C9: 01T03 | D9: Agriculture, forestry, fishing | E9: 1
A10: 113FF | B10: Forestry, fishing, related | C10: 01T03 | D10: Agriculture, forestry, fishing | E10: 1
A11: 211 | B11: Oil and gas extraction | C11: 06 | D11: Extraction of crude petroleum and natural gas | E11: 1
A12: 213 | B12: Support activities for mining | C12: 09 | D12: Mining support service activities | E12: 1
A13: 22 | B13: Utilities | C13: 351 | D13: Electricity | E13: 0.72 | F13: BEA 2012 Detail: electric ~72% of 22 output
A14: 22 | B14: Utilities | C14: 352T353 | D14: Gas, steam, AC | E14: 0.2 | F14: BEA Detail: gas distribution ~20%
A15: 22 | B15: Utilities | C15: 36T39 | D15: Water, sewerage, waste | E15: 0.08 | F15: BEA Detail: water/sewage ~8%
A16: 23 | B16: Construction | C16: 41T43 | D16: Construction | E16: 1
A17: 311FT | B17: Food, beverage, tobacco | C17: 10T12 | D17: Food, beverages, tobacco | E17: 1
A18: 313TT | B18: Textile mills and textile product mills | C18: 13T15 | D18: Textiles, apparel, leather | E18: 1
A19: 315AL | B19: Apparel and leather | C19: 13T15 | D19: Textiles, apparel, leather | E19: 1
A20: 321 | B20: Wood products | C20: 16 | D20: Wood and products of wood and cork | E20: 1
A21: 322 | B21: Paper products | C21: 17T18 | D21: Paper products and printing | E21: 1
A22: 323 | B22: Printing and related | C22: 17T18 | D22: Paper products and printing | E22: 1
A23: 324 | B23: Petroleum and coal products | C23: 19 | D23: Coke and refined petroleum products | E23: 0.961 | F23: BEA 2024 Detail: 324110 refineries + 324121/324122 asphalt = ~96.1% of 324 output ($601,241M / $625,936M)
A24: 324 | B24: Petroleum and coal products | C24: 241 | D24: Iron and steel (incl. coal coking) | E24: 0.039 | F24: EPS modeling convention: route NAICS 324190 (Other petroleum and coal products mfg, includes coal coking) to 241 to consolidate coke with iron and steel; matches eps-us national model
A25: 326 | B25: Plastics and rubber products | C25: 22 | D25: Rubber and plastics products | E25: 1
A26: 332 | B26: Fabricated metal products | C26: 25 | D26: Fabricated metal products | E26: 1
A27: 333 | B27: Machinery | C27: 28 | D27: Machinery and equipment n.e.c. | E27: 1
A28: 334 | B28: Computer and electronic products | C28: 26 | D28: Computer, electronic and optical products | E28: 1
A29: 335 | B29: Electrical equipment, appliances | C29: 27 | D29: Electrical equipment | E29: 1
A30: 3361MV | B30: Motor vehicles, bodies, trailers, parts | C30: 29 | D30: Motor vehicles, trailers, semi-trailers | E30: 1
A31: 3364OT | B31: Other transportation equipment | C31: 30 | D31: Other transport equipment | E31: 1
A32: 337 | B32: Furniture and related products | C32: 31T33 | D32: Furniture; other manufacturing; repair | E32: 1
A33: 339 | B33: Miscellaneous manufacturing | C33: 31T33 | D33: Furniture; other manufacturing; repair | E33: 1
A34: 42 | B34: Wholesale trade | C34: 45T47 | D34: Wholesale and retail trade | E34: 1
A35: 441 | B35: Motor vehicle and parts dealers | C35: 45T47 | D35: Wholesale and retail trade | E35: 1
A36: 445 | B36: Food and beverage stores | C36: 45T47 | D36: Wholesale and retail trade | E36: 1
... A43: 485 | B43: Transit and ground passenger | C43: 49T53 | D43: Transportation and storage | E43: 1
A44: 486 | B44: Pipeline transportation | C44: 352T353 | D44: Gas, steam, AC (incl. pipelines per EPS energy-side convention) | E44: 1 | F44: Reclassified from 49T53 (staff decision 2026-07-16): EPS 352T353 = 'energy pipelines and gas processing'; industrial-energy side sources pipeline fuel (AEO T36 / NAICS 486) here, so IO dollars follow. NOTE: diverges from eps-us national io-model (tags 486 -> 49T53); national files to be corrected separately.
A45: 487OS | B45: Other transportation and support | C45: 49T53 | D45: Transportation and storage | E45: 1
A46: 493 | B46: Warehousing and storage | C46: 49T53 | D46: Transportation and storage | E46: 1
A47: 511 | B47: Publishing industries (incl software) | C47: 58T60 | D47: Publishing, audiovisual, broadcasting | E47: 1
A48: 512 | B48: Motion picture and sound recording | C48: 58T60 | D48: Publishing, audiovisual, broadcasting | E48: 1
A49: 513 | B49: Broadcasting and telecom | C49: 58T60 | D49: Publishing, audiovisual, broadcasting | E49: 0.25 | F49: Placeholder ~25/75 broadcast/telecom per \u00a74.6
...

Sheet State_disagg_splits
A1: State-specific disaggregation ratios applied for VA.
A3: Five BEA Summary sectors are split into finer ISIC children. Ratios
A4: come from the layered proxy strategy in the migration plan (sec 4.0):
A5: 1. Pulled-from-source data (EIA-7A, Census ASM, GHGRP) where available
A6: 2. GHGRP emissions proxy where Census is suppressed
A7: 3. Hand-curated heuristic table (from industry knowledge)
A8: 4. National fallback ratio (last resort)
A11: BEA_code | B11: ISIC_code | C11: allocation_weight | D11: source
A12: 212 | B12: 05 | C12: 0.29815543 | D12: coal/(coal+nonfuel) mine-value share, 2012 USD: EIA coal 2019 $552M + USGS T3 nonfuel 2021 $1300M -> coal share 0.298 (applied to stateior 212 $2613M)
A13: 212 | B13: 07T08 | C13: 0.70184457 | D13: coal/(coal+nonfuel) mine-value share, 2012 USD: EIA coal 2019 $552M + USGS T3 nonfuel 2021 $1300M -> coal share 0.298 (applied to stateior 212 $2613M)
A14: 327 | B14: 231 | C14: 0.25 | D14: HEURISTIC (GHGRP Subpart H cement state list + glass industry profile; Census ASM suppressed or missing)
A15: 327 | B15: 239 | C15: 0.75 | D15: HEURISTIC (GHGRP Subpart H cement state list + glass industry profile; Census ASM suppressed or missing)
A16: 331 | B16: 241 | C16: 0.55 | D16: HEURISTIC (no ASM or GHGRP data pulled yet)
A17: 331 | B17: 242 | C17: 0.45 | D17: HEURISTIC (no ASM or GHGRP data pulled yet)
A18: 325 | B18: 20 | C18: 0.65 | D18: HEURISTIC (Census ASM suppressed or unpulled)
A19: 325 | B19: 21 | C19: 0.35 | D19: HEURISTIC (Census ASM suppressed or unpulled)

Sheet NAICS_to_ISIC_Key
A1: Concise NAICS Summary -> ISIC Rev 4 mapping used by this pipeline.
A2: See US Census Bureau NAICS 2017 to ISIC Rev 4 concordance for the full
A3: detail-level mapping:
A4: https://www.census.gov/naics/concordances/2017_NAICS_to_ISIC_4.xlsx
A7: ISIC Rev 4 code | B7: Title (42-ISIC scheme) | C7: BEA Summary sources (examples)
A8: 01T03 | B8: Agriculture, forestry and fishing | C8: 111CA Farms; 113FF Forestry/fishing/related
A9: 05 | B9: Mining of coal and lignite | C9: 212/coal (NAICS 2121)
A10: 06 | B10: Extraction of crude petroleum and natural gas | C10: 211 Oil and gas extraction
A11: 07T08 | B11: Mining of metal ores; other mining and quarrying | C11: 212/other (NAICS 2122+2123)
A12: 09 | B12: Mining support service activities | C12: 213 Support activities for mining
A13: 10T12 | B13: Food products, beverages and tobacco | C13: 311FT Food/beverage/tobacco
A14: 13T15 | B14: Textiles, wearing apparel, leather and related products | C14: 313TT Textile mills; 315AL Apparel/leather
A15: 16 | B15: Wood and products of wood and cork, except furniture | C15: 321 Wood products
A16: 17T18 | B16: Paper products and printing | C16: 322 Paper; 323 Printing
A17: 19 | B17: Coke and refined petroleum products | C17: 324 Petroleum and coal products
A18: 20 | B18: Chemicals and chemical products (excl. pharmaceuticals) | C18: 325/chem (NAICS 3251-3259 excl. 3254)
... A49: 97T98 | B49: Households as employers; undifferentiated production (zero in EPS) | C49: Designed zero row: households as employers (NAICS 814)

Sheet 3_Calc_Gov_ISIC
A1: STEP 1 - read BEA code / ISIC code / weight live from the Crosswalk tab, pull each BEA value from the source tab, then weight it
A2: BEA_code | B2: ISIC_code | C2: allocation_weight | D2: BEA_value_nominal | E2: weighted_nominal
A3: ='Crosswalk_BEA_to_ISIC'!A9 | B3: ='Crosswalk_BEA_to_ISIC'!C9 | C3: ='Crosswalk_BEA_to_ISIC'!E9 | D3: =IFERROR(INDEX('1_Gov_by_BEA'!$B$2:$B$74, MATCH($A3, '1_Gov_by_BEA'!$A$2:$A$74, 0)), 0) | E3: =C3*D3
A4: ='Crosswalk_BEA_to_ISIC'!A10 | B4: ='Crosswalk_BEA_to_ISIC'!C10 | C4: ='Crosswalk_BEA_to_ISIC'!E10 | D4: =IFERROR(INDEX('1_Gov_by_BEA'!$B$2:$B$74, MATCH($A4, '1_Gov_by_BEA'!$A$2:$A$74, 0)), 0) | E4: =C4*D4
A5: ='Crosswalk_BEA_to_ISIC'!A11 | B5: ='Crosswalk_BEA_to_ISIC'!C11 | C5: ='Crosswalk_BEA_to_ISIC'!E11 | D5: =IFERROR(INDEX('1_Gov_by_BEA'!$B$2:$B$74, MATCH($A5, '1_Gov_by_BEA'!$A$2:$A$74, 0)), 0) | E5: =C5*D5
A6: ='Crosswalk_BEA_to_ISIC'!A12 | B6: ='Crosswalk_BEA_to_ISIC'!C12 | C6: ='Crosswalk_BEA_to_ISIC'!E12 | D6: =IFERROR(INDEX('1_Gov_by_BEA'!$B$2:$B$74, MATCH($A6, '1_Gov_by_BEA'!$A$2:$A$74, 0)), 0) | E6: =C6*D6
A7: ='Crosswalk_BEA_to_ISIC'!A13 | B7: ='Crosswalk_BEA_to_ISIC'!C13 | C7: ='Crosswalk_BEA_to_ISIC'!E13 | D7: =IFERROR(INDEX('1_Gov_by_BEA'!$B$2:$B$74, MATCH($A7, '1_Gov_by_BEA'!$A$2:$A$74, 0)), 0) | E7: =C7*D7
A8: ='Crosswalk_BEA_to_ISIC'!A14 | B8: ='Crosswalk_BEA_to_ISIC'!C14 | C8: ='Crosswalk_BEA_to_ISIC'!E14 | D8: =IFERROR(INDEX('1_Gov_by_BEA'!$B$2:$B$74, MATCH($A8, '1_Gov_by_BEA'!$A$2:$A$74, 0)), 0) | E8: =C8*D8
A9: ='Crosswalk_BEA_to_ISIC'!A15 | B9: ='Crosswalk_BEA_to_ISIC'!C15 | C9: ='Crosswalk_BEA_to_ISIC'!E15 | D9: =IFERROR(INDEX('1_Gov_by_BEA'!$B$2:$B$74, MATCH($A9, '1_Gov_by_BEA'!$A$2:$A$74, 0)), 0) | E9: =C9*D9
A10: ='Crosswalk_BEA_to_ISIC'!A16 | B10: ='Crosswalk_BEA_to_ISIC'!C16 | C10: ='Crosswalk_BEA_to_ISIC'!E16 | D10: =IFERROR(INDEX('1_Gov_by_BEA'!$B$2:$B$74, MATCH($A10, '1_Gov_by_BEA'!$A$2:$A$74, 0)), 0) | E10: =C10*D10
A11: ='Crosswalk_BEA_to_ISIC'!A17 | B11: ='Crosswalk_BEA_to_ISIC'!C17 | C11: ='Crosswalk_BEA_to_ISIC'!E17 | D11: =IFERROR(INDEX('1_Gov_by_BEA'!$B$2:$B$74, MATCH($A11, '1_Gov_by_BEA'!$A$2:$A$74, 0)), 0) | E11: =C11*D11
A12: ='Crosswalk_BEA_to_ISIC'!A18 | B12: ='Crosswalk_BEA_to_ISIC'!C18 | C12: ='Crosswalk_BEA_to_ISIC'!E18 | D12: =IFERROR(INDEX('1_Gov_by_BEA'!$B$2:$B$74, MATCH($A12, '1_Gov_by_BEA'!$A$2:$A$74, 0)), 0) | E12: =C12*D12
A13: ='Crosswalk_BEA_to_ISIC'!A19 | B13: ='Crosswalk_BEA_to_ISIC'!C19 | C13: ='Crosswalk_BEA_to_ISIC'!E19 | D13: =IFERROR(INDEX('1_Gov_by_BEA'!$B$2:$B$74, MATCH($A13, '1_Gov_by_BEA'!$A$2:$A$74, 0)), 0) | E13: =C13*D13
A14: ='Crosswalk_BEA_to_ISIC'!A20 | B14: ='Crosswalk_BEA_to_ISIC'!C20 | C14: ='Crosswalk_BEA_to_ISIC'!E20 | D14: =IFERROR(INDEX('1_Gov_by_BEA'!$B$2:$B$74, MATCH($A14, '1_Gov_by_BEA'!$A$2:$A$74, 0)), 0) | E14: =C14*D14
... A81: ='Crosswalk_BEA_to_ISIC'!A87 | B81: ='Crosswalk_BEA_to_ISIC'!C87 | C81: ='Crosswalk_BEA_to_ISIC'!E87 | D81: =IFERROR(INDEX('1_Gov_by_BEA'!$B$2:$B$74, MATCH($A81, '1_Gov_by_BEA'!$A$2:$A$74, 0)), 0) | E81: =C81*D81
A83: STEP 2 - aggregate weighted values to 42 ISIC, then deflate to 2012 USD (Keys!$C$2)
A84: ISIC_code | B84: aggregated_nominal | C84: value_2012USD
A85: 01T03 | B85: =SUMIFS('3_Calc_Gov_ISIC'!$E$3:$E$81, '3_Calc_Gov_ISIC'!$B$3:$B$81, $A85) | C85: =B85/Keys!$C$2
A86: 05 | B86: =SUMIFS('3_Calc_Gov_ISIC'!$E$3:$E$81, '3_Calc_Gov_ISIC'!$B$3:$B$81, $A86) | C86: =B86/Keys!$C$2
A87: 06 | B87: =SUMIFS('3_Calc_Gov_ISIC'!$E$3:$E$81, '3_Calc_Gov_ISIC'!$B$3:$B$81, $A87) | C87: =B87/Keys!$C$2
A88: 07T08 | B88: =SUMIFS('3_Calc_Gov_ISIC'!$E$3:$E$81, '3_Calc_Gov_ISIC'!$B$3:$B$81, $A88) | C88: =B88/Keys!$C$2
A89: 09 | B89: =SUMIFS('3_Calc_Gov_ISIC'!$E$3:$E$81, '3_Calc_Gov_ISIC'!$B$3:$B$81, $A89) | C89: =B89/Keys!$C$2
A90: 10T12 | B90: =SUMIFS('3_Calc_Gov_ISIC'!$E$3:$E$81, '3_Calc_Gov_ISIC'!$B$3:$B$81, $A90) | C90: =B90/Keys!$C$2
A91: 13T15 | B91: =SUMIFS('3_Calc_Gov_ISIC'!$E$3:$E$81, '3_Calc_Gov_ISIC'!$B$3:$B$81, $A91) | C91: =B91/Keys!$C$2
A92: 16 | B92: =SUMIFS('3_Calc_Gov_ISIC'!$E$3:$E$81, '3_Calc_Gov_ISIC'!$B$3:$B$81, $A92) | C92: =B92/Keys!$C$2
A93: 17T18 | B93: =SUMIFS('3_Calc_Gov_ISIC'!$E$3:$E$81, '3_Calc_Gov_ISIC'!$B$3:$B$81, $A93) | C93: =B93/Keys!$C$2
A94: 19 | B94: =SUMIFS('3_Calc_Gov_ISIC'!$E$3:$E$81, '3_Calc_Gov_ISIC'!$B$3:$B$81, $A94) | C94: =B94/Keys!$C$2
A95: 20 | B95: =SUMIFS('3_Calc_Gov_ISIC'!$E$3:$E$81, '3_Calc_Gov_ISIC'!$B$3:$B$81, $A95) | C95: =B95/Keys!$C$2
A96: 21 | B96: =SUMIFS('3_Calc_Gov_ISIC'!$E$3:$E$81, '3_Calc_Gov_ISIC'!$B$3:$B$81, $A96) | C96: =B96/Keys!$C$2
... A126: 97T98 | B126: =SUMIFS('3_Calc_Gov_ISIC'!$E$3:$E$81, '3_Calc_Gov_ISIC'!$B$3:$B$81, $A126) | C126: =B126/Keys!$C$2

Sheet GaHEbIC-government
A1: Unit: USD | B1: 01T03 | C1: 05 | D1: 06 | E1: 07T08 | F1: 09 | G1: 10T12 | H1: 13T15 | I1: 16 | J1: 17T18 | K1: 19 | L1: 20 | M1: 21 | N1: 22 | O1: 231 | P1: 239 | Q1: 241 | R1: 242 | S1: 25 | T1: 26 | U1: 27 | V1: 28 | W1: 29 | X1: 30 | Y1: 31T33 | Z1: 351 | AA1: 352T353 | AB1: 36T39 | AC1: 41T43 | AD1: 45T47 | AE1: 49T53 | AF1: 55T56 | AG1: 58T60 | AH1: 61 | AI1: 62T63 | AJ1: 64T66 | AK1: 68 | AL1: 69T82 | AM1: 84 | AN1: 85 | AO1: 86T88 | AP1: 90T96 | AQ1: 97T98
A2: Government Expenditures | B2: =INDEX('3_Calc_Gov_ISIC'!$C$85:$C$126, MATCH(B$1, '3_Calc_Gov_ISIC'!$A$85:$A$126, 0)) | C2: =INDEX('3_Calc_Gov_ISIC'!$C$85:$C$126, MATCH(C$1, '3_Calc_Gov_ISIC'!$A$85:$A$126, 0)) | D2: =INDEX('3_Calc_Gov_ISIC'!$C$85:$C$126, MATCH(D$1, '3_Calc_Gov_ISIC'!$A$85:$A$126, 0)) | E2: =INDEX('3_Calc_Gov_ISIC'!$C$85:$C$126, MATCH(E$1, '3_Calc_Gov_ISIC'!$A$85:$A$126, 0)) | F2: =INDEX('3_Calc_Gov_ISIC'!$C$85:$C$126, MATCH(F$1, '3_Calc_Gov_ISIC'!$A$85:$A$126, 0)) | G2: =INDEX('3_Calc_Gov_ISIC'!$C$85:$C$126, MATCH(G$1, '3_Calc_Gov_ISIC'!$A$85:$A$126, 0)) | H2: =INDEX('3_Calc_Gov_ISIC'!$C$85:$C$126, MATCH(H$1, '3_Calc_Gov_ISIC'!$A$85:$A$126, 0)) | I2: =INDEX('3_Calc_Gov_ISIC'!$C$85:$C$126, MATCH(I$1, '3_Calc_Gov_ISIC'!$A$85:$A$126, 0)) | ... AQ2: =INDEX('3_Calc_Gov_ISIC'!$C$85:$C$126, MATCH(AQ$1, '3_Calc_Gov_ISIC'!$A$85:$A$126, 0))

Sheet 4_Calc_HH_ISIC
A1: STEP 1 - read BEA code / ISIC code / weight live from the Crosswalk tab, pull each BEA value from the source tab, then weight it
A2: BEA_code | B2: ISIC_code | C2: allocation_weight | D2: BEA_value_nominal | E2: weighted_nominal
A3: ='Crosswalk_BEA_to_ISIC'!A9 | B3: ='Crosswalk_BEA_to_ISIC'!C9 | C3: ='Crosswalk_BEA_to_ISIC'!E9 | D3: =IFERROR(INDEX('2_HH_by_BEA'!$B$2:$B$74, MATCH($A3, '2_HH_by_BEA'!$A$2:$A$74, 0)), 0) | E3: =C3*D3
A4: ='Crosswalk_BEA_to_ISIC'!A10 | B4: ='Crosswalk_BEA_to_ISIC'!C10 | C4: ='Crosswalk_BEA_to_ISIC'!E10 | D4: =IFERROR(INDEX('2_HH_by_BEA'!$B$2:$B$74, MATCH($A4, '2_HH_by_BEA'!$A$2:$A$74, 0)), 0) | E4: =C4*D4
A5: ='Crosswalk_BEA_to_ISIC'!A11 | B5: ='Crosswalk_BEA_to_ISIC'!C11 | C5: ='Crosswalk_BEA_to_ISIC'!E11 | D5: =IFERROR(INDEX('2_HH_by_BEA'!$B$2:$B$74, MATCH($A5, '2_HH_by_BEA'!$A$2:$A$74, 0)), 0) | E5: =C5*D5
A6: ='Crosswalk_BEA_to_ISIC'!A12 | B6: ='Crosswalk_BEA_to_ISIC'!C12 | C6: ='Crosswalk_BEA_to_ISIC'!E12 | D6: =IFERROR(INDEX('2_HH_by_BEA'!$B$2:$B$74, MATCH($A6, '2_HH_by_BEA'!$A$2:$A$74, 0)), 0) | E6: =C6*D6
A7: ='Crosswalk_BEA_to_ISIC'!A13 | B7: ='Crosswalk_BEA_to_ISIC'!C13 | C7: ='Crosswalk_BEA_to_ISIC'!E13 | D7: =IFERROR(INDEX('2_HH_by_BEA'!$B$2:$B$74, MATCH($A7, '2_HH_by_BEA'!$A$2:$A$74, 0)), 0) | E7: =C7*D7
A8: ='Crosswalk_BEA_to_ISIC'!A14 | B8: ='Crosswalk_BEA_to_ISIC'!C14 | C8: ='Crosswalk_BEA_to_ISIC'!E14 | D8: =IFERROR(INDEX('2_HH_by_BEA'!$B$2:$B$74, MATCH($A8, '2_HH_by_BEA'!$A$2:$A$74, 0)), 0) | E8: =C8*D8
A9: ='Crosswalk_BEA_to_ISIC'!A15 | B9: ='Crosswalk_BEA_to_ISIC'!C15 | C9: ='Crosswalk_BEA_to_ISIC'!E15 | D9: =IFERROR(INDEX('2_HH_by_BEA'!$B$2:$B$74, MATCH($A9, '2_HH_by_BEA'!$A$2:$A$74, 0)), 0) | E9: =C9*D9
A10: ='Crosswalk_BEA_to_ISIC'!A16 | B10: ='Crosswalk_BEA_to_ISIC'!C16 | C10: ='Crosswalk_BEA_to_ISIC'!E16 | D10: =IFERROR(INDEX('2_HH_by_BEA'!$B$2:$B$74, MATCH($A10, '2_HH_by_BEA'!$A$2:$A$74, 0)), 0) | E10: =C10*D10
A11: ='Crosswalk_BEA_to_ISIC'!A17 | B11: ='Crosswalk_BEA_to_ISIC'!C17 | C11: ='Crosswalk_BEA_to_ISIC'!E17 | D11: =IFERROR(INDEX('2_HH_by_BEA'!$B$2:$B$74, MATCH($A11, '2_HH_by_BEA'!$A$2:$A$74, 0)), 0) | E11: =C11*D11
A12: ='Crosswalk_BEA_to_ISIC'!A18 | B12: ='Crosswalk_BEA_to_ISIC'!C18 | C12: ='Crosswalk_BEA_to_ISIC'!E18 | D12: =IFERROR(INDEX('2_HH_by_BEA'!$B$2:$B$74, MATCH($A12, '2_HH_by_BEA'!$A$2:$A$74, 0)), 0) | E12: =C12*D12
A13: ='Crosswalk_BEA_to_ISIC'!A19 | B13: ='Crosswalk_BEA_to_ISIC'!C19 | C13: ='Crosswalk_BEA_to_ISIC'!E19 | D13: =IFERROR(INDEX('2_HH_by_BEA'!$B$2:$B$74, MATCH($A13, '2_HH_by_BEA'!$A$2:$A$74, 0)), 0) | E13: =C13*D13
A14: ='Crosswalk_BEA_to_ISIC'!A20 | B14: ='Crosswalk_BEA_to_ISIC'!C20 | C14: ='Crosswalk_BEA_to_ISIC'!E20 | D14: =IFERROR(INDEX('2_HH_by_BEA'!$B$2:$B$74, MATCH($A14, '2_HH_by_BEA'!$A$2:$A$74, 0)), 0) | E14: =C14*D14
... A81: ='Crosswalk_BEA_to_ISIC'!A87 | B81: ='Crosswalk_BEA_to_ISIC'!C87 | C81: ='Crosswalk_BEA_to_ISIC'!E87 | D81: =IFERROR(INDEX('2_HH_by_BEA'!$B$2:$B$74, MATCH($A81, '2_HH_by_BEA'!$A$2:$A$74, 0)), 0) | E81: =C81*D81
A83: STEP 2 - aggregate weighted values to 42 ISIC, then deflate to 2012 USD (Keys!$C$2)
A84: ISIC_code | B84: aggregated_nominal | C84: value_2012USD
A85: 01T03 | B85: =SUMIFS('4_Calc_HH_ISIC'!$E$3:$E$81, '4_Calc_HH_ISIC'!$B$3:$B$81, $A85) | C85: =B85/Keys!$C$2
A86: 05 | B86: =SUMIFS('4_Calc_HH_ISIC'!$E$3:$E$81, '4_Calc_HH_ISIC'!$B$3:$B$81, $A86) | C86: =B86/Keys!$C$2
A87: 06 | B87: =SUMIFS('4_Calc_HH_ISIC'!$E$3:$E$81, '4_Calc_HH_ISIC'!$B$3:$B$81, $A87) | C87: =B87/Keys!$C$2
A88: 07T08 | B88: =SUMIFS('4_Calc_HH_ISIC'!$E$3:$E$81, '4_Calc_HH_ISIC'!$B$3:$B$81, $A88) | C88: =B88/Keys!$C$2
A89: 09 | B89: =SUMIFS('4_Calc_HH_ISIC'!$E$3:$E$81, '4_Calc_HH_ISIC'!$B$3:$B$81, $A89) | C89: =B89/Keys!$C$2
A90: 10T12 | B90: =SUMIFS('4_Calc_HH_ISIC'!$E$3:$E$81, '4_Calc_HH_ISIC'!$B$3:$B$81, $A90) | C90: =B90/Keys!$C$2
A91: 13T15 | B91: =SUMIFS('4_Calc_HH_ISIC'!$E$3:$E$81, '4_Calc_HH_ISIC'!$B$3:$B$81, $A91) | C91: =B91/Keys!$C$2
A92: 16 | B92: =SUMIFS('4_Calc_HH_ISIC'!$E$3:$E$81, '4_Calc_HH_ISIC'!$B$3:$B$81, $A92) | C92: =B92/Keys!$C$2
A93: 17T18 | B93: =SUMIFS('4_Calc_HH_ISIC'!$E$3:$E$81, '4_Calc_HH_ISIC'!$B$3:$B$81, $A93) | C93: =B93/Keys!$C$2
A94: 19 | B94: =SUMIFS('4_Calc_HH_ISIC'!$E$3:$E$81, '4_Calc_HH_ISIC'!$B$3:$B$81, $A94) | C94: =B94/Keys!$C$2
A95: 20 | B95: =SUMIFS('4_Calc_HH_ISIC'!$E$3:$E$81, '4_Calc_HH_ISIC'!$B$3:$B$81, $A95) | C95: =B95/Keys!$C$2
A96: 21 | B96: =SUMIFS('4_Calc_HH_ISIC'!$E$3:$E$81, '4_Calc_HH_ISIC'!$B$3:$B$81, $A96) | C96: =B96/Keys!$C$2
... A126: 97T98 | B126: =SUMIFS('4_Calc_HH_ISIC'!$E$3:$E$81, '4_Calc_HH_ISIC'!$B$3:$B$81, $A126) | C126: =B126/Keys!$C$2

Sheet GaHEbIC-household
A1: Unit: USD | B1: 01T03 | C1: 05 | D1: 06 | E1: 07T08 | F1: 09 | G1: 10T12 | H1: 13T15 | I1: 16 | J1: 17T18 | K1: 19 | L1: 20 | M1: 21 | N1: 22 | O1: 231 | P1: 239 | Q1: 241 | R1: 242 | S1: 25 | T1: 26 | U1: 27 | V1: 28 | W1: 29 | X1: 30 | Y1: 31T33 | Z1: 351 | AA1: 352T353 | AB1: 36T39 | AC1: 41T43 | AD1: 45T47 | AE1: 49T53 | AF1: 55T56 | AG1: 58T60 | AH1: 61 | AI1: 62T63 | AJ1: 64T66 | AK1: 68 | AL1: 69T82 | AM1: 84 | AN1: 85 | AO1: 86T88 | AP1: 90T96 | AQ1: 97T98
A2: Household Expenditures | B2: =INDEX('4_Calc_HH_ISIC'!$C$85:$C$126, MATCH(B$1, '4_Calc_HH_ISIC'!$A$85:$A$126, 0)) | C2: =INDEX('4_Calc_HH_ISIC'!$C$85:$C$126, MATCH(C$1, '4_Calc_HH_ISIC'!$A$85:$A$126, 0)) | D2: =INDEX('4_Calc_HH_ISIC'!$C$85:$C$126, MATCH(D$1, '4_Calc_HH_ISIC'!$A$85:$A$126, 0)) | E2: =INDEX('4_Calc_HH_ISIC'!$C$85:$C$126, MATCH(E$1, '4_Calc_HH_ISIC'!$A$85:$A$126, 0)) | F2: =INDEX('4_Calc_HH_ISIC'!$C$85:$C$126, MATCH(F$1, '4_Calc_HH_ISIC'!$A$85:$A$126, 0)) | G2: =INDEX('4_Calc_HH_ISIC'!$C$85:$C$126, MATCH(G$1, '4_Calc_HH_ISIC'!$A$85:$A$126, 0)) | H2: =INDEX('4_Calc_HH_ISIC'!$C$85:$C$126, MATCH(H$1, '4_Calc_HH_ISIC'!$A$85:$A$126, 0)) | I2: =INDEX('4_Calc_HH_ISIC'!$C$85:$C$126, MATCH(I$1, '4_Calc_HH_ISIC'!$A$85:$A$126, 0)) | ... AQ2: =INDEX('4_Calc_HH_ISIC'!$C$85:$C$126, MATCH(AQ$1, '4_Calc_HH_ISIC'!$A$85:$A$126, 0))
