Workbook

Sheet About
A1: RQSD BAU RPS Qualifying Source Definitions | B1: Virginia | C1: 46256 | K1: Alabama | L1: AL
A2: RQSD RPS Qualifying Source Definitions | B2: =LOOKUP(B1,K1:L50,L1:L50) -> VA | K2: Alaska | L2: AK
K3: Arizona | L3: AZ | M3: TRUE
A4: Source: | B4: see notes | K4: Arkansas | L4: AR
K5: California | L5: CA | M5: TRUE
K6: Colorado | L6: CO | M6: TRUE
K7: Connecticut | L7: CT | M7: TRUE
A8: Notes | K8: Delaware | L8: DE | M8: TRUE
A9: Each U.S. state that has an RPS defines the sources that qualify for that RPS, leading to | K9: Florida | L9: FL
A10: differences between states. Here, we use a "clean energy standard" | K10: Georgia | L10: GA
A11: (counting everything except fossil fuels) as our definition for the BAU case. | K11: Hawaii | L11: HI | M11: TRUE
K12: Idaho | L12: ID
A13: The non-BAU version of this variable supports a boolean policy lever and is intended to be set by the | K13: Illinois | L13: IL | M13: TRUE
A14: model user. The example we include uses only wind, solar, and geothermal. | K14: Indiana | L14: IN
A15: Hydro is excluded because of limited potential for new large hydro and land use impacts. | K15: Iowa | L15: IA | M15: TRUE
A16: Biomass is excluded because it is not truly carbon-neutral, and it has other issues, such as | K16: Kansas | L16: KS
A17: local air quality impacts and land use challenges. | K17: Kentucky | L17: KY
A18: Nuclear is excluded because of the need to manage nuclear waste. | K18: Louisiana | L18: LA
K19: Maine | L19: ME | M19: TRUE
K20: Maryland | L20: MD | M20: TRUE
K21: Massachusetts | L21: MA | M21: TRUE
K22: Michigan | L22: MI | M22: TRUE
K23: Minnesota | L23: MN | M23: TRUE
K24: Mississippi | L24: MS
K25: Missouri | L25: MO | M25: TRUE
K26: Montana | L26: MT
K27: Nebraska | L27: NE
K28: Nevada | L28: NV | M28: TRUE
K29: New Hampshire | L29: NH | M29: TRUE
K30: New Jersey | L30: NJ | M30: TRUE
K31: New Mexico | L31: NM | M31: TRUE
K32: New York | L32: NY | M32: TRUE
K33: North Carolina | L33: NC | M33: TRUE
K34: North Dakota | L34: ND
K35: Ohio | L35: OH
K36: Oklahoma | L36: OK
K37: Oregon | L37: OR | M37: TRUE
K38: Pennsylvania | L38: PA | M38: TRUE
K39: Rhode Island | L39: RI | M39: TRUE
K40: South Carolina | L40: SC
...

Sheet RPS custom
B1: =INDEX(About!$M:$M,MATCH(B2,About!$K:$K,0)) | C1: =INDEX(About!$M:$M,MATCH(C2,About!$K:$K,0)) | D1: =INDEX(About!$M:$M,MATCH(D2,About!$K:$K,0)) -> TRUE | E1: =INDEX(About!$M:$M,MATCH(E2,About!$K:$K,0)) | F1: =INDEX(About!$M:$M,MATCH(F2,About!$K:$K,0)) -> TRUE | G1: =INDEX(About!$M:$M,MATCH(G2,About!$K:$K,0)) -> TRUE | H1: =INDEX(About!$M:$M,MATCH(H2,About!$K:$K,0)) -> TRUE | I1: =INDEX(About!$M:$M,MATCH(I2,About!$K:$K,0)) -> TRUE | ... AY1: =INDEX(About!$M:$M,MATCH(AY2,About!$K:$K,0))
A2: Electricity Source | B2: Alabama | C2: Alaska | D2: Arizona | E2: Arkansas | F2: California | G2: Colorado | H2: Connecticut | I2: Delaware | J2: Florida | K2: Georgia | L2: Hawaii | M2: Idaho | N2: Illinois | O2: Indiana | P2: Iowa | Q2: Kansas | R2: Kentucky | S2: Louisiana | T2: Maine | U2: Maryland | V2: Massachusetts | W2: Michigan | X2: Minnesota | Y2: Mississippi | Z2: Missouri | AA2: Montana | AB2: Nebraska | AC2: Nevada | AD2: New Hampshire | AE2: New Jersey | AF2: New Mexico | AG2: New York | AH2: North Carolina | AI2: North Dakota | AJ2: Ohio | AK2: Oklahoma | AL2: Oregon | AM2: Pennsylvania | AN2: Rhode Island | AO2: South Carolina | AP2: South Dakota | AQ2: Tennessee | AR2: Texas | AS2: Utah | AT2: Vermont | AU2: Virginia | AV2: Washington | AW2: West Virginia | AX2: Wisconsin | AY2: Wyoming
A3: hard coal | B3: 0 | C3: 0 | D3: 0 | E3: 0 | F3: 0 | G3: 0 | H3: 0 | I3: 0 | J3: 0 | K3: 0 | L3: 0 | M3: 0 | N3: 0 | O3: 0 | P3: 0 | Q3: 0 | R3: 0 | S3: 0 | T3: 0 | U3: 0 | V3: 0 | W3: 0 | X3: 0 | Y3: 0 | Z3: 0 | AA3: 0 | AB3: 0 | AC3: 0 | AD3: 0 | AE3: 0 | AF3: 0 | AG3: 0 | AH3: 0 | AI3: 0 | AJ3: 0 | AK3: 0 | AL3: 0 | AM3: 0 | AN3: 0 | AO3: 0 | AP3: 0 | AQ3: 0 | AR3: 0 | AS3: 0 | AT3: 0 | AU3: 0 | AV3: 0 | AW3: 0 | AX3: 0 | AY3: 0
A4: natural gas steam turbine | B4: 0 | C4: 0 | D4: 0 | E4: 0 | F4: 0 | G4: 0 | H4: 0 | I4: 0 | J4: 0 | K4: 0 | L4: 0 | M4: 0 | N4: 0 | O4: 0 | P4: 0 | Q4: 0 | R4: 0 | S4: 0 | T4: 0 | U4: 0 | V4: 0 | W4: 0 | X4: 0 | Y4: 0 | Z4: 0 | AA4: 0 | AB4: 0 | AC4: 0 | AD4: 0 | AE4: 0 | AF4: 0 | AG4: 0 | AH4: 0 | AI4: 0 | AJ4: 0 | AK4: 0 | AL4: 0 | AM4: 0 | AN4: 0 | AO4: 0 | AP4: 0 | AQ4: 0 | AR4: 0 | AS4: 0 | AT4: 0 | AU4: 0 | AV4: 0 | AW4: 0 | AX4: 0 | AY4: 0
A5: natural gas combined cycle | B5: 0 | C5: 0 | D5: 0 | E5: 0 | F5: 0 | G5: 0 | H5: 0 | I5: 0 | J5: 0 | K5: 0 | L5: 0 | M5: 0 | N5: 0 | O5: 0 | P5: 0 | Q5: 0 | R5: 0 | S5: 0 | T5: 0 | U5: 0 | V5: 0 | W5: 0 | X5: 0 | Y5: 0 | Z5: 0 | AA5: 0 | AB5: 0 | AC5: 0 | AD5: 0 | AE5: 0 | AF5: 0 | AG5: 0 | AH5: 0 | AI5: 0 | AJ5: 0 | AK5: 0 | AL5: 0 | AM5: 0 | AN5: 0 | AO5: 0 | AP5: 0 | AQ5: 0 | AR5: 0 | AS5: 0 | AT5: 0 | AU5: 0 | AV5: 0 | AW5: 0 | AX5: 0 | AY5: 0
A6: nuclear | B6: 0 | C6: 0 | D6: 0 | E6: 0 | F6: 0 | G6: 0 | H6: 0 | I6: 0 | J6: 0 | K6: 0 | L6: 0 | M6: 0 | N6: 0 | O6: 0 | P6: 0 | Q6: 0 | R6: 0 | S6: 0 | T6: 0 | U6: 0 | V6: 0 | W6: 0 | X6: 0 | Y6: 0 | Z6: 0 | AA6: 0 | AB6: 0 | AC6: 0 | AD6: 0 | AE6: 0 | AF6: 0 | AG6: 0 | AH6: 0 | AI6: 0 | AJ6: 0 | AK6: 0 | AL6: 0 | AM6: 0 | AN6: 0 | AO6: 0 | AP6: 0 | AQ6: 0 | AR6: 0 | AS6: 0 | AT6: 0 | AU6: 1 | AV6: 0 | AW6: 0 | AX6: 0 | AY6: 0
A7: hydro | B7: 0 | C7: 0 | D7: 1 | E7: 0 | F7: 0 | G7: 1 | H7: 1 | I7: 1 | J7: 0 | K7: 0 | L7: 0 | M7: 0 | N7: 1 | O7: 0 | P7: 0 | Q7: 0 | R7: 0 | S7: 0 | T7: 1 | U7: 1 | V7: 1 | W7: 1 | X7: 1 | Y7: 0 | Z7: 1 | AA7: 0 | AB7: 0 | AC7: 1 | AD7: 1 | AE7: 1 | AF7: 1 | AG7: 1 | AH7: 1 | AI7: 0 | AJ7: 0 | AK7: 0 | AL7: 1 | AM7: 1 | AN7: 1 | AO7: 0 | AP7: 0 | AQ7: 0 | AR7: 1 | AS7: 0 | AT7: 1 | AU7: 1 | AV7: 1 | AW7: 0 | AX7: 1 | AY7: 0
A8: onshore wind | B8: 1 | C8: 1 | D8: 1 | E8: 1 | F8: 1 | G8: 1 | H8: 1 | I8: 1 | J8: 1 | K8: 1 | L8: 1 | M8: 1 | N8: 1 | O8: 1 | P8: 1 | Q8: 1 | R8: 1 | S8: 1 | T8: 1 | U8: 1 | V8: 1 | W8: 1 | X8: 1 | Y8: 1 | Z8: 1 | AA8: 1 | AB8: 1 | AC8: 1 | AD8: 1 | AE8: 1 | AF8: 1 | AG8: 1 | AH8: 1 | AI8: 1 | AJ8: 1 | AK8: 1 | AL8: 1 | AM8: 1 | AN8: 1 | AO8: 1 | AP8: 1 | AQ8: 1 | AR8: 1 | AS8: 1 | AT8: 1 | AU8: 1 | AV8: 1 | AW8: 1 | AX8: 1 | AY8: 1
A9: solar PV | B9: 1 | C9: 1 | D9: 1 | E9: 1 | F9: 1 | G9: 1 | H9: 1 | I9: 1 | J9: 1 | K9: 1 | L9: 1 | M9: 1 | N9: 1 | O9: 1 | P9: 1 | Q9: 1 | R9: 1 | S9: 1 | T9: 1 | U9: 1 | V9: 1 | W9: 1 | X9: 1 | Y9: 1 | Z9: 1 | AA9: 1 | AB9: 1 | AC9: 1 | AD9: 1 | AE9: 1 | AF9: 1 | AG9: 1 | AH9: 1 | AI9: 1 | AJ9: 1 | AK9: 1 | AL9: 1 | AM9: 1 | AN9: 1 | AO9: 1 | AP9: 1 | AQ9: 1 | AR9: 1 | AS9: 1 | AT9: 1 | AU9: 1 | AV9: 1 | AW9: 1 | AX9: 1 | AY9: 1
A10: solar thermal | B10: 1 | C10: 1 | D10: 1 | E10: 1 | F10: 1 | G10: 1 | H10: 1 | I10: 1 | J10: 1 | K10: 1 | L10: 1 | M10: 1 | N10: 1 | O10: 1 | P10: 1 | Q10: 1 | R10: 1 | S10: 1 | T10: 1 | U10: 1 | V10: 1 | W10: 1 | X10: 1 | Y10: 1 | Z10: 1 | AA10: 1 | AB10: 1 | AC10: 1 | AD10: 1 | AE10: 1 | AF10: 1 | AG10: 1 | AH10: 1 | AI10: 1 | AJ10: 1 | AK10: 1 | AL10: 1 | AM10: 1 | AN10: 1 | AO10: 1 | AP10: 1 | AQ10: 1 | AR10: 1 | AS10: 1 | AT10: 1 | AU10: 1 | AV10: 1 | AW10: 1 | AX10: 1 | AY10: 1
A11: biomass | B11: 1 | C11: 1 | D11: 1 | E11: 1 | F11: 1 | G11: 1 | H11: 1 | I11: 1 | J11: 1 | K11: 1 | L11: 1 | M11: 1 | N11: 1 | O11: 1 | P11: 1 | Q11: 1 | R11: 1 | S11: 1 | T11: 1 | U11: 1 | V11: 1 | W11: 1 | X11: 1 | Y11: 1 | Z11: 1 | AA11: 1 | AB11: 1 | AC11: 1 | AD11: 1 | AE11: 1 | AF11: 1 | AG11: 1 | AH11: 1 | AI11: 1 | AJ11: 1 | AK11: 1 | AL11: 1 | AM11: 1 | AN11: 1 | AO11: 1 | AP11: 1 | AQ11: 1 | AR11: 1 | AS11: 1 | AT11: 1 | AU11: 1 | AV11: 1 | AW11: 1 | AX11: 1 | AY11: 1
A12: geothermal | B12: 1 | C12: 1 | D12: 1 | E12: 1 | F12: 1 | G12: 1 | H12: 1 | I12: 1 | J12: 1 | K12: 1 | L12: 1 | M12: 1 | N12: 1 | O12: 1 | P12: 1 | Q12: 1 | R12: 1 | S12: 1 | T12: 1 | U12: 1 | V12: 1 | W12: 1 | X12: 1 | Y12: 1 | Z12: 1 | AA12: 1 | AB12: 1 | AC12: 1 | AD12: 1 | AE12: 1 | AF12: 1 | AG12: 1 | AH12: 1 | AI12: 1 | AJ12: 1 | AK12: 1 | AL12: 1 | AM12: 1 | AN12: 1 | AO12: 1 | AP12: 1 | AQ12: 1 | AR12: 1 | AS12: 1 | AT12: 1 | AU12: 1 | AV12: 1 | AW12: 1 | AX12: 1 | AY12: 1
A13: petroleum | B13: 0 | C13: 0 | D13: 0 | E13: 0 | F13: 0 | G13: 0 | H13: 0 | I13: 0 | J13: 0 | K13: 0 | L13: 0 | M13: 0 | N13: 0 | O13: 0 | P13: 0 | Q13: 0 | R13: 0 | S13: 0 | T13: 0 | U13: 0 | V13: 0 | W13: 0 | X13: 0 | Y13: 0 | Z13: 0 | AA13: 0 | AB13: 0 | AC13: 0 | AD13: 0 | AE13: 0 | AF13: 0 | AG13: 0 | AH13: 0 | AI13: 0 | AJ13: 0 | AK13: 0 | AL13: 0 | AM13: 0 | AN13: 0 | AO13: 0 | AP13: 0 | AQ13: 0 | AR13: 0 | AS13: 0 | AT13: 0 | AU13: 0 | AV13: 0 | AW13: 0 | AX13: 0 | AY13: 0
A14: natural gas peaker | B14: 0 | C14: 0 | D14: 0 | E14: 0 | F14: 0 | G14: 0 | H14: 0 | I14: 0 | J14: 0 | K14: 0 | L14: 0 | M14: 0 | N14: 0 | O14: 0 | P14: 0 | Q14: 0 | R14: 0 | S14: 0 | T14: 0 | U14: 0 | V14: 0 | W14: 0 | X14: 0 | Y14: 0 | Z14: 0 | AA14: 0 | AB14: 0 | AC14: 0 | AD14: 0 | AE14: 0 | AF14: 0 | AG14: 0 | AH14: 0 | AI14: 0 | AJ14: 0 | AK14: 0 | AL14: 0 | AM14: 0 | AN14: 0 | AO14: 0 | AP14: 0 | AQ14: 0 | AR14: 0 | AS14: 0 | AT14: 0 | AU14: 0 | AV14: 0 | AW14: 0 | AX14: 0 | AY14: 0
A15: lignite | B15: =B3 -> 0 | C15: =C3 -> 0 | D15: =D3 -> 0 | E15: =E3 -> 0 | F15: =F3 -> 0 | G15: =G3 -> 0 | H15: =H3 -> 0 | I15: =I3 -> 0 | ... AY15: =AY3 -> 0
A16: offshore wind | B16: 1 | C16: 1 | D16: 1 | E16: 1 | F16: 1 | G16: 1 | H16: 1 | I16: 1 | J16: 1 | K16: 1 | L16: 1 | M16: 1 | N16: 1 | O16: 1 | P16: 1 | Q16: 1 | R16: 1 | S16: 1 | T16: 1 | U16: 1 | V16: 1 | W16: 1 | X16: 1 | Y16: 1 | Z16: 1 | AA16: 1 | AB16: 1 | AC16: 1 | AD16: 1 | AE16: 1 | AF16: 1 | AG16: 1 | AH16: 1 | AI16: 1 | AJ16: 1 | AK16: 1 | AL16: 1 | AM16: 1 | AN16: 1 | AO16: 1 | AP16: 1 | AQ16: 1 | AR16: 1 | AS16: 1 | AT16: 1 | AU16: 1 | AV16: 1 | AW16: 1 | AX16: 1 | AY16: 1
A17: crude oil | B17: 0 | C17: 0 | D17: 0 | E17: 0 | F17: 0 | G17: 0 | H17: 0 | I17: 0 | J17: 0 | K17: 0 | L17: 0 | M17: 0 | N17: 0 | O17: 0 | P17: 0 | Q17: 0 | R17: 0 | S17: 0 | T17: 0 | U17: 0 | V17: 0 | W17: 0 | X17: 0 | Y17: 0 | Z17: 0 | AA17: 0 | AB17: 0 | AC17: 0 | AD17: 0 | AE17: 0 | AF17: 0 | AG17: 0 | AH17: 0 | AI17: 0 | AJ17: 0 | AK17: 0 | AL17: 0 | AM17: 0 | AN17: 0 | AO17: 0 | AP17: 0 | AQ17: 0 | AR17: 0 | AS17: 0 | AT17: 0 | AU17: 0 | AV17: 0 | AW17: 0 | AX17: 0 | AY17: 0
A18: heavy or residual fuel oil | B18: 0 | C18: 0 | D18: 0 | E18: 0 | F18: 0 | G18: 0 | H18: 0 | I18: 0 | J18: 0 | K18: 0 | L18: 0 | M18: 0 | N18: 0 | O18: 0 | P18: 0 | Q18: 0 | R18: 0 | S18: 0 | T18: 0 | U18: 0 | V18: 0 | W18: 0 | X18: 0 | Y18: 0 | Z18: 0 | AA18: 0 | AB18: 0 | AC18: 0 | AD18: 0 | AE18: 0 | AF18: 0 | AG18: 0 | AH18: 0 | AI18: 0 | AJ18: 0 | AK18: 0 | AL18: 0 | AM18: 0 | AN18: 0 | AO18: 0 | AP18: 0 | AQ18: 0 | AR18: 0 | AS18: 0 | AT18: 0 | AU18: 0 | AV18: 0 | AW18: 0 | AX18: 0 | AY18: 0
A19: municipal solid waste | B19: 1 | C19: 1 | D19: 1 | E19: 1 | F19: 1 | G19: 1 | H19: 1 | I19: 1 | J19: 1 | K19: 1 | L19: 1 | M19: 1 | N19: 1 | O19: 1 | P19: 1 | Q19: 1 | R19: 1 | S19: 1 | T19: 1 | U19: 1 | V19: 1 | W19: 1 | X19: 1 | Y19: 1 | Z19: 1 | AA19: 1 | AB19: 1 | AC19: 1 | AD19: 1 | AE19: 1 | AF19: 1 | AG19: 1 | AH19: 1 | AI19: 1 | AJ19: 1 | AK19: 1 | AL19: 1 | AM19: 1 | AN19: 1 | AO19: 1 | AP19: 1 | AQ19: 1 | AR19: 1 | AS19: 1 | AT19: 1 | AU19: 1 | AV19: 1 | AW19: 1 | AX19: 1 | AY19: 1
A20: hard coal w CCS | B20: 0 | C20: 0 | D20: 0 | E20: 0 | F20: 0 | G20: 0 | H20: 0 | I20: 0 | J20: 0 | K20: 0 | L20: 0 | M20: 0 | N20: 0 | O20: 0 | P20: 0 | Q20: 0 | R20: 0 | S20: 0 | T20: 0 | U20: 0 | V20: 0 | W20: 0 | X20: 0 | Y20: 0 | Z20: 0 | AA20: 0 | AB20: 0 | AC20: 0 | AD20: 0 | AE20: 0 | AF20: 0 | AG20: 0 | AH20: 0 | AI20: 0 | AJ20: 0 | AK20: 0 | AL20: 0 | AM20: 0 | AN20: 0 | AO20: 0 | AP20: 0 | AQ20: 0 | AR20: 0 | AS20: 0 | AT20: 0 | AU20: 0 | AV20: 0 | AW20: 0 | AX20: 0 | AY20: 0
A21: natural gas combined cycle w CCS | B21: 0 | C21: 0 | D21: 0 | E21: 0 | F21: 0 | G21: 0 | H21: 0 | I21: 0 | J21: 0 | K21: 0 | L21: 0 | M21: 0 | N21: 0 | O21: 0 | P21: 0 | Q21: 0 | R21: 0 | S21: 0 | T21: 0 | U21: 0 | V21: 0 | W21: 0 | X21: 0 | Y21: 0 | Z21: 0 | AA21: 0 | AB21: 0 | AC21: 0 | AD21: 0 | AE21: 0 | AF21: 0 | AG21: 0 | AH21: 0 | AI21: 0 | AJ21: 0 | AK21: 0 | AL21: 0 | AM21: 0 | AN21: 0 | AO21: 0 | AP21: 0 | AQ21: 0 | AR21: 0 | AS21: 0 | AT21: 0 | AU21: 0 | AV21: 0 | AW21: 0 | AX21: 0 | AY21: 0
A22: biomass w CCS | B22: 0 | C22: 0 | D22: 1 | E22: 0 | F22: 1 | G22: 1 | H22: 1 | I22: 1 | J22: 1 | K22: 1 | L22: 1 | M22: 1 | N22: 1 | O22: 1 | P22: 1 | Q22: 1 | R22: 1 | S22: 1 | T22: 1 | U22: 1 | V22: 1 | W22: 1 | X22: 1 | Y22: 1 | Z22: 1 | AA22: 1 | AB22: 1 | AC22: 1 | AD22: 1 | AE22: 1 | AF22: 1 | AG22: 1 | AH22: 1 | AI22: 1 | AJ22: 1 | AK22: 1 | AL22: 1 | AM22: 1 | AN22: 1 | AO22: 1 | AP22: 1 | AQ22: 1 | AR22: 1 | AS22: 1 | AT22: 1 | AU22: 1 | AV22: 1 | AW22: 1 | AX22: 1 | AY22: 1
A23: lignite w CCS | B23: 0 | C23: 0 | D23: 0 | E23: 0 | F23: 0 | G23: 0 | H23: 0 | I23: 0 | J23: 0 | K23: 0 | L23: 0 | M23: 0 | N23: 0 | O23: 0 | P23: 0 | Q23: 0 | R23: 0 | S23: 0 | T23: 0 | U23: 0 | V23: 0 | W23: 0 | X23: 0 | Y23: 0 | Z23: 0 | AA23: 0 | AB23: 0 | AC23: 0 | AD23: 0 | AE23: 0 | AF23: 0 | AG23: 0 | AH23: 0 | AI23: 0 | AJ23: 0 | AK23: 0 | AL23: 0 | AM23: 0 | AN23: 0 | AO23: 0 | AP23: 0 | AQ23: 0 | AR23: 0 | AS23: 0 | AT23: 0 | AU23: 0 | AV23: 0 | AW23: 0 | AX23: 0 | AY23: 0
A24: small modular reactor | B24: 0 | C24: 0 | D24: 0 | E24: 0 | F24: 0 | G24: 0 | H24: 0 | I24: 0 | J24: 0 | K24: 0 | L24: 0 | M24: 0 | N24: 0 | O24: 0 | P24: 0 | Q24: 0 | R24: 0 | S24: 0 | T24: 0 | U24: 0 | V24: 0 | W24: 0 | X24: 0 | Y24: 0 | Z24: 0 | AA24: 0 | AB24: 0 | AC24: 0 | AD24: 0 | AE24: 0 | AF24: 0 | AG24: 0 | AH24: 0 | AI24: 0 | AJ24: 0 | AK24: 0 | AL24: 0 | AM24: 0 | AN24: 0 | AO24: 0 | AP24: 0 | AQ24: 0 | AR24: 0 | AS24: 0 | AT24: 0 | AU24: 0 | AV24: 0 | AW24: 0 | AX24: 0 | AY24: 0
A25: hydrogen combustion turbine | B25: 0 | C25: 0 | D25: 0 | E25: 0 | F25: 0 | G25: 0 | H25: 0 | I25: 0 | J25: 0 | K25: 0 | L25: 0 | M25: 0 | N25: 0 | O25: 0 | P25: 0 | Q25: 0 | R25: 0 | S25: 0 | T25: 0 | U25: 0 | V25: 0 | W25: 0 | X25: 0 | Y25: 0 | Z25: 0 | AA25: 0 | AB25: 0 | AC25: 0 | AD25: 0 | AE25: 0 | AF25: 0 | AG25: 0 | AH25: 0 | AI25: 0 | AJ25: 0 | AK25: 0 | AL25: 0 | AM25: 0 | AN25: 0 | AO25: 0 | AP25: 0 | AQ25: 0 | AR25: 0 | AS25: 0 | AT25: 0 | AU25: 0 | AV25: 0 | AW25: 0 | AX25: 0 | AY25: 0
A26: hydrogen combined cycle | B26: 0 | C26: 0 | D26: 0 | E26: 0 | F26: 0 | G26: 0 | H26: 0 | I26: 0 | J26: 0 | K26: 0 | L26: 0 | M26: 0 | N26: 0 | O26: 0 | P26: 0 | Q26: 0 | R26: 0 | S26: 0 | T26: 0 | U26: 0 | V26: 0 | W26: 0 | X26: 0 | Y26: 0 | Z26: 0 | AA26: 0 | AB26: 0 | AC26: 0 | AD26: 0 | AE26: 0 | AF26: 0 | AG26: 0 | AH26: 0 | AI26: 0 | AJ26: 0 | AK26: 0 | AL26: 0 | AM26: 0 | AN26: 0 | AO26: 0 | AP26: 0 | AQ26: 0 | AR26: 0 | AS26: 0 | AT26: 0 | AU26: 0 | AV26: 0 | AW26: 0 | AX26: 0 | AY26: 0

Sheet CES custom
B1: =INDEX(About!$M:$M,MATCH(B2,About!$K:$K,0)) | C1: =INDEX(About!$M:$M,MATCH(C2,About!$K:$K,0)) | D1: =INDEX(About!$M:$M,MATCH(D2,About!$K:$K,0)) -> TRUE | E1: =INDEX(About!$M:$M,MATCH(E2,About!$K:$K,0)) | F1: =INDEX(About!$M:$M,MATCH(F2,About!$K:$K,0)) -> TRUE | G1: =INDEX(About!$M:$M,MATCH(G2,About!$K:$K,0)) -> TRUE | H1: =INDEX(About!$M:$M,MATCH(H2,About!$K:$K,0)) -> TRUE | I1: =INDEX(About!$M:$M,MATCH(I2,About!$K:$K,0)) -> TRUE | ... AY1: =INDEX(About!$M:$M,MATCH(AY2,About!$K:$K,0))
A2: Electricity Source | B2: Alabama | C2: Alaska | D2: Arizona | E2: Arkansas | F2: California | G2: Colorado | H2: Connecticut | I2: Delaware | J2: Florida | K2: Georgia | L2: Hawaii | M2: Idaho | N2: Illinois | O2: Indiana | P2: Iowa | Q2: Kansas | R2: Kentucky | S2: Louisiana | T2: Maine | U2: Maryland | V2: Massachusetts | W2: Michigan | X2: Minnesota | Y2: Mississippi | Z2: Missouri | AA2: Montana | AB2: Nebraska | AC2: Nevada | AD2: New Hampshire | AE2: New Jersey | AF2: New Mexico | AG2: New York | AH2: North Carolina | AI2: North Dakota | AJ2: Ohio | AK2: Oklahoma | AL2: Oregon | AM2: Pennsylvania | AN2: Rhode Island | AO2: South Carolina | AP2: South Dakota | AQ2: Tennessee | AR2: Texas | AS2: Utah | AT2: Vermont | AU2: Virginia | AV2: Washington | AW2: West Virginia | AX2: Wisconsin | AY2: Wyoming
A3: hard coal | B3: 0 | C3: 0 | D3: 0 | E3: 0 | F3: 0 | G3: 0 | H3: 0 | I3: 0 | J3: 0 | K3: 0 | L3: 0 | M3: 0 | N3: 0 | O3: 0 | P3: 0 | Q3: 0 | R3: 0 | S3: 0 | T3: 0 | U3: 0 | V3: 0 | W3: 0 | X3: 0 | Y3: 0 | Z3: 0 | AA3: 0 | AB3: 0 | AC3: 0 | AD3: 0 | AE3: 0 | AF3: 0 | AG3: 0 | AH3: 0 | AI3: 0 | AJ3: 0 | AK3: 0 | AL3: 0 | AM3: 0 | AN3: 0 | AO3: 0 | AP3: 0 | AQ3: 0 | AR3: 0 | AS3: 0 | AT3: 0 | AU3: 0 | AV3: 0 | AW3: 0 | AX3: 0 | AY3: 0
A4: natural gas steam turbine | B4: 0 | C4: 0 | D4: 0 | E4: 0 | F4: 0 | G4: 0 | H4: 0 | I4: 0 | J4: 0 | K4: 0 | L4: 0 | M4: 0 | N4: 0 | O4: 0 | P4: 0 | Q4: 0 | R4: 0 | S4: 0 | T4: 0 | U4: 0 | V4: 0 | W4: 0 | X4: 0 | Y4: 0 | Z4: 0 | AA4: 0 | AB4: 0 | AC4: 0 | AD4: 0 | AE4: 0 | AF4: 0 | AG4: 0 | AH4: 0 | AI4: 0 | AJ4: 0 | AK4: 0 | AL4: 0 | AM4: 0 | AN4: 0 | AO4: 0 | AP4: 0 | AQ4: 0 | AR4: 0 | AS4: 0 | AT4: 0 | AU4: 0 | AV4: 0 | AW4: 0 | AX4: 0 | AY4: 0
A5: natural gas combined cycle | B5: 0 | C5: 0 | D5: 0 | E5: 0 | F5: 0 | G5: 0 | H5: 0 | I5: 0 | J5: 0 | K5: 0 | L5: 0 | M5: 0 | N5: 0 | O5: 0 | P5: 0 | Q5: 0 | R5: 0 | S5: 0 | T5: 0 | U5: 0 | V5: 0 | W5: 0 | X5: 0 | Y5: 0 | Z5: 0 | AA5: 0 | AB5: 0 | AC5: 0 | AD5: 0 | AE5: 0 | AF5: 0 | AG5: 0 | AH5: 0 | AI5: 0 | AJ5: 0 | AK5: 0 | AL5: 0 | AM5: 0 | AN5: 0 | AO5: 0 | AP5: 0 | AQ5: 0 | AR5: 0 | AS5: 0 | AT5: 0 | AU5: 0 | AV5: 0 | AW5: 0 | AX5: 0 | AY5: 0
A6: nuclear | B6: 1 | C6: 1 | D6: 1 | E6: 1 | F6: 1 | G6: 1 | H6: 1 | I6: 1 | J6: 1 | K6: 1 | L6: 1 | M6: 1 | N6: 1 | O6: 1 | P6: 1 | Q6: 1 | R6: 1 | S6: 1 | T6: 1 | U6: 1 | V6: 1 | W6: 1 | X6: 1 | Y6: 1 | Z6: 1 | AA6: 1 | AB6: 1 | AC6: 1 | AD6: 1 | AE6: 1 | AF6: 1 | AG6: 1 | AH6: 1 | AI6: 1 | AJ6: 1 | AK6: 1 | AL6: 1 | AM6: 1 | AN6: 1 | AO6: 1 | AP6: 1 | AQ6: 1 | AR6: 1 | AS6: 1 | AT6: 1 | AU6: 1 | AV6: 1 | AW6: 1 | AX6: 1 | AY6: 1
A7: hydro | B7: 1 | C7: 1 | D7: 1 | E7: 1 | F7: 1 | G7: 1 | H7: 1 | I7: 1 | J7: 1 | K7: 1 | L7: 1 | M7: 1 | N7: 1 | O7: 1 | P7: 1 | Q7: 1 | R7: 1 | S7: 1 | T7: 1 | U7: 1 | V7: 1 | W7: 1 | X7: 1 | Y7: 1 | Z7: 1 | AA7: 1 | AB7: 1 | AC7: 1 | AD7: 1 | AE7: 1 | AF7: 1 | AG7: 1 | AH7: 1 | AI7: 1 | AJ7: 1 | AK7: 1 | AL7: 1 | AM7: 1 | AN7: 1 | AO7: 1 | AP7: 1 | AQ7: 1 | AR7: 1 | AS7: 1 | AT7: 1 | AU7: 1 | AV7: 1 | AW7: 1 | AX7: 1 | AY7: 1
A8: onshore wind | B8: 1 | C8: 1 | D8: 1 | E8: 1 | F8: 1 | G8: 1 | H8: 1 | I8: 1 | J8: 1 | K8: 1 | L8: 1 | M8: 1 | N8: 1 | O8: 1 | P8: 1 | Q8: 1 | R8: 1 | S8: 1 | T8: 1 | U8: 1 | V8: 1 | W8: 1 | X8: 1 | Y8: 1 | Z8: 1 | AA8: 1 | AB8: 1 | AC8: 1 | AD8: 1 | AE8: 1 | AF8: 1 | AG8: 1 | AH8: 1 | AI8: 1 | AJ8: 1 | AK8: 1 | AL8: 1 | AM8: 1 | AN8: 1 | AO8: 1 | AP8: 1 | AQ8: 1 | AR8: 1 | AS8: 1 | AT8: 1 | AU8: 1 | AV8: 1 | AW8: 1 | AX8: 1 | AY8: 1
A9: solar PV | B9: 1 | C9: 1 | D9: 1 | E9: 1 | F9: 1 | G9: 1 | H9: 1 | I9: 1 | J9: 1 | K9: 1 | L9: 1 | M9: 1 | N9: 1 | O9: 1 | P9: 1 | Q9: 1 | R9: 1 | S9: 1 | T9: 1 | U9: 1 | V9: 1 | W9: 1 | X9: 1 | Y9: 1 | Z9: 1 | AA9: 1 | AB9: 1 | AC9: 1 | AD9: 1 | AE9: 1 | AF9: 1 | AG9: 1 | AH9: 1 | AI9: 1 | AJ9: 1 | AK9: 1 | AL9: 1 | AM9: 1 | AN9: 1 | AO9: 1 | AP9: 1 | AQ9: 1 | AR9: 1 | AS9: 1 | AT9: 1 | AU9: 1 | AV9: 1 | AW9: 1 | AX9: 1 | AY9: 1
A10: solar thermal | B10: 1 | C10: 1 | D10: 1 | E10: 1 | F10: 1 | G10: 1 | H10: 1 | I10: 1 | J10: 1 | K10: 1 | L10: 1 | M10: 1 | N10: 1 | O10: 1 | P10: 1 | Q10: 1 | R10: 1 | S10: 1 | T10: 1 | U10: 1 | V10: 1 | W10: 1 | X10: 1 | Y10: 1 | Z10: 1 | AA10: 1 | AB10: 1 | AC10: 1 | AD10: 1 | AE10: 1 | AF10: 1 | AG10: 1 | AH10: 1 | AI10: 1 | AJ10: 1 | AK10: 1 | AL10: 1 | AM10: 1 | AN10: 1 | AO10: 1 | AP10: 1 | AQ10: 1 | AR10: 1 | AS10: 1 | AT10: 1 | AU10: 1 | AV10: 1 | AW10: 1 | AX10: 1 | AY10: 1
A11: biomass | B11: 1 | C11: 1 | D11: 1 | E11: 1 | F11: 1 | G11: 1 | H11: 1 | I11: 1 | J11: 1 | K11: 1 | L11: 1 | M11: 1 | N11: 1 | O11: 1 | P11: 1 | Q11: 1 | R11: 1 | S11: 1 | T11: 1 | U11: 1 | V11: 1 | W11: 1 | X11: 1 | Y11: 1 | Z11: 1 | AA11: 1 | AB11: 1 | AC11: 1 | AD11: 1 | AE11: 1 | AF11: 1 | AG11: 1 | AH11: 1 | AI11: 1 | AJ11: 1 | AK11: 1 | AL11: 1 | AM11: 1 | AN11: 1 | AO11: 1 | AP11: 1 | AQ11: 1 | AR11: 1 | AS11: 1 | AT11: 1 | AU11: 1 | AV11: 1 | AW11: 1 | AX11: 1 | AY11: 1
A12: geothermal | B12: 1 | C12: 1 | D12: 1 | E12: 1 | F12: 1 | G12: 1 | H12: 1 | I12: 1 | J12: 1 | K12: 1 | L12: 1 | M12: 1 | N12: 1 | O12: 1 | P12: 1 | Q12: 1 | R12: 1 | S12: 1 | T12: 1 | U12: 1 | V12: 1 | W12: 1 | X12: 1 | Y12: 1 | Z12: 1 | AA12: 1 | AB12: 1 | AC12: 1 | AD12: 1 | AE12: 1 | AF12: 1 | AG12: 1 | AH12: 1 | AI12: 1 | AJ12: 1 | AK12: 1 | AL12: 1 | AM12: 1 | AN12: 1 | AO12: 1 | AP12: 1 | AQ12: 1 | AR12: 1 | AS12: 1 | AT12: 1 | AU12: 1 | AV12: 1 | AW12: 1 | AX12: 1 | AY12: 1
A13: petroleum | B13: 0 | C13: 0 | D13: 0 | E13: 0 | F13: 0 | G13: 0 | H13: 0 | I13: 0 | J13: 0 | K13: 0 | L13: 0 | M13: 0 | N13: 0 | O13: 0 | P13: 0 | Q13: 0 | R13: 0 | S13: 0 | T13: 0 | U13: 0 | V13: 0 | W13: 0 | X13: 0 | Y13: 0 | Z13: 0 | AA13: 0 | AB13: 0 | AC13: 0 | AD13: 0 | AE13: 0 | AF13: 0 | AG13: 0 | AH13: 0 | AI13: 0 | AJ13: 0 | AK13: 0 | AL13: 0 | AM13: 0 | AN13: 0 | AO13: 0 | AP13: 0 | AQ13: 0 | AR13: 0 | AS13: 0 | AT13: 0 | AU13: 0 | AV13: 0 | AW13: 0 | AX13: 0 | AY13: 0
A14: natural gas peaker | B14: 0 | C14: 0 | D14: 0 | E14: 0 | F14: 0 | G14: 0 | H14: 0 | I14: 0 | J14: 0 | K14: 0 | L14: 0 | M14: 0 | N14: 0 | O14: 0 | P14: 0 | Q14: 0 | R14: 0 | S14: 0 | T14: 0 | U14: 0 | V14: 0 | W14: 0 | X14: 0 | Y14: 0 | Z14: 0 | AA14: 0 | AB14: 0 | AC14: 0 | AD14: 0 | AE14: 0 | AF14: 0 | AG14: 0 | AH14: 0 | AI14: 0 | AJ14: 0 | AK14: 0 | AL14: 0 | AM14: 0 | AN14: 0 | AO14: 0 | AP14: 0 | AQ14: 0 | AR14: 0 | AS14: 0 | AT14: 0 | AU14: 0 | AV14: 0 | AW14: 0 | AX14: 0 | AY14: 0
A15: lignite | B15: =B3 -> 0 | C15: =C3 -> 0 | D15: =D3 -> 0 | E15: =E3 -> 0 | F15: =F3 -> 0 | G15: =G3 -> 0 | H15: =H3 -> 0 | I15: =I3 -> 0 | ... AF15: =AF3 -> 0 | AG15: 0 | AH15: =AH3 -> 0 | AI15: =AI3 -> 0 | AJ15: =AJ3 -> 0 | AK15: =AK3 -> 0 | AL15: =AL3 -> 0 | AM15: =AM3 -> 0 | AN15: =AN3 -> 0 | AO15: =AO3 -> 0 | ... AY15: =AY3 -> 0
A16: offshore wind | B16: 1 | C16: 1 | D16: 1 | E16: 1 | F16: 1 | G16: 1 | H16: 1 | I16: 1 | J16: 1 | K16: 1 | L16: 1 | M16: 1 | N16: 1 | O16: 1 | P16: 1 | Q16: 1 | R16: 1 | S16: 1 | T16: 1 | U16: 1 | V16: 1 | W16: 1 | X16: 1 | Y16: 1 | Z16: 1 | AA16: 1 | AB16: 1 | AC16: 1 | AD16: 1 | AE16: 1 | AF16: 1 | AG16: 1 | AH16: 1 | AI16: 1 | AJ16: 1 | AK16: 1 | AL16: 1 | AM16: 1 | AN16: 1 | AO16: 1 | AP16: 1 | AQ16: 1 | AR16: 1 | AS16: 1 | AT16: 1 | AU16: 1 | AV16: 1 | AW16: 1 | AX16: 1 | AY16: 1
A17: crude oil | B17: 0 | C17: 0 | D17: 0 | E17: 0 | F17: 0 | G17: 0 | H17: 0 | I17: 0 | J17: 0 | K17: 0 | L17: 0 | M17: 0 | N17: 0 | O17: 0 | P17: 0 | Q17: 0 | R17: 0 | S17: 0 | T17: 0 | U17: 0 | V17: 0 | W17: 0 | X17: 0 | Y17: 0 | Z17: 0 | AA17: 0 | AB17: 0 | AC17: 0 | AD17: 0 | AE17: 0 | AF17: 0 | AG17: 0 | AH17: 0 | AI17: 0 | AJ17: 0 | AK17: 0 | AL17: 0 | AM17: 0 | AN17: 0 | AO17: 0 | AP17: 0 | AQ17: 0 | AR17: 0 | AS17: 0 | AT17: 0 | AU17: 0 | AV17: 0 | AW17: 0 | AX17: 0 | AY17: 0
A18: heavy or residual fuel oil | B18: 0 | C18: 0 | D18: 0 | E18: 0 | F18: 0 | G18: 0 | H18: 0 | I18: 0 | J18: 0 | K18: 0 | L18: 0 | M18: 0 | N18: 0 | O18: 0 | P18: 0 | Q18: 0 | R18: 0 | S18: 0 | T18: 0 | U18: 0 | V18: 0 | W18: 0 | X18: 0 | Y18: 0 | Z18: 0 | AA18: 0 | AB18: 0 | AC18: 0 | AD18: 0 | AE18: 0 | AF18: 0 | AG18: 0 | AH18: 0 | AI18: 0 | AJ18: 0 | AK18: 0 | AL18: 0 | AM18: 0 | AN18: 0 | AO18: 0 | AP18: 0 | AQ18: 0 | AR18: 0 | AS18: 0 | AT18: 0 | AU18: 0 | AV18: 0 | AW18: 0 | AX18: 0 | AY18: 0
A19: municipal solid waste | B19: 1 | C19: 1 | D19: 1 | E19: 1 | F19: 1 | G19: 1 | H19: 1 | I19: 1 | J19: 1 | K19: 1 | L19: 1 | M19: 1 | N19: 1 | O19: 1 | P19: 1 | Q19: 1 | R19: 1 | S19: 1 | T19: 1 | U19: 1 | V19: 1 | W19: 1 | X19: 1 | Y19: 1 | Z19: 1 | AA19: 1 | AB19: 1 | AC19: 1 | AD19: 1 | AE19: 1 | AF19: 1 | AG19: 1 | AH19: 1 | AI19: 1 | AJ19: 1 | AK19: 1 | AL19: 1 | AM19: 1 | AN19: 1 | AO19: 1 | AP19: 1 | AQ19: 1 | AR19: 1 | AS19: 1 | AT19: 1 | AU19: 1 | AV19: 1 | AW19: 1 | AX19: 1 | AY19: 1
A20: hard coal w CCS | B20: 0 | C20: 0 | D20: 0 | E20: 0 | F20: 0 | G20: 1 | H20: 0 | I20: 0 | J20: 0 | K20: 0 | L20: 0 | M20: 0 | N20: 0 | O20: 0 | P20: 0 | Q20: 0 | R20: 0 | S20: 0 | T20: 0 | U20: 0 | V20: 0 | W20: 1 | X20: 0 | Y20: 0 | Z20: 0 | AA20: 0 | AB20: 0 | AC20: 1 | AD20: 0 | AE20: 0 | AF20: 0 | AG20: 0 | AH20: 1 | AI20: 0 | AJ20: 0 | AK20: 0 | AL20: 1 | AM20: 0 | AN20: 0 | AO20: 0 | AP20: 0 | AQ20: 0 | AR20: 0 | AS20: 0 | AT20: 0 | AU20: 0 | AV20: 0 | AW20: 0 | AX20: 0 | AY20: 0
A21: natural gas combined cycle w CCS | B21: 0 | C21: 0 | D21: 0 | E21: 0 | F21: 0 | G21: 1 | H21: 0 | I21: 0 | J21: 0 | K21: 0 | L21: 0 | M21: 0 | N21: 0 | O21: 0 | P21: 0 | Q21: 0 | R21: 0 | S21: 0 | T21: 0 | U21: 0 | V21: 0 | W21: 1 | X21: 0 | Y21: 0 | Z21: 0 | AA21: 0 | AB21: 0 | AC21: 1 | AD21: 0 | AE21: 0 | AF21: 0 | AG21: 0 | AH21: 1 | AI21: 0 | AJ21: 0 | AK21: 0 | AL21: 1 | AM21: 0 | AN21: 0 | AO21: 0 | AP21: 0 | AQ21: 0 | AR21: 0 | AS21: 0 | AT21: 0 | AU21: 0 | AV21: 0 | AW21: 0 | AX21: 0 | AY21: 0
A22: biomass w CCS | B22: 1 | C22: 1 | D22: 1 | E22: 1 | F22: 1 | G22: 1 | H22: 1 | I22: 1 | J22: 1 | K22: 1 | L22: 1 | M22: 1 | N22: 1 | O22: 1 | P22: 1 | Q22: 1 | R22: 1 | S22: 1 | T22: 1 | U22: 1 | V22: 1 | W22: 1 | X22: 1 | Y22: 1 | Z22: 1 | AA22: 1 | AB22: 1 | AC22: 1 | AD22: 1 | AE22: 1 | AF22: 1 | AG22: 0 | AH22: 1 | AI22: 1 | AJ22: 1 | AK22: 1 | AL22: 1 | AM22: 1 | AN22: 1 | AO22: 1 | AP22: 1 | AQ22: 1 | AR22: 1 | AS22: 1 | AT22: 1 | AU22: 1 | AV22: 1 | AW22: 1 | AX22: 1 | AY22: 1
A23: lignite w CCS | B23: 0 | C23: 0 | D23: 0 | E23: 0 | F23: 0 | G23: 1 | H23: 0 | I23: 0 | J23: 0 | K23: 0 | L23: 0 | M23: 0 | N23: 0 | O23: 0 | P23: 0 | Q23: 0 | R23: 0 | S23: 0 | T23: 0 | U23: 0 | V23: 0 | W23: 0 | X23: 0 | Y23: 0 | Z23: 0 | AA23: 0 | AB23: 0 | AC23: 1 | AD23: 0 | AE23: 0 | AF23: 0 | AG23: 0 | AH23: 1 | AI23: 0 | AJ23: 0 | AK23: 0 | AL23: 1 | AM23: 0 | AN23: 0 | AO23: 0 | AP23: 0 | AQ23: 0 | AR23: 0 | AS23: 0 | AT23: 0 | AU23: 0 | AV23: 0 | AW23: 0 | AX23: 0 | AY23: 0
A24: small modular reactor | B24: 1 | C24: 1 | D24: 1 | E24: 1 | F24: 1 | G24: 1 | H24: 1 | I24: 1 | J24: 1 | K24: 1 | L24: 1 | M24: 1 | N24: 1 | O24: 1 | P24: 1 | Q24: 1 | R24: 1 | S24: 1 | T24: 1 | U24: 1 | V24: 1 | W24: 1 | X24: 1 | Y24: 1 | Z24: 1 | AA24: 1 | AB24: 1 | AC24: 1 | AD24: 1 | AE24: 1 | AF24: 1 | AG24: 1 | AH24: 1 | AI24: 1 | AJ24: 1 | AK24: 1 | AL24: 1 | AM24: 1 | AN24: 1 | AO24: 1 | AP24: 1 | AQ24: 1 | AR24: 1 | AS24: 1 | AT24: 1 | AU24: 1 | AV24: 1 | AW24: 1 | AX24: 1 | AY24: 1
A25: hydrogen combustion turbine | B25: 1 | C25: 1 | D25: 1 | E25: 1 | F25: 1 | G25: 1 | H25: 1 | I25: 1 | J25: 1 | K25: 1 | L25: 1 | M25: 1 | N25: 1 | O25: 1 | P25: 1 | Q25: 1 | R25: 1 | S25: 1 | T25: 1 | U25: 1 | V25: 1 | W25: 1 | X25: 1 | Y25: 1 | Z25: 1 | AA25: 1 | AB25: 1 | AC25: 1 | AD25: 1 | AE25: 1 | AF25: 1 | AG25: 1 | AH25: 1 | AI25: 1 | AJ25: 1 | AK25: 1 | AL25: 1 | AM25: 1 | AN25: 1 | AO25: 1 | AP25: 1 | AQ25: 1 | AR25: 1 | AS25: 1 | AT25: 1 | AU25: 1 | AV25: 1 | AW25: 1 | AX25: 1 | AY25: 1
A26: hydrogen combined cycle | B26: 1 | C26: 1 | D26: 1 | E26: 1 | F26: 1 | G26: 1 | H26: 1 | I26: 1 | J26: 1 | K26: 1 | L26: 1 | M26: 1 | N26: 1 | O26: 1 | P26: 1 | Q26: 1 | R26: 1 | S26: 1 | T26: 1 | U26: 1 | V26: 1 | W26: 1 | X26: 1 | Y26: 1 | Z26: 1 | AA26: 1 | AB26: 1 | AC26: 1 | AD26: 1 | AE26: 1 | AF26: 1 | AG26: 1 | AH26: 1 | AI26: 1 | AJ26: 1 | AK26: 1 | AL26: 1 | AM26: 1 | AN26: 1 | AO26: 1 | AP26: 1 | AQ26: 1 | AR26: 1 | AS26: 1 | AT26: 1 | AU26: 1 | AV26: 1 | AW26: 1 | AX26: 1 | AY26: 1

Sheet summarize state specific
A1: =About!B1 -> Virginia
A2: Qualifies for RPS (Boolean) | B2: RPS | C2: CES
A3: hard coal | B3: =INDEX('RPS custom'!$B$3:$AY$26,MATCH('summarize state specific'!$A3,'RPS custom'!$A$3:$A$26,0),MATCH(About!$B$1,'RPS custom'!$B$2:$AY$2,0)) -> 0 | C3: =INDEX('CES custom'!$B$3:$AY$26,MATCH($A3,'CES custom'!$A$3:$A$26,0),MATCH(About!$B$1,'CES custom'!$B$2:$AY$2,0)) -> 0
A4: natural gas steam turbine | B4: =INDEX('RPS custom'!$B$3:$AY$26,MATCH('summarize state specific'!$A4,'RPS custom'!$A$3:$A$26,0),MATCH(About!$B$1,'RPS custom'!$B$2:$AY$2,0)) -> 0 | C4: =INDEX('CES custom'!$B$3:$AY$26,MATCH($A4,'CES custom'!$A$3:$A$26,0),MATCH(About!$B$1,'CES custom'!$B$2:$AY$2,0)) -> 0
A5: natural gas combined cycle | B5: =INDEX('RPS custom'!$B$3:$AY$26,MATCH('summarize state specific'!$A5,'RPS custom'!$A$3:$A$26,0),MATCH(About!$B$1,'RPS custom'!$B$2:$AY$2,0)) -> 0 | C5: =INDEX('CES custom'!$B$3:$AY$26,MATCH($A5,'CES custom'!$A$3:$A$26,0),MATCH(About!$B$1,'CES custom'!$B$2:$AY$2,0)) -> 0
A6: nuclear | B6: =INDEX('RPS custom'!$B$3:$AY$26,MATCH('summarize state specific'!$A6,'RPS custom'!$A$3:$A$26,0),MATCH(About!$B$1,'RPS custom'!$B$2:$AY$2,0)) -> 1 | C6: =INDEX('CES custom'!$B$3:$AY$26,MATCH($A6,'CES custom'!$A$3:$A$26,0),MATCH(About!$B$1,'CES custom'!$B$2:$AY$2,0)) -> 1
A7: hydro | B7: =INDEX('RPS custom'!$B$3:$AY$26,MATCH('summarize state specific'!$A7,'RPS custom'!$A$3:$A$26,0),MATCH(About!$B$1,'RPS custom'!$B$2:$AY$2,0)) -> 1 | C7: =INDEX('CES custom'!$B$3:$AY$26,MATCH($A7,'CES custom'!$A$3:$A$26,0),MATCH(About!$B$1,'CES custom'!$B$2:$AY$2,0)) -> 1
A8: onshore wind | B8: =INDEX('RPS custom'!$B$3:$AY$26,MATCH('summarize state specific'!$A8,'RPS custom'!$A$3:$A$26,0),MATCH(About!$B$1,'RPS custom'!$B$2:$AY$2,0)) -> 1 | C8: =INDEX('CES custom'!$B$3:$AY$26,MATCH($A8,'CES custom'!$A$3:$A$26,0),MATCH(About!$B$1,'CES custom'!$B$2:$AY$2,0)) -> 1
A9: solar PV | B9: =INDEX('RPS custom'!$B$3:$AY$26,MATCH('summarize state specific'!$A9,'RPS custom'!$A$3:$A$26,0),MATCH(About!$B$1,'RPS custom'!$B$2:$AY$2,0)) -> 1 | C9: =INDEX('CES custom'!$B$3:$AY$26,MATCH($A9,'CES custom'!$A$3:$A$26,0),MATCH(About!$B$1,'CES custom'!$B$2:$AY$2,0)) -> 1
A10: solar thermal | B10: =INDEX('RPS custom'!$B$3:$AY$26,MATCH('summarize state specific'!$A10,'RPS custom'!$A$3:$A$26,0),MATCH(About!$B$1,'RPS custom'!$B$2:$AY$2,0)) -> 1 | C10: =INDEX('CES custom'!$B$3:$AY$26,MATCH($A10,'CES custom'!$A$3:$A$26,0),MATCH(About!$B$1,'CES custom'!$B$2:$AY$2,0)) -> 1
A11: biomass | B11: =INDEX('RPS custom'!$B$3:$AY$26,MATCH('summarize state specific'!$A11,'RPS custom'!$A$3:$A$26,0),MATCH(About!$B$1,'RPS custom'!$B$2:$AY$2,0)) -> 1 | C11: =INDEX('CES custom'!$B$3:$AY$26,MATCH($A11,'CES custom'!$A$3:$A$26,0),MATCH(About!$B$1,'CES custom'!$B$2:$AY$2,0)) -> 1
A12: geothermal | B12: =INDEX('RPS custom'!$B$3:$AY$26,MATCH('summarize state specific'!$A12,'RPS custom'!$A$3:$A$26,0),MATCH(About!$B$1,'RPS custom'!$B$2:$AY$2,0)) -> 1 | C12: =INDEX('CES custom'!$B$3:$AY$26,MATCH($A12,'CES custom'!$A$3:$A$26,0),MATCH(About!$B$1,'CES custom'!$B$2:$AY$2,0)) -> 1
A13: petroleum | B13: =INDEX('RPS custom'!$B$3:$AY$26,MATCH('summarize state specific'!$A13,'RPS custom'!$A$3:$A$26,0),MATCH(About!$B$1,'RPS custom'!$B$2:$AY$2,0)) -> 0 | C13: =INDEX('CES custom'!$B$3:$AY$26,MATCH($A13,'CES custom'!$A$3:$A$26,0),MATCH(About!$B$1,'CES custom'!$B$2:$AY$2,0)) -> 0
A14: natural gas peaker | B14: =INDEX('RPS custom'!$B$3:$AY$26,MATCH('summarize state specific'!$A14,'RPS custom'!$A$3:$A$26,0),MATCH(About!$B$1,'RPS custom'!$B$2:$AY$2,0)) -> 0 | C14: =INDEX('CES custom'!$B$3:$AY$26,MATCH($A14,'CES custom'!$A$3:$A$26,0),MATCH(About!$B$1,'CES custom'!$B$2:$AY$2,0)) -> 0
... A26: hydrogen combined cycle | B26: =INDEX('RPS custom'!$B$3:$AY$26,MATCH('summarize state specific'!$A26,'RPS custom'!$A$3:$A$26,0),MATCH(About!$B$1,'RPS custom'!$B$2:$AY$2,0)) -> 0 | C26: =INDEX('CES custom'!$B$3:$AY$26,MATCH($A26,'CES custom'!$A$3:$A$26,0),MATCH(About!$B$1,'CES custom'!$B$2:$AY$2,0)) -> 1

Sheet BEPQSD-RQSD
A1: Qualifies for RPS (Boolean) | B1: 2021 | C1: 2022 | D1: 2023 | E1: 2024 | F1: 2025 | G1: 2026 | H1: 2027 | I1: 2028 | J1: 2029 | K1: 2030 | L1: 2031 | M1: 2032 | N1: 2033 | O1: 2034 | P1: 2035 | Q1: 2036 | R1: 2037 | S1: 2038 | T1: 2039 | U1: 2040 | V1: 2041 | W1: 2042 | X1: 2043 | Y1: 2044 | Z1: 2045 | AA1: 2046 | AB1: 2047 | AC1: 2048 | AD1: 2049 | AE1: 2050
A2: hard coal | B2: ='summarize state specific'!$B3 -> 0 | C2: ='summarize state specific'!$B3 -> 0 | D2: ='summarize state specific'!$B3 -> 0 | E2: ='summarize state specific'!$B3 -> 0 | F2: ='summarize state specific'!$B3 -> 0 | G2: ='summarize state specific'!$B3 -> 0 | H2: ='summarize state specific'!$B3 -> 0 | I2: ='summarize state specific'!$B3 -> 0 | ... AE2: ='summarize state specific'!$B3 -> 0
A3: natural gas steam turbine | B3: ='summarize state specific'!$B4 -> 0 | C3: ='summarize state specific'!$B4 -> 0 | D3: ='summarize state specific'!$B4 -> 0 | E3: ='summarize state specific'!$B4 -> 0 | F3: ='summarize state specific'!$B4 -> 0 | G3: ='summarize state specific'!$B4 -> 0 | H3: ='summarize state specific'!$B4 -> 0 | I3: ='summarize state specific'!$B4 -> 0 | ... AE3: ='summarize state specific'!$B4 -> 0
A4: natural gas combined cycle | B4: ='summarize state specific'!$B5 -> 0 | C4: ='summarize state specific'!$B5 -> 0 | D4: ='summarize state specific'!$B5 -> 0 | E4: ='summarize state specific'!$B5 -> 0 | F4: ='summarize state specific'!$B5 -> 0 | G4: ='summarize state specific'!$B5 -> 0 | H4: ='summarize state specific'!$B5 -> 0 | I4: ='summarize state specific'!$B5 -> 0 | ... AE4: ='summarize state specific'!$B5 -> 0
A5: nuclear | B5: ='summarize state specific'!$B6 -> 1 | C5: ='summarize state specific'!$B6 -> 1 | D5: ='summarize state specific'!$B6 -> 1 | E5: ='summarize state specific'!$B6 -> 1 | F5: ='summarize state specific'!$B6 -> 1 | G5: ='summarize state specific'!$B6 -> 1 | H5: ='summarize state specific'!$B6 -> 1 | I5: ='summarize state specific'!$B6 -> 1 | ... AE5: ='summarize state specific'!$B6 -> 1
A6: hydro | B6: ='summarize state specific'!$B7 -> 1 | C6: ='summarize state specific'!$B7 -> 1 | D6: ='summarize state specific'!$B7 -> 1 | E6: ='summarize state specific'!$B7 -> 1 | F6: ='summarize state specific'!$B7 -> 1 | G6: ='summarize state specific'!$B7 -> 1 | H6: ='summarize state specific'!$B7 -> 1 | I6: ='summarize state specific'!$B7 -> 1 | ... AE6: ='summarize state specific'!$B7 -> 1
A7: onshore wind | B7: ='summarize state specific'!$B8 -> 1 | C7: ='summarize state specific'!$B8 -> 1 | D7: ='summarize state specific'!$B8 -> 1 | E7: ='summarize state specific'!$B8 -> 1 | F7: ='summarize state specific'!$B8 -> 1 | G7: ='summarize state specific'!$B8 -> 1 | H7: ='summarize state specific'!$B8 -> 1 | I7: ='summarize state specific'!$B8 -> 1 | ... AE7: ='summarize state specific'!$B8 -> 1
A8: solar PV | B8: ='summarize state specific'!$B9 -> 1 | C8: ='summarize state specific'!$B9 -> 1 | D8: ='summarize state specific'!$B9 -> 1 | E8: ='summarize state specific'!$B9 -> 1 | F8: ='summarize state specific'!$B9 -> 1 | G8: ='summarize state specific'!$B9 -> 1 | H8: ='summarize state specific'!$B9 -> 1 | I8: ='summarize state specific'!$B9 -> 1 | ... AE8: ='summarize state specific'!$B9 -> 1
A9: solar thermal | B9: ='summarize state specific'!$B10 -> 1 | C9: ='summarize state specific'!$B10 -> 1 | D9: ='summarize state specific'!$B10 -> 1 | E9: ='summarize state specific'!$B10 -> 1 | F9: ='summarize state specific'!$B10 -> 1 | G9: ='summarize state specific'!$B10 -> 1 | H9: ='summarize state specific'!$B10 -> 1 | I9: ='summarize state specific'!$B10 -> 1 | ... AE9: ='summarize state specific'!$B10 -> 1
A10: biomass | B10: ='summarize state specific'!$B11 -> 1 | C10: ='summarize state specific'!$B11 -> 1 | D10: ='summarize state specific'!$B11 -> 1 | E10: ='summarize state specific'!$B11 -> 1 | F10: ='summarize state specific'!$B11 -> 1 | G10: ='summarize state specific'!$B11 -> 1 | H10: ='summarize state specific'!$B11 -> 1 | I10: ='summarize state specific'!$B11 -> 1 | ... AE10: ='summarize state specific'!$B11 -> 1
A11: geothermal | B11: ='summarize state specific'!$B12 -> 1 | C11: ='summarize state specific'!$B12 -> 1 | D11: ='summarize state specific'!$B12 -> 1 | E11: ='summarize state specific'!$B12 -> 1 | F11: ='summarize state specific'!$B12 -> 1 | G11: ='summarize state specific'!$B12 -> 1 | H11: ='summarize state specific'!$B12 -> 1 | I11: ='summarize state specific'!$B12 -> 1 | ... AE11: ='summarize state specific'!$B12 -> 1
A12: petroleum | B12: ='summarize state specific'!$B13 -> 0 | C12: ='summarize state specific'!$B13 -> 0 | D12: ='summarize state specific'!$B13 -> 0 | E12: ='summarize state specific'!$B13 -> 0 | F12: ='summarize state specific'!$B13 -> 0 | G12: ='summarize state specific'!$B13 -> 0 | H12: ='summarize state specific'!$B13 -> 0 | I12: ='summarize state specific'!$B13 -> 0 | ... AE12: ='summarize state specific'!$B13 -> 0
A13: natural gas peaker | B13: ='summarize state specific'!$B14 -> 0 | C13: ='summarize state specific'!$B14 -> 0 | D13: ='summarize state specific'!$B14 -> 0 | E13: ='summarize state specific'!$B14 -> 0 | F13: ='summarize state specific'!$B14 -> 0 | G13: ='summarize state specific'!$B14 -> 0 | H13: ='summarize state specific'!$B14 -> 0 | I13: ='summarize state specific'!$B14 -> 0 | ... AE13: ='summarize state specific'!$B14 -> 0
... A25: hydrogen combined cycle | B25: ='summarize state specific'!$B26 -> 0 | C25: ='summarize state specific'!$B26 -> 0 | D25: ='summarize state specific'!$B26 -> 0 | E25: ='summarize state specific'!$B26 -> 0 | F25: ='summarize state specific'!$B26 -> 0 | G25: ='summarize state specific'!$B26 -> 0 | H25: ='summarize state specific'!$B26 -> 0 | I25: ='summarize state specific'!$B26 -> 0 | ... AE25: ='summarize state specific'!$B26 -> 0

Sheet BEPQSD-CQSD
A1: Qualifies for RPS (Boolean) | B1: 2021 | C1: 2022 | D1: 2023 | E1: 2024 | F1: 2025 | G1: 2026 | H1: 2027 | I1: 2028 | J1: 2029 | K1: 2030 | L1: 2031 | M1: 2032 | N1: 2033 | O1: 2034 | P1: 2035 | Q1: 2036 | R1: 2037 | S1: 2038 | T1: 2039 | U1: 2040 | V1: 2041 | W1: 2042 | X1: 2043 | Y1: 2044 | Z1: 2045 | AA1: 2046 | AB1: 2047 | AC1: 2048 | AD1: 2049 | AE1: 2050
A2: hard coal | B2: ='summarize state specific'!$C3 -> 0 | C2: ='summarize state specific'!$C3 -> 0 | D2: ='summarize state specific'!$C3 -> 0 | E2: ='summarize state specific'!$C3 -> 0 | F2: ='summarize state specific'!$C3 -> 0 | G2: ='summarize state specific'!$C3 -> 0 | H2: ='summarize state specific'!$C3 -> 0 | I2: ='summarize state specific'!$C3 -> 0 | ... AE2: ='summarize state specific'!$C3 -> 0
A3: natural gas steam turbine | B3: ='summarize state specific'!$C4 -> 0 | C3: ='summarize state specific'!$C4 -> 0 | D3: ='summarize state specific'!$C4 -> 0 | E3: ='summarize state specific'!$C4 -> 0 | F3: ='summarize state specific'!$C4 -> 0 | G3: ='summarize state specific'!$C4 -> 0 | H3: ='summarize state specific'!$C4 -> 0 | I3: ='summarize state specific'!$C4 -> 0 | ... AE3: ='summarize state specific'!$C4 -> 0
A4: natural gas combined cycle | B4: ='summarize state specific'!$C5 -> 0 | C4: ='summarize state specific'!$C5 -> 0 | D4: ='summarize state specific'!$C5 -> 0 | E4: ='summarize state specific'!$C5 -> 0 | F4: ='summarize state specific'!$C5 -> 0 | G4: ='summarize state specific'!$C5 -> 0 | H4: ='summarize state specific'!$C5 -> 0 | I4: ='summarize state specific'!$C5 -> 0 | ... AE4: ='summarize state specific'!$C5 -> 0
A5: nuclear | B5: ='summarize state specific'!$C6 -> 1 | C5: ='summarize state specific'!$C6 -> 1 | D5: ='summarize state specific'!$C6 -> 1 | E5: ='summarize state specific'!$C6 -> 1 | F5: ='summarize state specific'!$C6 -> 1 | G5: ='summarize state specific'!$C6 -> 1 | H5: ='summarize state specific'!$C6 -> 1 | I5: ='summarize state specific'!$C6 -> 1 | ... AE5: ='summarize state specific'!$C6 -> 1
A6: hydro | B6: ='summarize state specific'!$C7 -> 1 | C6: ='summarize state specific'!$C7 -> 1 | D6: ='summarize state specific'!$C7 -> 1 | E6: ='summarize state specific'!$C7 -> 1 | F6: ='summarize state specific'!$C7 -> 1 | G6: ='summarize state specific'!$C7 -> 1 | H6: ='summarize state specific'!$C7 -> 1 | I6: ='summarize state specific'!$C7 -> 1 | ... AE6: ='summarize state specific'!$C7 -> 1
A7: onshore wind | B7: ='summarize state specific'!$C8 -> 1 | C7: ='summarize state specific'!$C8 -> 1 | D7: ='summarize state specific'!$C8 -> 1 | E7: ='summarize state specific'!$C8 -> 1 | F7: ='summarize state specific'!$C8 -> 1 | G7: ='summarize state specific'!$C8 -> 1 | H7: ='summarize state specific'!$C8 -> 1 | I7: ='summarize state specific'!$C8 -> 1 | ... AE7: ='summarize state specific'!$C8 -> 1
A8: solar PV | B8: ='summarize state specific'!$C9 -> 1 | C8: ='summarize state specific'!$C9 -> 1 | D8: ='summarize state specific'!$C9 -> 1 | E8: ='summarize state specific'!$C9 -> 1 | F8: ='summarize state specific'!$C9 -> 1 | G8: ='summarize state specific'!$C9 -> 1 | H8: ='summarize state specific'!$C9 -> 1 | I8: ='summarize state specific'!$C9 -> 1 | ... AE8: ='summarize state specific'!$C9 -> 1
A9: solar thermal | B9: ='summarize state specific'!$C10 -> 1 | C9: ='summarize state specific'!$C10 -> 1 | D9: ='summarize state specific'!$C10 -> 1 | E9: ='summarize state specific'!$C10 -> 1 | F9: ='summarize state specific'!$C10 -> 1 | G9: ='summarize state specific'!$C10 -> 1 | H9: ='summarize state specific'!$C10 -> 1 | I9: ='summarize state specific'!$C10 -> 1 | ... AE9: ='summarize state specific'!$C10 -> 1
A10: biomass | B10: ='summarize state specific'!$C11 -> 1 | C10: ='summarize state specific'!$C11 -> 1 | D10: ='summarize state specific'!$C11 -> 1 | E10: ='summarize state specific'!$C11 -> 1 | F10: ='summarize state specific'!$C11 -> 1 | G10: ='summarize state specific'!$C11 -> 1 | H10: ='summarize state specific'!$C11 -> 1 | I10: ='summarize state specific'!$C11 -> 1 | ... AE10: ='summarize state specific'!$C11 -> 1
A11: geothermal | B11: ='summarize state specific'!$C12 -> 1 | C11: ='summarize state specific'!$C12 -> 1 | D11: ='summarize state specific'!$C12 -> 1 | E11: ='summarize state specific'!$C12 -> 1 | F11: ='summarize state specific'!$C12 -> 1 | G11: ='summarize state specific'!$C12 -> 1 | H11: ='summarize state specific'!$C12 -> 1 | I11: ='summarize state specific'!$C12 -> 1 | ... AE11: ='summarize state specific'!$C12 -> 1
A12: petroleum | B12: ='summarize state specific'!$C13 -> 0 | C12: ='summarize state specific'!$C13 -> 0 | D12: ='summarize state specific'!$C13 -> 0 | E12: ='summarize state specific'!$C13 -> 0 | F12: ='summarize state specific'!$C13 -> 0 | G12: ='summarize state specific'!$C13 -> 0 | H12: ='summarize state specific'!$C13 -> 0 | I12: ='summarize state specific'!$C13 -> 0 | ... AE12: ='summarize state specific'!$C13 -> 0
A13: natural gas peaker | B13: ='summarize state specific'!$C14 -> 0 | C13: ='summarize state specific'!$C14 -> 0 | D13: ='summarize state specific'!$C14 -> 0 | E13: ='summarize state specific'!$C14 -> 0 | F13: ='summarize state specific'!$C14 -> 0 | G13: ='summarize state specific'!$C14 -> 0 | H13: ='summarize state specific'!$C14 -> 0 | I13: ='summarize state specific'!$C14 -> 0 | ... AE13: ='summarize state specific'!$C14 -> 0
... A25: hydrogen combined cycle | B25: ='summarize state specific'!$C26 -> 1 | C25: ='summarize state specific'!$C26 -> 1 | D25: ='summarize state specific'!$C26 -> 1 | E25: ='summarize state specific'!$C26 -> 1 | F25: ='summarize state specific'!$C26 -> 1 | G25: ='summarize state specific'!$C26 -> 1 | H25: ='summarize state specific'!$C26 -> 1 | I25: ='summarize state specific'!$C26 -> 1 | ... AE25: ='summarize state specific'!$C26 -> 1
