Workbook
Name Eno_TM: '[1]1997 Table 1a Modified'!#REF!
Name Eno_TM: '[2]1997 Table 1a Modified'!#REF!
Name Eno_TM: '[1]1997 Table 1a Modified'!#REF!
Name Eno_Tons: '[1]1997 Table 1a Modified'!#REF!
Name Eno_Tons: '[2]1997 Table 1a Modified'!#REF!
Name Eno_Tons: '[1]1997 Table 1a Modified'!#REF!
Name NTS_YR: [3]About!$B$136
Name Sum_T2: '[1]1997 Table 1a Modified'!#REF!
Name Sum_T2: '[2]1997 Table 1a Modified'!#REF!
Name Sum_T2: '[1]1997 Table 1a Modified'!#REF!
Name Sum_TTM: '[1]1997 Table 1a Modified'!#REF!
Name Sum_TTM: '[2]1997 Table 1a Modified'!#REF!
Name Sum_TTM: '[1]1997 Table 1a Modified'!#REF!
Name ti_tbl_50: #REF!
Name ti_tbl_50: #REF!
Name ti_tbl_50: #REF!
Name ti_tbl_69: #REF!
Name ti_tbl_69: #REF!
Name ti_tbl_69: #REF!

Sheet About
A1: BCDTRtSY BAU Cargo Dist Transported Relative to Start Year | B1: Virginia | C1: 46248 | H1: State | I1: Abbr.
B2: =VLOOKUP(B1,H2:I52,2) -> VA | H2: Alabama | I2: AL
A3: Sources: | B3: See Notes section for which vehicle types use which sources | H3: Alaska | I3: AK
B4: EIA | H4: Arizona | I4: AZ
B5: 2025, 2026 | H5: Arkansas | I5: AR
B6: Annual Energy Outlook | H6: California | I6: CA
B7: Alternative Electricity and Transportation | H7: Colorado | I7: CO
B8: https://www.eia.gov/outlooks/aeo/tables_side.php | H8: Connecticut | I8: CT
B9: Tables 7, 36, 46, 47, 49 | H9: Delaware | I9: DE
H10: Florida | I10: FL
B11: Bus adjustment factor, 2020-2025 | H11: Georgia | I11: GA
B12: EPA | H12: Hawaii | I12: HI
B13: 2022 | H13: Idaho | I13: ID
B14: Inventory of U.S. Greenhouse Gas Emissions and Sinks: 1990-2020 | H14: Illinois | I14: IL
B15: https://www.epa.gov/ghgemissions/inventory-us-greenhouse-gas-emissions-and-sinks-1990-2020 | H15: Indiana | I15: IN
B16: Table 3-13 | H16: Iowa | I16: IA
H17: Kansas | I17: KS
A18: Notes | H18: Kentucky | I18: KY
A19: This variable contains ratios of cargo distance transported in each year of the | H19: Louisiana | I19: LA
A20: model run relative to the start year. The start year is the year before the | H20: Maine | I20: ME
A21: first simulated year. So if the first year for which the model outputs data | H21: Maryland | I21: MD
A22: is 2020, the start year is 2019. The start year column does not have to be | H22: Massachusetts | I22: MA
A23: included in the outputs but is retained here for visual clarity. | H23: Michigan | I23: MI
A24: We use AEO 2021 to calculate start year vehicles, as AEO 2021 does not include 2019 data. | H24: Minnesota | I24: MN
H25: Mississippi | I25: MS
A26: We scale by passenger-miles, freight ton-miles, or vehicle-miles where available. | H26: Missouri | I26: MO
A27: (We assume vehicle loading remains constant, so scaling by vehicle-miles is | H27: Montana | I27: MT
A28: identical to scaling by passenger-miles or freight ton-miles.) | H28: Nebraska | I28: NE
H29: Nevada | I29: NV
A30: We classify AEO's light commercial trucks category as well as light-medium and medium duty vehicles | H30: New Hampshire | I30: NH
A31: in "freight LDVs" and heavy duty vehicles in "freight HDVs." | H31: New Jersey | I31: NJ
A32: 2026-08-14: re-anchored to 2025 = 1 on AEO 2026 alone (was mixed AEO2025/AEO2026, which put the editions' level re-benchmark into 2025 as a fake -5.7% LDV travel drop). Population adjustment re-anchored 2024 -> 2025 to match. Approved by Olivia 2026-08-14. | H32: New Mexico | I32: NM
A33: Without any calibration adjustment, the very large dip in passenger air travel in 2020 leads to discrepancies | H33: New York | I33: NY
A34: in energy use between AEO and the EPS outputs given our current methodology. Therefore, we add a calibration | H34: North Carolina | I34: NC
A35: adjustment factor here, which adjusts the BAU aircraft cargo distance so that final aircraft energy use aligns | H35: North Dakota | I35: ND
A36: with the energy use in AEO 2021. | H36: Ohio | I36: OH
H37: Oklahoma | I37: OK
A38: For buses, we choose to use the EPA GHG Inventory to calculate the 2020 value, due to the fact the Inventory | H38: Oregon | I38: OR
A39: reports only a ~20% drop in emissions from buses vs. the AEO which reports a ~50% drop. We then scale back | H39: Pennsylvania | I39: PA
A40: up to AEO values over a period of 5 years. | H40: Rhode Island | I40: RI
...

Sheet Sources
A1: Source citations
A2: Compiled from docs/methodology/*.md and builder scripts. Built 2026-06-04. Per organizational guidance: framed as inputs for staff review. Staff should verify every URL and version against the primary source before incorporating these citations in published work.
A4: 1 | B4: Energy Innovation (internal)
B5: IA reference workbook BCDTRtSY — BAU Cargo Distance Transported Relative to Start Year (national growth curves)
B6: internal eps-us repo: InputData/trans/BCDTRtSY/
B7: BAU Cargo Dist Transported Relative to Start Yr.xlsx — EPS US baseline snapshot, TBD: confirm EPS version with staff
A9: 2 | B9: EIA
B10: Annual Energy Outlook 2026 — Transportation Tables 7, 35, 45, 47, 49 (national growth-rate sources)
B11: https://www.eia.gov/outlooks/aeo/
B12: Tables 7 (Travel Indicators), 35 (Energy Use by Mode), 45 (Car Stock), 47 (Air Travel), 49 (Freight Truck) — embedded verbatim in workbook, April 2026
A14: 3 | B14: EIA
B15: Annual Energy Outlook 2025 — Transportation Tables 7, 35, 45–49 (legacy IA references)
B16: https://www.eia.gov/outlooks/aeo/
B17: Tables 7, 35, 45, 46, 47, 49 — embedded verbatim in workbook (from IA reference, December 2025 release)
A19: 4 | B19: EPA
B20: Inventory of U.S. Greenhouse Gas Emissions and Sinks, Table 3-13 — Transportation Fuel Use by Vehicle Type
B21: https://www.epa.gov/ghgemissions/inventory-us-greenhouse-gas-emissions-and-sinks
B22: EPA GHG Inventory (2022 reporting year, embedded verbatim in IA reference)
A24: 5 | B24: Census Bureau
B25: State Population Totals — Vintage 2025 (NST-EST2025-POP)
B26: https://www.census.gov/programs-surveys/popest/data/tables.html
B27: NST-EST2025-POP.xlsx (annual estimates 2020–2025)
A29: 6 | B29: University of Virginia Weldon Cooper Center for Public Service
B30: National Population Projections (state-level, 2020 base)
B31: https://www.coopercenter.org/national-population-projections
B32: NationalProjections_ProjectedTotalPopulation_2030-2050.xlsx (released July 2024)

Sheet source data>

Sheet EPA_Table 3-13
A1: Table 3-13: CO2 Emissions from Fossil Fuel Combustion in Transportation End-Use Sector (MMT CO2 Eq.)
A3: Fuel/Vehicle Type | B3: 2020 | C3: 2021 | G3: 2021 to 2020 growth rate
A4: Gasolinea | B4: 937 | C4: 1029 | F4: Buses | G4: =SUM(C8,C15,C35,C41,C45)/SUM(B45,B41,B35,B15,B8) -> 1.0416667
A5: Passenger Cars | B5: 328 | C5: 361
A6: Light-Duty Trucks | B6: 566 | C6: 620
A7: Medium- and Heavy-Duty Trucksb | B7: 24 | C7: 27
A8: Buses | B8: 3 | C8: 3
A9: Motorcycles | B9: 7 | C9: 7
A10: Recreational Boatsc | B10: 10 | C10: 11
A11: Distillate Fuel Oil (Diesel)a | B11: 455 | C11: 488
A12: Passenger Cars | B12: 3 | C12: 3
A13: Light-Duty Trucks | B13: 30 | C13: 33
A14: Medium- and Heavy-Duty Trucksb | B14: 353 | C14: 380
A15: Buses | B15: 20 | C15: 21
A16: Rail | B16: 31 | C16: 32
... A50: Biofuels-Biodieselh | B50: 17.7 | C50: 16.1
A51: + Does not exceed 0.05 MMT CO2 Eq.
A52: a On-road fuel consumption data from FHWA Table MF-21 and MF-27 were used to determine total on-road use of motor gasoline and diesel fuel (FHWA 1996 through 2023). Ratios developed from MOVES3 output are used to apportion FHWA fuel consumption data to vehicle type and fuel type (see Annex 3.2 for information about the MOVES model).
A53: b Includes medium- and heavy-duty trucks over 8,500 lbs.
A54: c In 2014, EPA incorporated the NONROAD2008 model into the MOVES model framework. The current Inventory uses the Nonroad component of MOVES3 for years 1999 through 2021. See Annex 3.2 for information about the MOVES model.
A55: d Note that large year over year fluctuations in emission estimates partially reflect nature of data collection for these sources.
A56: e Official estimates exclude emissions from the combustion of both aviation and marine international bunker fuels; however, estimates of international bunker fuel-related emissions are presented for informational purposes.
A57: f Commercial aircraft, as modeled in FAA’s Aviation Environmental Design Tool (AEDT), consists of passenger aircraft, cargo, and other chartered flights.
A58: g Pipelines reflect CO2 emissions from natural gas-powered pipelines transporting natural gas.
A59: h Ethanol and biodiesel estimates are presented for informational purposes only. See Section 3.10 of this chapter and the estimates in Land Use, Land-Use Change, and Forestry (see Chapter 6), in line with IPCC methodological guidance and UNFCCC reporting obligations, for more information on ethanol and biodiesel.
A60: i Transportation sector natural gas and LPG consumption are based on data from EIA (2021b). Prior to the 1990 to 2015 Inventory, data from DOE TEDB were used to estimate each vehicle class’s share of the total natural gas and LPG consumption. Since TEDB does not include estimates for natural gas use by medium and heavy-duty trucks or LPG use by passenger cars, EIA Alternative Fuel Vehicle Data (Browning 2017) is now used to determine each vehicle class’s share of the total natural gas and LPG consumption. These changes were first incorporated in the 1990 to 2016 Inventory and apply to the 1990 to 2021 time period.
A61: j Includes emissions from rail electricity.
A62: k Electricity consumption by passenger cars, light-duty trucks (SUVs), and buses is based on plug-in electric vehicle sales and engine efficiency data, as outlined in Browning (2018a). In prior Inventory years, CO2 emissions from electric vehicle charging were allocated to the residential and commercial sectors. They are now allocated to the transportation sector. These changes apply to the 2010 through 2021 time period.
A63: Notes: This table does not include emissions from non-transportation mobile sources, such as agricultural equipment and construction/mining equipment; it also does not include emissions associated with electricity consumption by pipelines or lubricants used in transportation. In addition, this table does not include CO2 emissions from U.S. Territories, since these are covered in a separate chapter of the Inventory. Totals may not sum due to independent rounding.

Sheet AEO 2025 Table 7
A1: Table 7. Transportation Sector Key Indicators and Delivered Energy Consumption
A2: https://www.eia.gov/outlooks/aeo/data/browser/#/?id=7-AEO2025&cases=alttrnp&sourcekey=0
A3: Fri Dec 05 2025 14:42:41 GMT-0800 (Pacific Standard Time)
A4: Source: U.S. Energy Information Administration
B5: full name | C5: api key | D5: units | E5: 2023 | F5: 2024 | G5: 2025 | H5: 2026 | I5: 2027 | J5: 2028 | K5: 2029 | L5: 2030 | M5: 2031 | N5: 2032 | O5: 2033 | P5: 2034 | Q5: 2035 | R5: 2036 | S5: 2037 | T5: 2038 | U5: 2039 | V5: 2040 | W5: 2041 | X5: 2042 | Y5: 2043 | Z5: 2044 | AA5: 2045 | AB5: 2046 | AC5: 2047 | AD5: 2048 | AE5: 2049 | AF5: 2050 | AG5: Growth (2024-2050)
A6: Key Indicators
A7: Travel Indicators
A8: (billion vehicle miles traveled)
A9: Light-Duty Vehicles less than 8 | B9: 501 pounds | C9: Transportation: Travel Indicators: Light-Duty Vehicles <= 8,500 lbs: Alternative Transportation | D9: AEO.2025.ALTTRNP.KEI_TRV_TRN_NA_LDV_NA_NA_BLNVEHMLS.A | E9: billion vehicle miles | F9: 3013.7297 | G9: 3058.3716 | H9: 3083.4512 | I9: 3100.0171 | J9: 3112.2297 | K9: 3125.5762 | L9: 3140.167 | M9: 3154.0073 | N9: 3161.4351 | O9: 3167.1465 | P9: 3171.917 | Q9: 3174.3567 | R9: 3179.4163 | S9: 3189.5078 | T9: 3202.9607 | U9: 3216.1187 | V9: 3230.5129 | W9: 3244.2317 | X9: 3257.2742 | Y9: 3268.8367 | Z9: 3279.3418 | AA9: 3288.4412 | AB9: 3297.5173 | AC9: 3308.5703 | AD9: 3321.3464 | AE9: 3335.0469 | AF9: 3349.864 | AG9: 0.004
A10: Commercial Light Trucks | B10: Transportation: Travel Indicators: Commercial Light Trucks: Alternative Transportation | C10: AEO.2025.ALTTRNP.KEI_TRV_TRN_NA_CML_NA_NA_BLNVEHMLS.A | D10: billion vehicle miles | F10: 90.234665 | G10: 88.746048 | H10: 87.524918 | I10: 86.879402 | J10: 86.146126 | K10: 85.551414 | L10: 85.088478 | M10: 84.55584 | N10: 84.013214 | O10: 83.542664 | P10: 83.043007 | Q10: 82.538109 | R10: 82.013916 | S10: 81.499672 | T10: 80.976738 | U10: 80.459801 | V10: 79.954575 | W10: 79.410118 | X10: 78.884186 | Y10: 78.326515 | Z10: 77.80687 | AA10: 77.239433 | AB10: 76.680191 | AC10: 76.081207 | AD10: 75.451775 | AE10: 74.792137 | AF10: 74.117767 | AG10: -0.008
A11: Freight Trucks greater than 10 | B11: 000 pounds | C11: Transportation: Travel Indicators: Freight Trucks > 10,000 lbs.: Alternative Transportation | D11: AEO.2025.ALTTRNP.KEI_TRV_TRN_NA_FGHT_NA_NA_BLNVEHMLS.A | E11: billion vehicle miles | F11: 340.05481 | G11: 346.20789 | H11: 350.06781 | I11: 353.52682 | J11: 356.01294 | K11: 358.95523 | L11: 362.11615 | M11: 364.84686 | N11: 367.715 | O11: 370.28033 | P11: 373.22687 | Q11: 376.19421 | R11: 379.62561 | S11: 383.28888 | T11: 386.97992 | U11: 390.32495 | V11: 393.89111 | W11: 397.25488 | X11: 400.59506 | Y11: 403.50134 | Z11: 406.14972 | AA11: 409.08057 | AB11: 411.83875 | AC11: 416.01117 | AD11: 420.09766 | AE11: 423.84226 | AF11: 427.05206 | AG11: 0.009
A12: (billion passenger miles traveled)
A13: Bus Transportation | B13: Transportation: Travel Indicators: Bus: Alternative Transportation | C13: AEO.2025.ALTTRNP.KEI_TRV_TRN_NA_BST_NA_NA_BPM.A | D13: billion passenger miles | F13: 190.78021 | G13: 196.63762 | H13: 200.38203 | I13: 202.76497 | J13: 204.50441 | K13: 205.76622 | L13: 206.65466 | M13: 207.15369 | N13: 207.40228 | O13: 207.54491 | P13: 207.69394 | Q13: 207.71609 | R13: 207.67081 | S13: 207.61053 | T13: 207.42905 | U13: 207.19026 | V13: 206.88676 | W13: 206.52594 | X13: 206.10233 | Y13: 205.65778 | Z13: 205.15973 | AA13: 204.65633 | AB13: 204.09099 | AC13: 203.49281 | AD13: 202.89883 | AE13: 202.30595 | AF13: 201.76945 | AG13: 0.002
A14: Passenger Rail | B14: Transportation: Travel Indicators: Passenger Rail: Alternative Transportation | C14: AEO.2025.ALTTRNP.KEI_TRV_TRN_NA_RLP_NA_NA_BPM.A | D14: billion passenger miles | F14: 25.878023 | G14: 28.773293 | H14: 30.990028 | I14: 32.691128 | J14: 34.018692 | K14: 35.161125 | L14: 36.109001 | M14: 36.852859 | N14: 37.463329 | O14: 37.9645 | P14: 38.458427 | Q14: 38.854378 | R14: 39.233795 | S14: 39.64349 | T14: 40.072304 | U14: 40.454437 | V14: 40.811695 | W14: 41.128437 | X14: 41.427906 | Y14: 41.717632 | Z14: 41.951229 | AA14: 42.199917 | AB14: 42.38929 | AC14: 42.61396 | AD14: 42.893345 | AE14: 43.173431 | AF14: 43.548084 | AG14: 0.02
A15: (billion seat miles available)
A16: Air | B16: Transportation: Travel Indicators: Air: Alternative Transportation | C16: AEO.2025.ALTTRNP.KEI_TRV_TRN_NA_AIR_NA_NA_BLNSEATMLS.A | D16: billion seat miles | F16: 1413.1366 | G16: 1426.5015 | H16: 1461.8976 | I16: 1494.7886 | J16: 1522.1002 | K16: 1551.6201 | L16: 1578.683 | M16: 1601.1815 | N16: 1627.1464 | O16: 1654.8922 | P16: 1681.6215 | Q16: 1711.0176 | R16: 1740.9607 | S16: 1772.7719 | T16: 1806.9364 | U16: 1841.1686 | V16: 1875.4396 | W16: 1909.1254 | X16: 1945.6185 | Y16: 1981.347 | Z16: 2014.7141 | AA16: 2047.4543 | AB16: 2079.6472 | AC16: 2117.3379 | AD16: 2157.5337 | AE16: 2196.0696 | AF16: 2234.0925 | AG16: 0.018
A17: (billion ton miles traveled)
A18: Rail | B18: Transportation: Travel Indicators: Rail: Alternative Transportation | C18: AEO.2025.ALTTRNP.KEI_TRV_TRN_NA_RAIL_NA_NA_BLNTNMLS.A | D18: billion ton miles | F18: 1464.8552 | G18: 1498.5776 | H18: 1462.3732 | I18: 1413.7332 | J18: 1414.1151 | K18: 1410.5652 | L18: 1369.7415 | M18: 1370.1805 | N18: 1305.8112 | O18: 1312.2113 | P18: 1299.8524 | Q18: 1300.421 | R18: 1305.7511 | S18: 1312.3923 | T18: 1330.2866 | U18: 1321.975 | V18: 1328.3295 | W18: 1330.2947 | X18: 1337.3475 | Y18: 1345.2047 | Z18: 1349.7686 | AA18: 1354.5587 | AB18: 1355.686 | AC18: 1370.3556 | AD18: 1382.5275 | AE18: 1392.7019 | AF18: 1397.2123 | AG18: -0.002
A19: Domestic Shipping | B19: Transportation: Travel Indicators: Domestic Shipping: Alternative Transportation | C19: AEO.2025.ALTTRNP.KEI_TRV_TRN_NA_DMT_NA_NA_BLNTNMLS.A | D19: billion ton miles | F19: 458.77335 | G19: 464.89285 | H19: 462.96167 | I19: 460.98572 | J19: 459.37042 | K19: 457.35059 | L19: 454.85974 | M19: 451.94983 | N19: 448.2905 | O19: 446.2366 | P19: 444.57028 | Q19: 442.67673 | R19: 440.63129 | S19: 439.09964 | T19: 437.71414 | U19: 435.98474 | V19: 434.76898 | W19: 433.49097 | X19: 432.2272 | Y19: 430.6734 | Z19: 428.80133 | AA19: 427.06717 | AB19: 425.276 | AC19: 424.65442 | AD19: 423.51385 | AE19: 422.14224 | AF19: 420.62109 | AG19: -0.003 | AH19: =AF19/F19 -> 0.91683856
A20: Energy Efficiency Indicators
A21: (miles per gallon)
A22: New Light-Duty Vehicle CAFE Standard | B22: Transportation: Energy Efficiency Indicators: CAFE Standard: New Light-Duty Vehicle: Alternative Transportation | C22: AEO.2025.ALTTRNP.EFI_CAFES_TRN_HWY_LDTY_NEW_NA_MLSPGLN.A | D22: mpg | F22: 39.271114 | G22: 42.959927 | H22: 47.575771 | I22: 47.493256 | J22: 47.449085 | K22: 47.490925 | L22: 47.59132 | M22: 47.604393 | N22: 47.569965 | O22: 47.492599 | P22: 47.679401 | Q22: 47.648468 | R22: 47.59169 | S22: 47.590065 | T22: 47.59457 | U22: 47.597126 | V22: 47.557652 | W22: 47.536556 | X22: 47.522251 | Y22: 47.527641 | Z22: 47.509605 | AA22: 47.515839 | AB22: 47.499699 | AC22: 47.476486 | AD22: 47.471779 | AE22: 47.466419 | AF22: 47.51144 | AG22: 0.007
A23: New Car | B23: Transportation: Energy Efficiency Indicators: CAFE Standard: New Car: Alternative Transportation | C23: AEO.2025.ALTTRNP.EFI_CAFES_TRN_HWY_CAR_NEW_NA_MLSPGLN.A | D23: mpg | F23: 48.175083 | G23: 52.414536 | H23: 58.241451 | I23: 58.255463 | J23: 58.26667 | K23: 58.284412 | L23: 58.290977 | M23: 58.296238 | N23: 58.292618 | O23: 58.297882 | P23: 58.32222 | Q23: 58.317551 | R23: 58.313091 | S23: 58.312267 | T23: 58.318325 | U23: 58.320648 | V23: 58.313702 | W23: 58.314289 | X23: 58.312122 | Y23: 58.322739 | Z23: 58.317924 | AA23: 58.327766 | AB23: 58.321186 | AC23: 58.318832 | AD23: 58.325527 | AE23: 58.327377 | AF23: 58.347694 | AG23: 0.007
A24: New Light Truck | B24: Transportation: Energy Efficiency Indicators: CAFE Standard: New Light Truck: Alternative Transportation | C24: AEO.2025.ALTTRNP.EFI_CAFES_TRN_HWY_LTRT_NEW_NA_MLSPGLN.A | D24: mpg | F24: 35.086903 | G24: 38.087925 | H24: 42.293404 | I24: 42.265976 | J24: 42.251019 | K24: 42.23045 | L24: 42.21875 | M24: 42.207088 | N24: 42.198193 | O24: 42.188656 | P24: 42.178352 | Q24: 42.170338 | R24: 42.163197 | S24: 42.15712 | T24: 42.150414 | U24: 42.144039 | V24: 42.139084 | W24: 42.13335 | X24: 42.127731 | Y24: 42.121071 | Z24: 42.115974 | AA24: 42.109615 | AB24: 42.105438 | AC24: 42.100983 | AD24: 42.095028 | AE24: 42.089645 | AF24: 42.083157 | AG24: 0.007
A25: Compliance New Light-Duty Vehicle | B25: Transportation: Energy Efficiency Indicators: Compliance: New Light-Duty Vehicle: Alternative Transportation | C25: AEO.2025.ALTTRNP.EFI_CAFEC_TRN_HWY_LDTY_NEW_NA_MLSPGLN.A | D25: mpg | F25: 39.942822 | G25: 43.957706 | H25: 47.924385 | I25: 48.168633 | J25: 48.206814 | K25: 47.845936 | L25: 47.905159 | M25: 48.590633 | N25: 49.493092 | O25: 48.658333 | P25: 49.540321 | Q25: 50.266624 | R25: 50.779812 | S25: 51.219345 | T25: 51.674301 | U25: 52.231579 | V25: 52.558426 | W25: 52.808189 | X25: 52.984974 | Y25: 53.223259 | Z25: 53.34993 | AA25: 53.548645 | AB25: 53.65453 | AC25: 53.715496 | AD25: 53.847446 | AE25: 53.972466 | AF25: 54.298809 | AG25: 0.012
A26: New Car | B26: Transportation: Energy Efficiency Indicators: Compliance: New Car: Alternative Transportation | C26: AEO.2025.ALTTRNP.EFI_CAFEC_TRN_HWY_CAR_NEW_NA_MLSPGLN.A | D26: mpg | F26: 53.113453 | G26: 57.640594 | H26: 63.3256 | I26: 68.261688 | J26: 68.800171 | K26: 66.58007 | L26: 66.17157 | M26: 67.334129 | N26: 70.141273 | O26: 69.02169 | P26: 70.175095 | Q26: 72.345963 | R26: 73.417397 | S26: 74.362701 | T26: 75.273003 | U26: 76.767471 | V26: 77.966553 | W26: 78.546875 | X26: 79.005653 | Y26: 79.448586 | Z26: 79.81424 | AA26: 80.153214 | AB26: 80.456696 | AC26: 80.688454 | AD26: 80.951462 | AE26: 81.205383 | AF26: 81.537048 | AG26: 0.017
A27: New Light Truck | B27: Transportation: Energy Efficiency Indicators: Compliance: New Light Truck: Alternative Transportation | C27: AEO.2025.ALTTRNP.EFI_CAFEC_TRN_HWY_LTRT_NEW_NA_MLSPGLN.A | D27: mpg | F27: 34.459515 | G27: 37.642277 | H27: 41.127472 | I27: 40.267258 | J27: 40.25531 | K27: 40.242519 | L27: 40.218754 | M27: 40.700054 | N27: 41.130524 | O27: 40.5546 | P27: 40.930511 | Q27: 41.310795 | R27: 41.765965 | S27: 42.053349 | T27: 42.351562 | U27: 42.643215 | V27: 42.837719 | W27: 43.033184 | X27: 43.158432 | Y27: 43.308086 | Z27: 43.407925 | AA27: 43.533504 | AB27: 43.621685 | AC27: 43.68882 | AD27: 43.782269 | AE27: 43.872547 | AF27: 44.049908 | AG27: 0.009
A28: Tested New Light-Duty Vehicle | B28: Transportation: Energy Efficiency Indicators: Tested: New Light-Duty Vehicle: Alternative Transportation | C28: AEO.2025.ALTTRNP.EFI_CAFET_TRN_HWY_LDTY_NEW_NA_MLSPGLN.A | D28: mpg | F28: 36.992214 | G28: 40.049953 | H28: 42.808971 | I28: 43.230892 | J28: 44.016903 | K28: 44.308899 | L28: 44.989899 | M28: 45.61496 | N28: 46.454155 | O28: 45.667557 | P28: 46.478081 | Q28: 47.149429 | R28: 47.616024 | S28: 48.020485 | T28: 48.435196 | U28: 48.949013 | V28: 49.253231 | W28: 49.479267 | X28: 49.642773 | Y28: 49.856163 | Z28: 49.976059 | AA28: 50.153816 | AB28: 50.256393 | AC28: 50.313774 | AD28: 50.431538 | AE28: 50.545406 | AF28: 50.836014 | AG28: 0.012
A29: New Car | B29: Transportation: Energy Efficiency Indicators: Tested: New Car: Alternative Transportation | C29: AEO.2025.ALTTRNP.EFI_CAFET_TRN_HWY_CAR_NEW_NA_MLSPGLN.A | D29: mpg | F29: 48.381924 | G29: 51.754009 | H29: 55.653797 | I29: 59.137737 | J29: 61.278339 | K29: 61.308632 | L29: 62.88327 | M29: 63.968285 | N29: 66.642883 | O29: 65.576897 | P29: 66.66021 | Q29: 68.722473 | R29: 69.727547 | S29: 70.61306 | T29: 71.466324 | U29: 72.886696 | V29: 74.021286 | W29: 74.5662 | X29: 74.998436 | Y29: 75.41684 | Z29: 75.761993 | AA29: 76.083054 | AB29: 76.370346 | AC29: 76.590515 | AD29: 76.839706 | AE29: 77.080559 | AF29: 77.395805 | AG29: 0.018
A30: New Light Truck | B30: Transportation: Energy Efficiency Indicators: Tested: New Light Truck: Alternative Transportation | C30: AEO.2025.ALTTRNP.EFI_CAFET_TRN_HWY_LTRT_NEW_NA_MLSPGLN.A | D30: mpg | F30: 32.114288 | G30: 34.514839 | H30: 36.986862 | I30: 36.634201 | J30: 37.092926 | K30: 37.343777 | L30: 37.577011 | M30: 38.011017 | N30: 38.403038 | O30: 37.869068 | P30: 38.209908 | Q30: 38.555424 | R30: 38.963661 | S30: 39.224598 | T30: 39.495064 | U30: 39.75996 | V30: 39.93721 | W30: 40.114799 | X30: 40.230305 | Y30: 40.36813 | Z30: 40.460381 | AA30: 40.576187 | AB30: 40.657494 | AC30: 40.719509 | AD30: 40.805653 | AE30: 40.888672 | AF30: 41.051575 | AG30: 0.009
A31: On-Road New Light-Duty Vehicle | B31: Transportation: Energy Efficiency Indicators: On-Road New Light-Duty Vehicle: Alternative Transportation | C31: AEO.2025.ALTTRNP.EFI_CAFEO_TRN_HWY_LDTY_NEW_NA_MLSPGLN.A | D31: mpg | F31: 27.538565 | G31: 29.747971 | H31: 31.720669 | I31: 32.058968 | J31: 32.641983 | K31: 32.859589 | L31: 33.335556 | M31: 33.78616 | N31: 34.398438 | O31: 33.841164 | P31: 34.423504 | Q31: 34.90659 | R31: 35.2328 | S31: 35.521309 | T31: 35.816288 | U31: 36.185467 | V31: 36.402821 | W31: 36.561584 | X31: 36.675686 | Y31: 36.824799 | Z31: 36.907936 | AA31: 37.031731 | AB31: 37.102467 | AC31: 37.140446 | AD31: 37.221237 | AE31: 37.299519 | AF31: 37.503345 | AG31: 0.012
A32: New Car | B32: Transportation: Energy Efficiency Indicators: On-Road New Car: Alternative Transportation | C32: AEO.2025.ALTTRNP.EFI_CAFEO_TRN_HWY_CAR_NEW_NA_MLSPGLN.A | D32: mpg | F32: 35.736515 | G32: 38.187515 | H32: 41.026562 | I32: 43.567795 | J32: 45.12907 | K32: 45.143227 | L32: 46.28548 | M32: 47.069462 | N32: 49.029163 | O32: 48.263416 | P32: 49.0424 | Q32: 50.544037 | R32: 51.270535 | S32: 51.909389 | T32: 52.522804 | U32: 53.556107 | V32: 54.379284 | W32: 54.76899 | X32: 55.077839 | Y32: 55.373089 | Z32: 55.619442 | AA32: 55.844055 | AB32: 56.048706 | AC32: 56.203579 | AD32: 56.377033 | AE32: 56.545631 | AF32: 56.762432 | AG32: 0.018
A33: New Light Truck | B33: Transportation: Energy Efficiency Indicators: On-Road New Light Truck: Alternative Transportation | C33: AEO.2025.ALTTRNP.EFI_CAFEO_TRN_HWY_LTRT_NEW_NA_MLSPGLN.A | D33: mpg | F33: 23.988018 | G33: 25.717506 | H33: 27.470898 | I33: 27.24152 | J33: 27.584202 | K33: 27.775764 | L33: 27.919968 | M33: 28.231255 | N33: 28.51063 | O33: 28.137867 | P33: 28.37771 | Q33: 28.619431 | R33: 28.901937 | S33: 29.085546 | T33: 29.275507 | U33: 29.461161 | V33: 29.584818 | W33: 29.708748 | X33: 29.788166 | Y33: 29.883118 | Z33: 29.9464 | AA33: 30.026072 | AB33: 30.081591 | AC33: 30.123497 | AD33: 30.182156 | AE33: 30.238665 | AF33: 30.351025 | AG33: 0.009
... A37: Freight Truck | B37: Transportation: Energy Efficiency Indicators: Freight Truck: Alternative Transportation | C37: AEO.2025.ALTTRNP.EFI_NA_TRN_HWY_FRTT_STK_NA_MLSPGLN.A | D37: mpg | F37: 7.757023 | G37: 7.826031 | H37: 7.906292 | I37: 7.996029 | J37: 8.094789 | K37: 8.199175 | L37: 8.307471 | M37: 8.417607 | N37: 8.528322 | O37: 8.63801 | P37: 8.745068 | Q37: 8.847067 | R37: 8.942054 | S37: 9.029954 | T37: 9.112733 | U37: 9.191482 | V37: 9.266891 | W37: 9.337207 | X37: 9.402058 | Y37: 9.46137 | Z37: 9.51621 | AA37: 9.569106 | AB37: 9.620891 | AC37: 9.670567 | AD37: 9.716979 | AE37: 9.761371 | AF37: 9.804544 | AG37: 0.009
A38: (seat miles per gallon)
A39: Aircraft | B39: Transportation: Energy Efficiency Indicators: Aircraft: Alternative Transportation | C39: AEO.2025.ALTTRNP.EFI_NA_TRN_NA_AIRC_NA_NA_SEATMPG.A | D39: seat mpg | F39: 85.368492 | G39: 85.782234 | H39: 86.453064 | I39: 87.12735 | J39: 87.815926 | K39: 88.497086 | L39: 89.183655 | M39: 89.886848 | N39: 90.639893 | O39: 91.399002 | P39: 92.155807 | Q39: 92.914574 | R39: 93.675323 | S39: 94.433296 | T39: 95.211731 | U39: 95.983521 | V39: 96.76857 | W39: 97.563377 | X39: 98.389313 | Y39: 99.21096 | Z39: 100.03321 | AA39: 100.86144 | AB39: 101.69376 | AC39: 102.53442 | AD39: 103.37976 | AE39: 104.222 | AF39: 105.06316 | AG39: 0.008
A40: (ton miles/thousand Btu)
A41: Rail | B41: Transportation: Energy Efficiency Indicators: Rail: Alternative Transportation | C41: AEO.2025.ALTTRNP.EFI_NA_TRN_NA_RAIL_NA_NA_TONMLPTHBTU.A | D41: ton miles/thousand Btu | F41: 3.37345 | G41: 3.37701 | H41: 3.380574 | I41: 3.384142 | J41: 3.387713 | K41: 3.391289 | L41: 3.394868 | M41: 3.398451 | N41: 3.402037 | O41: 3.405628 | P41: 3.409222 | Q41: 3.41282 | R41: 3.416422 | S41: 3.420027 | T41: 3.423637 | U41: 3.42725 | V41: 3.430867 | W41: 3.434488 | X41: 3.438113 | Y41: 3.441741 | Z41: 3.445373 | AA41: 3.44901 | AB41: 3.452649 | AC41: 3.456293 | AD41: 3.459941 | AE41: 3.463593 | AF41: 3.467248 | AG41: 0.001
A42: Domestic Shipping | B42: Transportation: Energy Efficiency Indicators: Domestic Shipping: Alternative Transportation | C42: AEO.2025.ALTTRNP.EFI_NA_TRN_NA_DMT_NA_NA_TONMLPTHBTU.A | D42: ton miles/thousand Btu | F42: 4.857779 | G42: 4.876665 | H42: 4.895624 | I42: 4.914657 | J42: 4.933764 | K42: 4.952945 | L42: 4.9722 | M42: 4.991531 | N42: 5.010937 | O42: 5.030418 | P42: 5.049975 | Q42: 5.069608 | R42: 5.089317 | S42: 5.109103 | T42: 5.128966 | U42: 5.148906 | V42: 5.168923 | W42: 5.189019 | X42: 5.209192 | Y42: 5.229445 | Z42: 5.249775 | AA42: 5.270185 | AB42: 5.290674 | AC42: 5.311243 | AD42: 5.331892 | AE42: 5.352621 | AF42: 5.37343 | AG42: 0.004
A43: Energy Use by Mode
...

Sheet AEO 2025 Table 35
A1: Table 35. Transportation Sector Energy Use by Mode and Type
A2: https://www.eia.gov/outlooks/aeo/data/browser/#/?id=45-AEO2025&cases=alttrnp&sourcekey=0
A3: Fri Dec 05 2025 14:48:52 GMT-0800 (Pacific Standard Time)
A4: Source: U.S. Energy Information Administration
B5: full name | C5: api key | D5: units | E5: 2023 | F5: 2024 | G5: 2025 | H5: 2026 | I5: 2027 | J5: 2028 | K5: 2029 | L5: 2030 | M5: 2031 | N5: 2032 | O5: 2033 | P5: 2034 | Q5: 2035 | R5: 2036 | S5: 2037 | T5: 2038 | U5: 2039 | V5: 2040 | W5: 2041 | X5: 2042 | Y5: 2043 | Z5: 2044 | AA5: 2045 | AB5: 2046 | AC5: 2047 | AD5: 2048 | AE5: 2049 | AF5: 2050 | AG5: Growth (2024-2050)
A6: Energy Use by Mode
A7: Highway
A8: Light-Duty Vehicles | B8: Transportation Energy Use: Highway: Light-Duty Vehicles: Alternative Transportation | C8: AEO.2025.ALTTRNP.CNSM_NA_TRN_HWY_LDV_NA_NA_TRLBTU.A | D8: trillion Btu | F8: 15264.654 | G8: 15318.795 | H8: 15263.797 | I8: 15137.205 | J8: 14977.219 | K8: 14792.022 | L8: 14586.776 | M8: 14410.759 | N8: 14212.753 | O8: 14032.138 | P8: 13876.546 | Q8: 13716.936 | R8: 13531.819 | S8: 13355.209 | T8: 13213.084 | U8: 13074.737 | V8: 12960.392 | W8: 12861.576 | X8: 12746.393 | Y8: 12672.746 | Z8: 12583.18 | AA8: 12516.974 | AB8: 12440.612 | AC8: 12393.32 | AD8: 12311.716 | AE8: 12264.786 | AF8: 12255.932 | AG8: -0.008
A9: Automobiles | B9: Transportation Energy Use: Highway: Light-Duty Vehicles: Automobiles: Alternative Transportation | C9: AEO.2025.ALTTRNP.CNSM_NA_TRN_HWY_LDV_AUTO_NA_TRLBTU.A | D9: trillion Btu | F9: 5666.4248 | G9: 5554.9678 | H9: 5400.2788 | I9: 5213.4336 | J9: 5021.1035 | K9: 4829.0156 | L9: 4647.3159 | M9: 4471.4189 | N9: 4301.4409 | O9: 4137.5469 | P9: 4011.3757 | Q9: 3874.7188 | R9: 3737.3823 | S9: 3626.634 | T9: 3540.1406 | U9: 3457.0771 | V9: 3381.4636 | W9: 3320.8726 | X9: 3263.1855 | Y9: 3214.3291 | Z9: 3165.2424 | AA9: 3127.6562 | AB9: 3090.6357 | AC9: 3066.7412 | AD9: 3033.1829 | AE9: 3002.1785 | AF9: 2982.7175 | AG9: -0.024
A10: Light Trucks | B10: Transportation Energy Use: Highway: Light-Duty Vehicles: Light Trucks: Alternative Transportation | C10: AEO.2025.ALTTRNP.CNSM_NA_TRN_HWY_LDV_LTRT_NA_TRLBTU.A | D10: trillion Btu | F10: 9580.5361 | G10: 9746.5537 | H10: 9846.8047 | I10: 9907.7139 | J10: 9940.7285 | K10: 9948.2871 | L10: 9925.3662 | M10: 9925.8486 | N10: 9898.3975 | O10: 9882.2314 | P10: 9853.2383 | Q10: 9830.7393 | R10: 9783.4082 | S10: 9717.9102 | T10: 9662.5664 | U10: 9607.5527 | V10: 9569.0596 | W10: 9531.0273 | X10: 9473.7139 | Y10: 9449.0752 | Z10: 9408.7441 | AA10: 9380.2471 | AB10: 9341.0205 | AC10: 9317.6934 | AD10: 9269.752 | AE10: 9253.9219 | AF10: 9264.5908 | AG10: -0.001
A11: Motorcycles | B11: Transportation Energy Use: Highway: Light-Duty Vehicles: Motorcycles: Alternative Transportation | C11: AEO.2025.ALTTRNP.CNSM_NA_TRN_HWY_LDV_MCYCL_NA_TRLBTU.A | D11: trillion Btu | F11: 17.693827 | G11: 17.273775 | H11: 16.712742 | I11: 16.057793 | J11: 15.386235 | K11: 14.720136 | L11: 14.094455 | M11: 13.491011 | N11: 12.914552 | O11: 12.358894 | P11: 11.931881 | Q11: 11.47748 | R11: 11.027963 | S11: 10.665314 | T11: 10.377406 | U11: 10.107397 | V11: 9.867947 | W11: 9.675448 | X11: 9.493168 | Y11: 9.342217 | Z11: 9.193549 | AA11: 9.070769 | AB11: 8.956112 | AC11: 8.885429 | AD11: 8.781081 | AE11: 8.685104 | AF11: 8.623068 | AG11: -0.027
A12: Commercial Light Trucks | B12: Transportation Energy Use: Highway: Commercial Light Trucks: Alternative Transportation | C12: AEO.2025.ALTTRNP.CNSM_NA_TRN_HWY_CML_NA_NA_TRLBTU.A | D12: trillion Btu | F12: 874.37512 | G12: 855.73944 | H12: 839.74072 | I12: 829.06293 | J12: 817.03815 | K12: 806.52301 | L12: 797.05286 | M12: 786.66846 | N12: 776.01849 | O12: 765.74768 | P12: 755.15271 | Q12: 744.23328 | R12: 733.15375 | S12: 721.99127 | T12: 710.85889 | U12: 699.93121 | V12: 689.72302 | W12: 678.65424 | X12: 668.12085 | Y12: 657.26196 | Z12: 646.87317 | AA12: 636.53192 | AB12: 626.42468 | AC12: 616.49579 | AD12: 606.53198 | AE12: 596.60645 | AF12: 586.6828 | AG12: -0.015
A13: Buses | B13: Transportation Energy Use: Highway: Buses: Alternative Transportation | C13: AEO.2025.ALTTRNP.CNSM_NA_TRN_HWY_BUS_NA_NA_TRLBTU.A | D13: trillion Btu | F13: 207.85881 | G13: 213.51556 | H13: 216.12988 | I13: 217.12576 | J13: 217.48173 | K13: 217.42764 | L13: 217.24431 | M13: 216.24175 | N13: 214.76508 | O13: 213.18587 | P13: 211.90617 | Q13: 210.37204 | R13: 208.78293 | S13: 207.22485 | T13: 205.64493 | U13: 203.97955 | V13: 202.18666 | W13: 200.30072 | X13: 198.29199 | Y13: 196.33681 | Z13: 194.28084 | AA13: 192.31953 | AB13: 190.19499 | AC13: 187.9511 | AD13: 185.79196 | AE13: 183.69107 | AF13: 181.90389 | AG13: -0.005
A14: Transit | B14: Transportation Energy Use: Highway: Buses: Transit: Alternative Transportation | C14: AEO.2025.ALTTRNP.CNSM_NA_TRN_HWY_BUS_TNST_NA_TRLBTU.A | D14: trillion Btu | F14: 76.710045 | G14: 81.313904 | H14: 83.939346 | I14: 85.569359 | J14: 86.754189 | K14: 87.688942 | L14: 88.627594 | M14: 88.838867 | N14: 88.562233 | O14: 88.112343 | P14: 87.900932 | Q14: 87.407082 | R14: 86.832077 | S14: 86.239662 | T14: 85.77771 | U14: 85.252876 | V14: 84.619087 | W14: 83.913132 | X14: 83.115341 | Y14: 82.391418 | Z14: 81.586922 | AA14: 80.892448 | AB14: 80.055817 | AC14: 79.108192 | AD14: 78.258156 | AE14: 77.463318 | AF14: 76.982124 | AG14: 0
A15: Intercity | B15: Transportation Energy Use: Highway: Buses: Intercity: Alternative Transportation | C15: AEO.2025.ALTTRNP.CNSM_NA_TRN_HWY_BUS_ICYT_NA_TRLBTU.A | D15: trillion Btu | F15: 30.108593 | G15: 31.324183 | H15: 32.204269 | I15: 32.814285 | J15: 33.256687 | K15: 33.580925 | L15: 33.812759 | M15: 33.971855 | N15: 34.074734 | O15: 34.127522 | P15: 34.138332 | Q15: 34.117863 | R15: 34.071152 | S15: 34.002563 | T15: 33.932446 | U15: 33.85054 | V15: 33.759457 | W15: 33.660358 | X15: 33.556801 | Y15: 33.447479 | Z15: 33.332581 | AA15: 33.213673 | AB15: 33.091961 | AC15: 32.971535 | AD15: 32.850975 | AE15: 32.727406 | AF15: 32.602531 | AG15: 0.003
A16: School | B16: Transportation Energy Use: Highway: Buses: School: Alternative Transportation | C16: AEO.2025.ALTTRNP.CNSM_NA_TRN_HWY_BUS_SCBU_NA_TRLBTU.A | D16: trillion Btu | F16: 101.04017 | G16: 100.87748 | H16: 99.986282 | I16: 98.742126 | J16: 97.470871 | K16: 96.157784 | L16: 94.803955 | M16: 93.431023 | N16: 92.128098 | O16: 90.945992 | P16: 89.86692 | Q16: 88.847099 | R16: 87.879684 | S16: 86.982628 | T16: 85.934761 | U16: 84.876144 | V16: 83.808136 | W16: 82.727234 | X16: 81.619865 | Y16: 80.497902 | Z16: 79.361336 | AA16: 78.213409 | AB16: 77.047211 | AC16: 75.871361 | AD16: 74.682838 | AE16: 73.500343 | AF16: 72.319229 | AG16: -0.013
A17: Freight Trucks | B17: Transportation Energy Use: Highway: Freight Trucks: Alternative Transportation | C17: AEO.2025.ALTTRNP.CNSM_NA_TRN_HWY_FGHT_NA_NA_TRLBTU.A | D17: trillion Btu | F17: 6005.127 | G17: 6058.6118 | H17: 6062.5513 | I17: 6052.2773 | J17: 6018.6777 | K17: 5988.854 | L17: 5960.1274 | M17: 5923.48 | N17: 5889.1938 | O17: 5851.3447 | P17: 5821.8594 | Q17: 5796.4863 | R17: 5783.0732 | S17: 5777.6479 | T17: 5775.5737 | U17: 5770.502 | V17: 5770.6045 | W17: 5771.0684 | X17: 5774.9722 | Y17: 5776.5781 | Z17: 5777.749 | AA17: 5784.5146 | AB17: 5789.7837 | AC17: 5816.376 | AD17: 5843.7744 | AE17: 5867.5796 | AF17: 5884.5645 | AG17: -0.001
A18: Light Medium | B18: Transportation Energy Use: Highway: Freight Trucks: Light Medium: Alternative Transportation | C18: AEO.2025.ALTTRNP.CNSM_NA_TRN_HWY_FGHT_LITEMED_NA_TRLBTU.A | D18: trillion Btu | F18: 851.47601 | G18: 863.49976 | H18: 867.48792 | I18: 868.15887 | J18: 866.95129 | K18: 870.92328 | L18: 877.43018 | M18: 883.93866 | N18: 890.85523 | O18: 897.59168 | P18: 905.22339 | Q18: 912.45801 | R18: 919.90442 | S18: 926.81397 | T18: 933.20429 | U18: 938.7359 | V18: 945.26697 | W18: 950.28949 | X18: 954.30872 | Y18: 956.26917 | Z18: 958.11407 | AA18: 961.7926 | AB18: 966.23438 | AC18: 973.57996 | AD18: 979.5119 | AE18: 984.37396 | AF18: 988.6319 | AG18: 0.006
A19: Medium | B19: Transportation Energy Use: Highway: Freight Trucks: Medium: Alternative Transportation | C19: AEO.2025.ALTTRNP.CNSM_NA_TRN_HWY_FGHT_MD10T26KLB_NA_TRLBTU.A | D19: trillion Btu | F19: 945.58374 | G19: 933.90814 | H19: 915.86285 | I19: 898.11731 | J19: 880.15131 | K19: 864.79657 | L19: 851.15039 | M19: 837.89587 | N19: 826.3302 | O19: 814.63721 | P19: 804.64459 | Q19: 795.93488 | R19: 789.71979 | S19: 785.57684 | T19: 782.27106 | U19: 779.23023 | V19: 777.32288 | W19: 775.71301 | X19: 775.07422 | Y19: 774.70258 | Z19: 774.43353 | AA19: 774.8346 | AB19: 774.97778 | AC19: 778.14654 | AD19: 781.60486 | AE19: 784.56281 | AF19: 786.19134 | AG19: -0.007
A20: Heavy | B20: Transportation Energy Use: Highway: Freight Trucks: Large: Alternative Transportation | C20: AEO.2025.ALTTRNP.CNSM_NA_TRN_HWY_FGHT_LRGGT26KLB_NA_TRLBTU.A | D20: trillion Btu | F20: 4208.0674 | G20: 4261.2041 | H20: 4279.2012 | I20: 4286.001 | J20: 4271.5757 | K20: 4253.1348 | L20: 4231.5469 | M20: 4201.645 | N20: 4172.0083 | O20: 4139.1157 | P20: 4111.9912 | Q20: 4088.0933 | R20: 4073.449 | S20: 4065.2573 | T20: 4060.0986 | U20: 4052.5354 | V20: 4048.0146 | W20: 4045.0657 | X20: 4045.5889 | Y20: 4045.6067 | Z20: 4045.2017 | AA20: 4047.8877 | AB20: 4048.5718 | AC20: 4064.6492 | AD20: 4082.6575 | AE20: 4098.6436 | AF20: 4109.7412 | AG20: -0.001
A21: Non-Highway
A22: Air | B22: Transportation Energy Use: Non-Highway: Air: Alternative Transportation | C22: AEO.2025.ALTTRNP.CNSM_NA_TRN_AIR_NA_NA_NA_TRLBTU.A | D22: trillion Btu | F22: 3268.3242 | G22: 3262.0327 | H22: 3288.7466 | I22: 3323.8755 | J22: 3351.2607 | K22: 3383.5483 | L22: 3411.5718 | M22: 3430.9507 | N22: 3454.6042 | O22: 3479.3049 | P22: 3503.2454 | Q22: 3534.0239 | R22: 3567.5562 | S22: 3607.156 | T22: 3649.6206 | U22: 3693.1416 | V22: 3735.9509 | W22: 3776.4458 | X22: 3821.688 | Y22: 3863.9778 | Z22: 3901.178 | AA22: 3936.9099 | AB22: 3970.2231 | AC22: 4011.1311 | AD22: 4055.1304 | AE22: 4094.5156 | AF22: 4133.5112 | AG22: 0.009
A23: General Aviation | B23: Transportation Energy Use: Non-Highway: Air: General Aviation: Alternative Transportation | C23: AEO.2025.ALTTRNP.CNSM_NA_TRN_AIR_GAV_NA_NA_TRLBTU.A | D23: trillion Btu | F23: 176.96918 | G23: 176.66234 | H23: 177.92859 | I23: 179.59653 | J23: 180.89647 | K23: 182.43054 | L23: 183.76234 | M23: 184.68278 | N23: 185.80727 | O23: 186.98187 | P23: 188.12065 | Q23: 189.5851 | R23: 191.18109 | S23: 193.06606 | T23: 195.08763 | U23: 197.15936 | V23: 199.19751 | W23: 201.12561 | X23: 203.2796 | Y23: 205.29327 | Z23: 207.06455 | AA23: 208.76579 | AB23: 210.35208 | AC23: 212.29996 | AD23: 214.39508 | AE23: 216.27049 | AF23: 218.12735 | AG23: 0.008
A24: Domestic Passenger | B24: Transportation Energy Use: Non-Highway: Air: Domestic Passenger: Alternative Transportation | C24: AEO.2025.ALTTRNP.CNSM_NA_TRN_AIR_DAC_NA_NA_TRLBTU.A | D24: trillion Btu | F24: 1627.3729 | G24: 1628.4395 | H24: 1648.2767 | I24: 1668.1155 | J24: 1681.5041 | K24: 1697.8981 | L24: 1711.0428 | M24: 1719.0887 | N24: 1729.4327 | O24: 1740.863 | P24: 1751.28 | Q24: 1764.3302 | R24: 1777.9761 | S24: 1793.6168 | T24: 1811.2522 | U24: 1829.1019 | V24: 1846.6696 | W24: 1863.1866 | X24: 1882.0354 | Y24: 1899.4946 | Z24: 1914.4185 | AA24: 1928.4327 | AB24: 1941.7546 | AC24: 1959.423 | AD24: 1978.9136 | AE24: 1996.4678 | AF24: 2013.1691 | AG24: 0.008
A25: International Passenger | B25: Transportation Energy Use: Non-Highway: Air: International Passenger: Alternative Transportation | C25: AEO.2025.ALTTRNP.CNSM_NA_TRN_AIR_IAC_NA_NA_TRLBTU.A | D25: trillion Btu | F25: 908.70795 | G25: 902.83484 | H25: 908.52081 | I25: 918.44818 | J25: 927.18286 | K25: 936.98395 | L25: 946.00244 | M25: 952.78186 | N25: 960.73151 | O25: 968.70251 | P25: 976.70752 | Q25: 987.04419 | R25: 998.51453 | S25: 1012.2177 | T25: 1026.4883 | U25: 1041.1876 | V25: 1055.6478 | W25: 1069.3749 | X25: 1084.5186 | Y25: 1098.7596 | Z25: 1111.4924 | AA25: 1123.8741 | AB25: 1135.3002 | AC25: 1148.7244 | AD25: 1162.9369 | AE25: 1175.6084 | AF25: 1188.4796 | AG25: 0.01
A26: Dedicated Freight | B26: Transportation Energy Use: Non-Highway: Air: Dedicated Freight: Alternative Transportation | C26: AEO.2025.ALTTRNP.CNSM_NA_TRN_AIR_DFT_NA_NA_TRLBTU.A | D26: trillion Btu | F26: 555.27417 | G26: 554.09625 | H26: 554.02063 | I26: 557.71521 | J26: 561.67737 | K26: 566.23572 | L26: 570.76416 | M26: 574.39746 | N26: 578.63281 | O26: 582.75751 | P26: 587.13721 | Q26: 593.06451 | R26: 599.88422 | S26: 608.25562 | T26: 616.79248 | U26: 625.69299 | V26: 634.4361 | W26: 642.75873 | X26: 651.85437 | Y26: 660.43036 | Z26: 668.20258 | AA26: 675.8371 | AB26: 682.81634 | AC26: 690.68384 | AD26: 698.88489 | AE26: 706.16888 | AF26: 713.73535 | AG26: 0.01
A27: Water | B27: Transportation Energy Use: Non-Highway: Water: Alternative Transportation | C27: AEO.2025.ALTTRNP.CNSM_NA_TRN_WTR_NA_NA_NA_TRLBTU.A | D27: trillion Btu | F27: 1054.1652 | G27: 1034.7566 | H27: 1041.5731 | I27: 1053.5527 | J27: 1062.5481 | K27: 1072.6205 | L27: 1082.1591 | M27: 1090.1638 | N27: 1099.3053 | O27: 1108.4968 | P27: 1118.2167 | Q27: 1125.7186 | R27: 1131.6902 | S27: 1137.6836 | T27: 1142.8618 | U27: 1147.9878 | V27: 1152.5002 | W27: 1156.8479 | X27: 1161.4255 | Y27: 1165.7836 | Z27: 1169.736 | AA27: 1173.3649 | AB27: 1176.1564 | AC27: 1181.0236 | AD27: 1186.9668 | AE27: 1192.5219 | AF27: 1197.6055 | AG27: 0.005
A28: Freight | B28: Transportation Energy Use: Non-Highway: Water: Freight: Alternative Transportation | C28: AEO.2025.ALTTRNP.CNSM_NA_TRN_WTR_FGT_NA_NA_TRLBTU.A | D28: trillion Btu | F28: 846.56012 | G28: 828.71191 | H28: 836.32147 | I28: 849.11847 | J28: 859.40271 | K28: 870.53509 | L28: 881.40619 | M28: 891.09924 | N28: 901.58679 | O28: 911.99438 | P28: 922.96387 | Q28: 931.48334 | R28: 938.4212 | S28: 945.2287 | T28: 951.15991 | U28: 957.08179 | V28: 962.37433 | W28: 967.52905 | X28: 972.80926 | Y28: 977.92731 | Z28: 982.77283 | AA28: 987.35004 | AB28: 991.14075 | AC28: 996.73749 | AD28: 1003.3494 | AE28: 1009.6706 | AF28: 1015.5508 | AG28: 0.007
A29: Domestic Shipping | B29: Transportation Energy Use: Non-Highway: Water: Freight: Domestic Shipping: Alternative Transportation | C29: AEO.2025.ALTTRNP.CNSM_NA_TRN_WTR_DMT_NA_NA_TRLBTU.A | D29: trillion Btu | F29: 94.440971 | G29: 95.330078 | H29: 94.566444 | I29: 93.798164 | J29: 93.107506 | K29: 92.339127 | L29: 91.480576 | M29: 90.543335 | N29: 89.462425 | O29: 88.707657 | P29: 88.034157 | Q29: 87.31971 | R29: 86.579651 | S29: 85.944572 | T29: 85.341614 | U29: 84.675209 | V29: 84.112099 | W29: 83.540062 | X29: 82.97393 | Y29: 82.355484 | Z29: 81.679947 | AA29: 81.034569 | AB29: 80.382202 | AC29: 79.95388 | AD29: 79.430321 | AE29: 78.86647 | AF29: 78.277954 | AG29: -0.007
A30: International Shipping | B30: Transportation Energy Use: Non-Highway: Water: Freight: International Shipping: Alternative Transportation | C30: AEO.2025.ALTTRNP.CNSM_NA_TRN_WTR_INTS_NA_NA_TRLBTU.A | D30: trillion Btu | F30: 752.11914 | G30: 733.38184 | H30: 741.755 | I30: 755.32031 | J30: 766.29523 | K30: 778.19598 | L30: 789.9256 | M30: 800.55591 | N30: 812.12439 | O30: 823.28674 | P30: 834.92969 | Q30: 844.16363 | R30: 851.84155 | S30: 859.28412 | T30: 865.8183 | U30: 872.40656 | V30: 878.26221 | W30: 883.98901 | X30: 889.83533 | Y30: 895.57184 | Z30: 901.0929 | AA30: 906.31549 | AB30: 910.75855 | AC30: 916.78363 | AD30: 923.91907 | AE30: 930.80414 | AF30: 937.27283 | AG30: 0.009
A31: Recreational Boats | B31: Transportation Energy Use: Non-Highway: Water: Recreational Boats: Alternative Transportation | C31: AEO.2025.ALTTRNP.CNSM_NA_TRN_WTR_RBT_NA_NA_TRLBTU.A | D31: trillion Btu | F31: 207.60503 | G31: 206.04472 | H31: 205.25169 | I31: 204.43427 | J31: 203.14537 | K31: 202.08534 | L31: 200.75287 | M31: 199.06451 | N31: 197.71854 | O31: 196.5025 | P31: 195.25281 | Q31: 194.23524 | R31: 193.26904 | S31: 192.45489 | T31: 191.70195 | U31: 190.90596 | V31: 190.12585 | W31: 189.31891 | X31: 188.61624 | Y31: 187.85625 | Z31: 186.96317 | AA31: 186.01485 | AB31: 185.01559 | AC31: 184.28604 | AD31: 183.61746 | AE31: 182.85123 | AF31: 182.0547 | AG31: -0.005
A32: Rail | B32: Transportation Energy Use: Non-Highway: Rail: Alternative Transportation | C32: AEO.2025.ALTTRNP.CNSM_NA_TRN_RAIL_RAIL_NA_NA_TRLBTU.A | D32: trillion Btu | F32: 478.12289 | G32: 490.24942 | H32: 480.51019 | I32: 466.46356 | J32: 466.65649 | K32: 465.71143 | L32: 453.8681 | M32: 454.02496 | N32: 435.08209 | O32: 436.88516 | P32: 433.13406 | Q32: 433.3237 | R32: 435.01944 | S32: 437.10776 | T32: 442.49597 | U32: 440.17383 | V32: 442.09015 | W32: 442.67453 | X32: 444.71454 | Y32: 446.9794 | Z32: 448.21762 | AA32: 449.54321 | AB32: 449.73407 | AC32: 453.87384 | AD32: 457.34601 | AE32: 460.23428 | AF32: 461.59979 | AG32: -0.001
A33: Freight | B33: Transportation Energy Use: Non-Highway: Rail: Freight: Alternative Transportation | C33: AEO.2025.ALTTRNP.CNSM_NA_TRN_RAIL_FGT_NA_NA_TRLBTU.A | D33: trillion Btu | F33: 434.23068 | G33: 443.7587 | H33: 432.5813 | I33: 417.75235 | J33: 417.42465 | K33: 415.93777 | L33: 403.47412 | M33: 403.17804 | N33: 383.83212 | O33: 385.30667 | P33: 381.27539 | Q33: 381.04004 | R33: 382.19842 | S33: 383.7374 | T33: 388.55951 | U33: 385.72473 | V33: 387.1702 | W33: 387.33423 | X33: 388.97726 | Y33: 390.85007 | Z33: 391.76263 | AA33: 392.73843 | AB33: 392.65094 | AC33: 396.48129 | AD33: 399.58118 | AE33: 402.09753 | AF33: 402.97449 | AG33: -0.003
... A42: Jet Fuel and Aviation Gasoline | B42: Transportation Energy Use: Military Use: Aviation: Alternative Transportation | C42: AEO.2025.ALTTRNP.CNSM_NA_TRN_MLU_AVI_NA_NA_TRLBTU.A | D42: trillion Btu | F42: 335.94638 | G42: 339.76504 | H42: 342.12509 | I42: 343.58023 | J42: 344.23431 | K42: 344.10706 | L42: 343.94382 | M42: 344.2944 | N42: 344.57822 | O42: 344.87469 | P42: 345.11853 | Q42: 345.30908 | R42: 345.64752 | S42: 346.09128 | T42: 346.51938 | U42: 346.93585 | V42: 347.34112 | W42: 347.7366 | X42: 348.12558 | Y42: 348.51016 | Z42: 348.89059 | AA42: 349.26682 | AB42: 349.64249 | AC42: 350.01758 | AD42: 350.39069 | AE42: 350.76431 | AF42: 351.13889 | AG42: 0.002
A43: Residual Fuel Oil | B43: Transportation Energy Use: Military Use: Residual Fuel Oil: Alternative Transportation | C43: AEO.2025.ALTTRNP.CNSM_NA_TRN_MLU_RFO_NA_NA_TRLBTU.A | D43: trillion Btu | F43: 0 | G43: 0 | H43: 0 | I43: 0 | J43: 0 | K43: 0 | L43: 0 | M43: 0 | N43: 0 | O43: 0 | P43: 0 | Q43: 0 | R43: 0 | S43: 0 | T43: 0 | U43: 0 | V43: 0 | W43: 0 | X43: 0 | Y43: 0 | Z43: 0 | AA43: 0 | AB43: 0 | AC43: 0 | AD43: 0 | AE43: 0 | AF43: 0 | AG43: - -
A44: Distillates and Diesel | B44: Transportation Energy Use: Military Use: Distillate Fuel Oil: Alternative Transportation | C44: AEO.2025.ALTTRNP.CNSM_NA_TRN_MLU_DFO_NA_NA_TRLBTU.A | D44: trillion Btu | F44: 108.84243 | G44: 110.07963 | H44: 110.84426 | I44: 111.31572 | J44: 111.52762 | K44: 111.4864 | L44: 111.43352 | M44: 111.54709 | N44: 111.63905 | O44: 111.73511 | P44: 111.81412 | Q44: 111.87587 | R44: 111.98552 | S44: 112.1293 | T44: 112.26799 | U44: 112.40292 | V44: 112.53424 | W44: 112.66235 | X44: 112.78838 | Y44: 112.91296 | Z44: 113.03624 | AA44: 113.15813 | AB44: 113.27985 | AC44: 113.40138 | AD44: 113.52225 | AE44: 113.6433 | AF44: 113.76468 | AG44: 0.002
A45: Total | B45: Transportation Energy Use: Total: Alternative Transportation | C45: AEO.2025.ALTTRNP.CNSM_NA_TRN_NA_TOT_NA_NA_TRLBTU.A | D45: trillion Btu | F45: 29023.836 | G45: 29108.83 | H45: 29092.584 | I45: 28954.326 | J45: 28829.18 | K45: 28671.768 | L45: 28471.893 | M45: 28308.326 | N45: 28159.508 | O45: 28023.869 | P45: 27891.523 | Q45: 27749.92 | R45: 27603.795 | S45: 27481.891 | T45: 27396.92 | U45: 27298.916 | V45: 27232.668 | W45: 27171.793 | X45: 27104.918 | Y45: 27072.625 | Z45: 27025.742 | AA45: 26999.422 | AB45: 26969.1 | AC45: 26995.1 | AD45: 26992.889 | AE45: 27013.363 | AF45: 27068.242 | AG45: -0.003
A46: Energy Use by Type
A47: Motor Gasoline excluding E85 | B47: Transportation Energy Use: Petroleum: Motor Gasoline: Alternative Transportation | C47: AEO.2025.ALTTRNP.CNSM_NA_TRN_NA_PET_MGS_NA_TRLBTU.A | D47: trillion Btu | F47: 16560.4 | G47: 16586.141 | H47: 16491.031 | I47: 16322.833 | J47: 16116.017 | K47: 15889.713 | L47: 15646.424 | M47: 15442.433 | N47: 15218.63 | O47: 15020.562 | P47: 14848.118 | Q47: 14673.362 | R47: 14472.294 | S47: 14278.983 | T47: 14119.805 | U47: 13963.114 | V47: 13831.296 | W47: 13713.389 | X47: 13578.589 | Y47: 13483.399 | Z47: 13372.886 | AA47: 13287.871 | AB47: 13192.723 | AC47: 13130.141 | AD47: 13032.898 | AE47: 12968.009 | AF47: 12939.202 | AG47: -0.009
A48: E85 | B48: Transportation Energy Use: E85: Alternative Transportation | C48: AEO.2025.ALTTRNP.CNSM_NA_TRN_NA_E85_NA_NA_TRLBTU.A | D48: trillion Btu | F48: 41.284557 | G48: 40.049072 | H48: 37.582172 | I48: 34.528759 | J48: 33.338047 | K48: 32.040035 | L48: 30.544378 | M48: 28.232197 | N48: 26.313066 | O48: 24.350527 | P48: 22.539648 | Q48: 20.880737 | R48: 19.347086 | S48: 18.291014 | T48: 16.780552 | U48: 16.01264 | V48: 15.460896 | W48: 14.956593 | X48: 14.46664 | Y48: 14.072709 | Z48: 13.952835 | AA48: 13.3923 | AB48: 13.186946 | AC48: 13.295124 | AD48: 13.06893 | AE48: 12.868924 | AF48: 12.591402 | AG48: -0.045
...

Sheet AEO 2025 Table 45
A1: Table 45. Transportation Fleet Car and Truck Stock by Type and Technology
A2: https://www.eia.gov/outlooks/aeo/data/browser/#/?id=55-AEO2025&cases=alttrnp&sourcekey=0
A3: Fri Dec 05 2025 14:50:52 GMT-0800 (Pacific Standard Time)
A4: Source: U.S. Energy Information Administration
B5: full name | C5: api key | D5: units | E5: 2023 | F5: 2024 | G5: 2025 | H5: 2026 | I5: 2027 | J5: 2028 | K5: 2029 | L5: 2030 | M5: 2031 | N5: 2032 | O5: 2033 | P5: 2034 | Q5: 2035 | R5: 2036 | S5: 2037 | T5: 2038 | U5: 2039 | V5: 2040 | W5: 2041 | X5: 2042 | Y5: 2043 | Z5: 2044 | AA5: 2045 | AB5: 2046 | AC5: 2047 | AD5: 2048 | AE5: 2049 | AF5: 2050 | AG5: Growth (2024-2050)
A6: Car Stock
A7: Conventional Cars
A8: Gasoline ICE Vehicles | B8: Fleet Vehicle Stock: Conventional Cars: Gasoline: Alternative Transportation | C8: AEO.2025.ALTTRNP.ECI_STK_CNV_FLC_GSL_NA_NA_TH.A | D8: thousands | F8: 5075.3691 | G8: 4824.9785 | H8: 4539.7256 | I8: 4228.9844 | J8: 3937.7976 | K8: 3710.9226 | L8: 3512.5742 | M8: 3327.2087 | N8: 3127.4695 | O8: 2978.8933 | P8: 2861.5793 | Q8: 2729.3728 | R8: 2603.5134 | S8: 2492.502 | T8: 2396.8831 | U8: 2302.8364 | V8: 2209.5779 | W8: 2126.697 | X8: 2053.364 | Y8: 1987.5833 | Z8: 1926.649 | AA8: 1871.7106 | AB8: 1819.1608 | AC8: 1769.2786 | AD8: 1721.4883 | AE8: 1676.5723 | AF8: 1637.2051 | AG8: -0.043
A9: TDI Diesel ICE | B9: Fleet Vehicle Stock: Conventional Cars: TDI Diesel: Alternative Transportation | C9: AEO.2025.ALTTRNP.ECI_STK_CNV_FLC_TDS_NA_NA_TH.A | D9: thousands | F9: 15.97803 | G9: 13.911413 | H9: 12.051627 | I9: 10.370836 | J9: 8.844614 | K9: 7.479106 | L9: 6.284921 | M9: 5.252181 | N9: 4.372341 | O9: 3.643175 | P9: 3.051164 | Q9: 2.579858 | R9: 2.209668 | S9: 1.920185 | T9: 1.695036 | U9: 1.51745 | V9: 1.368175 | W9: 1.237102 | X9: 1.121457 | Y9: 1.018339 | Z9: 0.925365 | AA9: 0.841181 | AB9: 0.764935 | AC9: 0.69586 | AD9: 0.633263 | AE9: 0.576521 | AF9: 0.52507 | AG9: -0.123
A10: Total Conventional Cars | B10: Fleet Vehicle Stock: Conventional Cars: Total: Alternative Transportation | C10: AEO.2025.ALTTRNP.ECI_STK_CNV_FLC_NA_NA_NA_TH.A | D10: thousands | F10: 5091.3472 | G10: 4838.8901 | H10: 4551.7773 | I10: 4239.355 | J10: 3946.6423 | K10: 3718.4016 | L10: 3518.8591 | M10: 3332.4609 | N10: 3131.8418 | O10: 2982.5364 | P10: 2864.6306 | Q10: 2731.9526 | R10: 2605.7231 | S10: 2494.4221 | T10: 2398.5781 | U10: 2304.3538 | V10: 2210.946 | W10: 2127.9341 | X10: 2054.4854 | Y10: 1988.6016 | Z10: 1927.5745 | AA10: 1872.5518 | AB10: 1819.9257 | AC10: 1769.9744 | AD10: 1722.1216 | AE10: 1677.1488 | AF10: 1637.7301 | AG10: -0.043
A11: Alternative-Fuel Cars
A12: Ethanol-Flex Fuel ICE | B12: Fleet Vehicle Stock: Alternative-Fuel Cars: Ethanol-Flex Fuel ICE: Alternative Transportation | C12: AEO.2025.ALTTRNP.ECI_STK_ALF1_FLC_EFFI_NA_NA_TH.A | D12: thousands | F12: 185.83043 | G12: 158.76605 | H12: 134.82158 | I12: 113.52628 | J12: 94.714485 | K12: 78.336166 | L12: 64.364655 | M12: 52.711391 | N12: 43.209827 | O12: 35.860065 | P12: 30.128227 | Q12: 25.750183 | R12: 22.493084 | S12: 19.972109 | T12: 17.990849 | U12: 16.438389 | V12: 15.174291 | W12: 14.108563 | X12: 13.189731 | Y12: 12.385399 | Z12: 11.676161 | AA12: 11.033206 | AB12: 10.440344 | AC12: 9.893756 | AD12: 9.3883 | AE12: 8.92121 | AF12: 8.487045 | AG12: -0.112
A13: 100-Mile Electric Vehicle | B13: Fleet Vehicle Stock: Alternative-Fuel Cars: 100-Mile Electric Vehicle: Alternative Transportation | C13: AEO.2025.ALTTRNP.ECI_STK_ALF1_FLC_100MIEV_NA_NA_TH.A | D13: thousands | F13: 11.85019 | G13: 12.360404 | H13: 12.04448 | I13: 11.302363 | J13: 10.383241 | K13: 9.624597 | L13: 9.14712 | M13: 8.794331 | N13: 8.563879 | O13: 7.991126 | P13: 7.706276 | Q13: 7.585549 | R13: 7.577725 | S13: 7.639728 | T13: 7.761407 | U13: 7.928746 | V13: 7.974091 | W13: 8.047615 | X13: 8.139864 | Y13: 8.259529 | Z13: 8.361784 | AA13: 8.471305 | AB13: 8.556553 | AC13: 8.620687 | AD13: 8.678905 | AE13: 8.732212 | AF13: 8.828277 | AG13: -0.011
A14: 200-Mile Electric Vehicle | B14: Fleet Vehicle Stock: Alternative-Fuel Cars: 200-Mile Electric Vehicle: Alternative Transportation | C14: AEO.2025.ALTTRNP.ECI_STK_ALF1_FLC_200MIEV_NA_NA_TH.A | D14: thousands | F14: 70.611595 | G14: 89.524704 | H14: 108.11518 | I14: 128.68025 | J14: 142.52853 | K14: 151.67728 | L14: 165.15234 | M14: 179.0822 | N14: 235.65671 | O14: 287.33295 | P14: 334.09531 | Q14: 392.7757 | R14: 437.33997 | S14: 473.97659 | T14: 507.0426 | U14: 555.18976 | V14: 592.68933 | W14: 622.91486 | X14: 647.55518 | Y14: 671.5658 | Z14: 692.02985 | AA14: 712.49701 | AB14: 728.66309 | AC14: 741.73767 | AD14: 753.25073 | AE14: 763.21765 | AF14: 776.83136 | AG14: 0.097
A15: 300-Mile Electric Vehicle | B15: Fleet Vehicle Stock: Alternative-Fuel Cars: 300-Mile Electric Vehicle: Alternative Transportation | C15: AEO.2025.ALTTRNP.ECI_STK_ALF1_FLC_300MIEV_NA_NA_TH.A | D15: thousands | F15: 278.5542 | G15: 365.3042 | H15: 506.17468 | I15: 651.42444 | J15: 761.15637 | K15: 835.7478 | L15: 906.38159 | M15: 966.11365 | N15: 1013.4059 | O15: 1021.9559 | P15: 1053.6199 | Q15: 1086.2643 | R15: 1118.5103 | S15: 1148.3688 | T15: 1176.9158 | U15: 1200.6284 | V15: 1230.4824 | W15: 1251.8945 | X15: 1267.2229 | Y15: 1277.7421 | Z15: 1286.0959 | AA15: 1292.9971 | AB15: 1297.876 | AC15: 1300.225 | AD15: 1299.7361 | AE15: 1298.2346 | AF15: 1298.1738 | AG15: 0.061
A16: Plug-in 20 Gasoline Hybrid | B16: Fleet Vehicle Stock: Alternative-Fuel Cars: Plug-in 20 Gasoline Hybrid: Alternative Transportation | C16: AEO.2025.ALTTRNP.ECI_STK_ALF1_FLC_PI20GH_NA_NA_TH.A | D16: thousands | F16: 24.319166 | G16: 28.024124 | H16: 31.654152 | I16: 35.126587 | J16: 37.782135 | K16: 38.713367 | L16: 39.330399 | M16: 39.821682 | N16: 39.222111 | O16: 37.875874 | P16: 37.592007 | Q16: 37.293442 | R16: 37.181023 | S16: 37.163883 | T16: 37.256145 | U16: 37.154495 | V16: 37.032181 | W16: 36.916473 | X16: 36.799957 | Y16: 36.725025 | Z16: 36.56406 | AA16: 36.438702 | AB16: 36.224213 | AC16: 35.973831 | AD16: 35.735878 | AE16: 35.502071 | AF16: 35.428936 | AG16: 0.015
A17: Plug-in 50 Gasoline Hybrid | B17: Fleet Vehicle Stock: Alternative-Fuel Cars: Plug-in 50 Gasoline Hybrid: Alternative Transportation | C17: AEO.2025.ALTTRNP.ECI_STK_ALF1_FLC_PI50GH_NA_NA_TH.A | D17: thousands | F17: 16.713234 | G17: 19.646 | H17: 27.47275 | I17: 34.305477 | J17: 39.878403 | K17: 43.144493 | L17: 45.670815 | M17: 47.934826 | N17: 47.271561 | O17: 44.810276 | P17: 44.349277 | Q17: 43.442249 | R17: 43.14138 | S17: 43.079933 | T17: 43.204563 | U17: 42.328564 | V17: 41.575184 | W17: 40.920044 | X17: 40.343662 | Y17: 39.810692 | Z17: 39.193901 | AA17: 38.606316 | AB17: 37.957912 | AC17: 37.301849 | AD17: 36.676651 | AE17: 36.085972 | AF17: 35.664669 | AG17: 0.03
A18: Electric-Diesel Hybrid | B18: Fleet Vehicle Stock: Alternative-Fuel Cars: Electric-Diesel Hybrid: Alternative Transportation | C18: AEO.2025.ALTTRNP.ECI_STK_ALF1_FLC_EDH_NA_NA_TH.A | D18: thousands | F18: 0 | G18: 0 | H18: 0 | I18: 0 | J18: 0 | K18: 0 | L18: 0 | M18: 0 | N18: 0 | O18: 0 | P18: 0 | Q18: 0 | R18: 0 | S18: 0 | T18: 0 | U18: 0 | V18: 0 | W18: 0 | X18: 0 | Y18: 0 | Z18: 0 | AA18: 0 | AB18: 0 | AC18: 0 | AD18: 0 | AE18: 0 | AF18: 0 | AG18: - -
A19: Electric-Gasoline Hybrid | B19: Fleet Vehicle Stock: Alternative-Fuel Cars: Electric-Gasoline Hybrid: Alternative Transportation | C19: AEO.2025.ALTTRNP.ECI_STK_ALF1_FLC_EGH_NA_NA_TH.A | D19: thousands | F19: 274.11764 | G19: 308.04507 | H19: 323.01923 | I19: 335.71899 | J19: 337.89535 | K19: 341.75336 | L19: 345.65527 | M19: 349.70908 | N19: 346.89227 | O19: 349.15042 | P19: 355.9191 | Q19: 358.72296 | R19: 360.87073 | S19: 363.92602 | T19: 368.21139 | U19: 371.38156 | V19: 372.19873 | W19: 373.74976 | X19: 376.0116 | Y19: 378.73047 | Z19: 381.48401 | AA19: 384.61078 | AB19: 387.44223 | AC19: 389.94586 | AD19: 392.03339 | AE19: 394.1467 | AF19: 397.24316 | AG19: 0.014
A20: Natural Gas ICE | B20: Fleet Vehicle Stock: Alternative-Fuel Cars: Natural Gas ICE: Alternative Transportation | C20: AEO.2025.ALTTRNP.ECI_STK_ALF1_FLC_NGI_NA_NA_TH.A | D20: thousands | F20: 9.965523 | G20: 9.08284 | H20: 8.202013 | I20: 7.321419 | J20: 6.466685 | K20: 5.655651 | L20: 4.984686 | M20: 4.35171 | N20: 3.793523 | O20: 3.313169 | P20: 2.91656 | Q20: 2.58629 | R20: 2.315182 | S20: 2.136791 | T20: 1.984197 | U20: 1.85726 | V20: 1.744241 | W20: 1.638098 | X20: 1.538415 | Y20: 1.444798 | Z20: 1.356878 | AA20: 1.274307 | AB20: 1.196762 | AC20: 1.123936 | AD20: 1.055541 | AE20: 0.991308 | AF20: 0.930984 | AG20: -0.087
A21: Natural Gas Bi-fuel | B21: Fleet Vehicle Stock: Alternative-Fuel Cars: Natural Gas Bi-fuel: Alternative Transportation | C21: AEO.2025.ALTTRNP.ECI_STK_ALF1_FLC_NBF_NA_NA_TH.A | D21: thousands | F21: 0.236445 | G21: 0.222056 | H21: 0.208544 | I21: 0.195853 | J21: 0.183935 | K21: 0.172742 | L21: 0.16223 | M21: 0.152358 | N21: 0.143086 | O21: 0.134379 | P21: 0.126202 | Q21: 0.118522 | R21: 0.11131 | S21: 0.104536 | T21: 0.098175 | U21: 0.092201 | V21: 0.08659 | W21: 0.081321 | X21: 0.076372 | Y21: 0.071725 | Z21: 0.06736 | AA21: 0.063261 | AB21: 0.059411 | AC21: 0.055796 | AD21: 0.0524 | AE21: 0.049212 | AF21: 0.046217 | AG21: -0.061
A22: Propane ICE | B22: Fleet Vehicle Stock: Alternative-Fuel Cars: Propane ICE: Alternative Transportation | C22: AEO.2025.ALTTRNP.ECI_STK_ALF1_FLC_PROP_NA_NA_TH.A | D22: thousands | F22: 1.530565 | G22: 1.330983 | H22: 1.206502 | I22: 1.130379 | J22: 1.061592 | K22: 0.996991 | L22: 0.936321 | M22: 0.879343 | N22: 0.825832 | O22: 0.775578 | P22: 0.728382 | Q22: 0.684058 | R22: 0.642431 | S22: 0.603337 | T22: 0.566622 | U22: 0.532141 | V22: 0.499759 | W22: 0.469347 | X22: 0.440786 | Y22: 0.413963 | Z22: 0.388772 | AA22: 0.365114 | AB22: 0.342896 | AC22: 0.322029 | AD22: 0.302433 | AE22: 0.284029 | AF22: 0.266745 | AG22: -0.065
A23: Propane Bi-fuel | B23: Fleet Vehicle Stock: Alternative-Fuel Cars: Propane Bi-fuel: Alternative Transportation | C23: AEO.2025.ALTTRNP.ECI_STK_ALF1_FLC_PBF_NA_NA_TH.A | D23: thousands | F23: 2.995354 | G23: 2.585502 | H23: 2.306102 | I23: 2.135293 | J23: 1.990221 | K23: 1.86911 | L23: 1.755369 | M23: 1.64855 | N23: 1.54823 | O23: 1.454016 | P23: 1.365535 | Q23: 1.282438 | R23: 1.204397 | S23: 1.131106 | T23: 1.062275 | U23: 0.997633 | V23: 0.936924 | W23: 0.879909 | X23: 0.826364 | Y23: 0.776077 | Z23: 0.72885 | AA23: 0.684498 | AB23: 0.642844 | AC23: 0.603725 | AD23: 0.566987 | AE23: 0.532484 | AF23: 0.50008 | AG23: -0.067
A24: Fuel Cell Methanol | B24: Fleet Vehicle Stock: Alternative-Fuel Cars: Fuel Cell Methanol: Alternative Transportation | C24: AEO.2025.ALTTRNP.ECI_STK_ALF1_FLC_FCLMTH_NA_NA_TH.A | D24: thousands | F24: 0 | G24: 0 | H24: 0 | I24: 0 | J24: 0 | K24: 0 | L24: 0 | M24: 0 | N24: 0 | O24: 0 | P24: 0 | Q24: 0 | R24: 0 | S24: 0 | T24: 0 | U24: 0 | V24: 0 | W24: 0 | X24: 0 | Y24: 0 | Z24: 0 | AA24: 0 | AB24: 0 | AC24: 0 | AD24: 0 | AE24: 0 | AF24: 0 | AG24: - -
